2024-01-17 04:13:07,785 - django.utils.autoreload - INFO - /djangoapp/trigger_web_scraping_dou_api/scrapers.py changed, reloading.
2024-01-17 04:13:16,293 - django.request - ERROR - Internal Server Error: /trigger_web_scraping_dou_api/
Traceback (most recent call last):
  File "/venv/lib/python3.11/site-packages/django/core/handlers/exception.py", line 55, in inner
    response = get_response(request)
               ^^^^^^^^^^^^^^^^^^^^^
  File "/venv/lib/python3.11/site-packages/django/core/handlers/base.py", line 197, in _get_response
    response = wrapped_callback(request, *callback_args, **callback_kwargs)
               ^^^^^^^^^^^^^^^^^^^^^^^^^^^^^^^^^^^^^^^^^^^^^^^^^^^^^^^^^^^^
  File "/venv/lib/python3.11/site-packages/django/views/decorators/csrf.py", line 56, in wrapper_view
    return view_func(*args, **kwargs)
           ^^^^^^^^^^^^^^^^^^^^^^^^^^
  File "/venv/lib/python3.11/site-packages/django/views/generic/base.py", line 104, in view
    return self.dispatch(request, *args, **kwargs)
           ^^^^^^^^^^^^^^^^^^^^^^^^^^^^^^^^^^^^^^^
  File "/venv/lib/python3.11/site-packages/rest_framework/views.py", line 509, in dispatch
    response = self.handle_exception(exc)
               ^^^^^^^^^^^^^^^^^^^^^^^^^^
  File "/venv/lib/python3.11/site-packages/rest_framework/views.py", line 469, in handle_exception
    self.raise_uncaught_exception(exc)
  File "/venv/lib/python3.11/site-packages/rest_framework/views.py", line 480, in raise_uncaught_exception
    raise exc
  File "/venv/lib/python3.11/site-packages/rest_framework/views.py", line 506, in dispatch
    response = handler(request, *args, **kwargs)
               ^^^^^^^^^^^^^^^^^^^^^^^^^^^^^^^^^
  File "/djangoapp/trigger_web_scraping_dou_api/views.py", line 43, in get
    return self.handle_URL_empty_params(saveInDBFlagURLQueryString=False, detailDOUJournalFlag=True)
           ^^^^^^^^^^^^^^^^^^^^^^^^^^^^^^^^^^^^^^^^^^^^^^^^^^^^^^^^^^^^^^^^^^^^^^^^^^^^^^^^^^^^^^^^^
  File "/djangoapp/trigger_web_scraping_dou_api/views.py", line 142, in handle_URL_empty_params
    response = ScraperUtil.run_scraper_with_empty_params_using_others_instance_of_our_apis(saveInDBFlagURLQueryString, detailDOUJournalFlag)
               ^^^^^^^^^^^^^^^^^^^^^^^^^^^^^^^^^^^^^^^^^^^^^^^^^^^^^^^^^^^^^^^^^^^^^^^^^^^^^^^^^^^^^^^^^^^^^^^^^^^^^^^^^^^^^^^^^^^^^^^^^^^^^
  File "/djangoapp/trigger_web_scraping_dou_api/scrapers.py", line 175, in run_scraper_with_empty_params_using_others_instance_of_our_apis
    all_dous_with_current_date_moreDetails = list(executor.map(ScraperUtil.make_request_for_others_clone_api, urls_clones_instances))
                                                  ^^^^^^^^^^^^^^^^^^^^^^^^^^^^^^^^^^^^^^^^^^^^^^^^^^^^^^^^^^^^^^^^^^^^^^^^^^^^^^^^^^
  File "/usr/local/lib/python3.11/concurrent/futures/_base.py", line 608, in map
    fs = [self.submit(fn, *args) for args in zip(*iterables)]
         ^^^^^^^^^^^^^^^^^^^^^^^^^^^^^^^^^^^^^^^^^^^^^^^^^^^^
  File "/usr/local/lib/python3.11/concurrent/futures/_base.py", line 608, in <listcomp>
    fs = [self.submit(fn, *args) for args in zip(*iterables)]
          ^^^^^^^^^^^^^^^^^^^^^^
  File "/usr/local/lib/python3.11/concurrent/futures/thread.py", line 169, in submit
    raise RuntimeError('cannot schedule new futures after '
RuntimeError: cannot schedule new futures after interpreter shutdown
2024-01-17 04:13:16,513 - django.request - WARNING - Not Found: /favicon.ico
2024-01-17 04:13:20,034 - django.request - ERROR - Internal Server Error: /trigger_web_scraping_dou_api/
Traceback (most recent call last):
  File "/venv/lib/python3.11/site-packages/django/core/handlers/exception.py", line 55, in inner
    response = get_response(request)
               ^^^^^^^^^^^^^^^^^^^^^
  File "/venv/lib/python3.11/site-packages/django/core/handlers/base.py", line 197, in _get_response
    response = wrapped_callback(request, *callback_args, **callback_kwargs)
               ^^^^^^^^^^^^^^^^^^^^^^^^^^^^^^^^^^^^^^^^^^^^^^^^^^^^^^^^^^^^
  File "/venv/lib/python3.11/site-packages/django/views/decorators/csrf.py", line 56, in wrapper_view
    return view_func(*args, **kwargs)
           ^^^^^^^^^^^^^^^^^^^^^^^^^^
  File "/venv/lib/python3.11/site-packages/django/views/generic/base.py", line 104, in view
    return self.dispatch(request, *args, **kwargs)
           ^^^^^^^^^^^^^^^^^^^^^^^^^^^^^^^^^^^^^^^
  File "/venv/lib/python3.11/site-packages/rest_framework/views.py", line 509, in dispatch
    response = self.handle_exception(exc)
               ^^^^^^^^^^^^^^^^^^^^^^^^^^
  File "/venv/lib/python3.11/site-packages/rest_framework/views.py", line 469, in handle_exception
    self.raise_uncaught_exception(exc)
  File "/venv/lib/python3.11/site-packages/rest_framework/views.py", line 480, in raise_uncaught_exception
    raise exc
  File "/venv/lib/python3.11/site-packages/rest_framework/views.py", line 506, in dispatch
    response = handler(request, *args, **kwargs)
               ^^^^^^^^^^^^^^^^^^^^^^^^^^^^^^^^^
  File "/djangoapp/trigger_web_scraping_dou_api/views.py", line 43, in get
    return self.handle_URL_empty_params(saveInDBFlagURLQueryString=False, detailDOUJournalFlag=True)
           ^^^^^^^^^^^^^^^^^^^^^^^^^^^^^^^^^^^^^^^^^^^^^^^^^^^^^^^^^^^^^^^^^^^^^^^^^^^^^^^^^^^^^^^^^
  File "/djangoapp/trigger_web_scraping_dou_api/views.py", line 142, in handle_URL_empty_params
    response = ScraperUtil.run_scraper_with_empty_params_using_others_instance_of_our_apis(saveInDBFlagURLQueryString, detailDOUJournalFlag)
               ^^^^^^^^^^^^^^^^^^^^^^^^^^^^^^^^^^^^^^^^^^^^^^^^^^^^^^^^^^^^^^^^^^^^^^^^^^^^^^^^^^^^^^^^^^^^^^^^^^^^^^^^^^^^^^^^^^^^^^^^^^^^^
  File "/djangoapp/trigger_web_scraping_dou_api/scrapers.py", line 175, in run_scraper_with_empty_params_using_others_instance_of_our_apis
    all_dous_with_current_date_moreDetails = list(executor.map(ScraperUtil.make_request_for_others_clone_api, urls_clones_instances))
                                                  ^^^^^^^^^^^^^^^^^^^^^^^^^^^^^^^^^^^^^^^^^^^^^^^^^^^^^^^^^^^^^^^^^^^^^^^^^^^^^^^^^^
  File "/usr/local/lib/python3.11/concurrent/futures/_base.py", line 608, in map
    fs = [self.submit(fn, *args) for args in zip(*iterables)]
         ^^^^^^^^^^^^^^^^^^^^^^^^^^^^^^^^^^^^^^^^^^^^^^^^^^^^
  File "/usr/local/lib/python3.11/concurrent/futures/_base.py", line 608, in <listcomp>
    fs = [self.submit(fn, *args) for args in zip(*iterables)]
          ^^^^^^^^^^^^^^^^^^^^^^
  File "/usr/local/lib/python3.11/concurrent/futures/thread.py", line 169, in submit
    raise RuntimeError('cannot schedule new futures after '
RuntimeError: cannot schedule new futures after interpreter shutdown
2024-01-17 04:13:20,158 - django.request - WARNING - Not Found: /favicon.ico
2024-01-17 04:13:46,521 - django.request - ERROR - Internal Server Error: /trigger_web_scraping_dou_api/
Traceback (most recent call last):
  File "/venv/lib/python3.11/site-packages/django/core/handlers/exception.py", line 55, in inner
    response = get_response(request)
               ^^^^^^^^^^^^^^^^^^^^^
  File "/venv/lib/python3.11/site-packages/django/core/handlers/base.py", line 197, in _get_response
    response = wrapped_callback(request, *callback_args, **callback_kwargs)
               ^^^^^^^^^^^^^^^^^^^^^^^^^^^^^^^^^^^^^^^^^^^^^^^^^^^^^^^^^^^^
  File "/venv/lib/python3.11/site-packages/django/views/decorators/csrf.py", line 56, in wrapper_view
    return view_func(*args, **kwargs)
           ^^^^^^^^^^^^^^^^^^^^^^^^^^
  File "/venv/lib/python3.11/site-packages/django/views/generic/base.py", line 104, in view
    return self.dispatch(request, *args, **kwargs)
           ^^^^^^^^^^^^^^^^^^^^^^^^^^^^^^^^^^^^^^^
  File "/venv/lib/python3.11/site-packages/rest_framework/views.py", line 509, in dispatch
    response = self.handle_exception(exc)
               ^^^^^^^^^^^^^^^^^^^^^^^^^^
  File "/venv/lib/python3.11/site-packages/rest_framework/views.py", line 469, in handle_exception
    self.raise_uncaught_exception(exc)
  File "/venv/lib/python3.11/site-packages/rest_framework/views.py", line 480, in raise_uncaught_exception
    raise exc
  File "/venv/lib/python3.11/site-packages/rest_framework/views.py", line 506, in dispatch
    response = handler(request, *args, **kwargs)
               ^^^^^^^^^^^^^^^^^^^^^^^^^^^^^^^^^
  File "/djangoapp/trigger_web_scraping_dou_api/views.py", line 43, in get
    return self.handle_URL_empty_params(saveInDBFlagURLQueryString=False, detailDOUJournalFlag=True)
           ^^^^^^^^^^^^^^^^^^^^^^^^^^^^^^^^^^^^^^^^^^^^^^^^^^^^^^^^^^^^^^^^^^^^^^^^^^^^^^^^^^^^^^^^^
  File "/djangoapp/trigger_web_scraping_dou_api/views.py", line 142, in handle_URL_empty_params
    response = ScraperUtil.run_scraper_with_empty_params_using_others_instance_of_our_apis(saveInDBFlagURLQueryString, detailDOUJournalFlag)
               ^^^^^^^^^^^^^^^^^^^^^^^^^^^^^^^^^^^^^^^^^^^^^^^^^^^^^^^^^^^^^^^^^^^^^^^^^^^^^^^^^^^^^^^^^^^^^^^^^^^^^^^^^^^^^^^^^^^^^^^^^^^^^
  File "/djangoapp/trigger_web_scraping_dou_api/scrapers.py", line 175, in run_scraper_with_empty_params_using_others_instance_of_our_apis
    all_dous_with_current_date_moreDetails = list(executor.map(ScraperUtil.make_request_for_others_clone_api, urls_clones_instances))
                                                  ^^^^^^^^^^^^^^^^^^^^^^^^^^^^^^^^^^^^^^^^^^^^^^^^^^^^^^^^^^^^^^^^^^^^^^^^^^^^^^^^^^
  File "/usr/local/lib/python3.11/concurrent/futures/_base.py", line 608, in map
    fs = [self.submit(fn, *args) for args in zip(*iterables)]
         ^^^^^^^^^^^^^^^^^^^^^^^^^^^^^^^^^^^^^^^^^^^^^^^^^^^^
  File "/usr/local/lib/python3.11/concurrent/futures/_base.py", line 608, in <listcomp>
    fs = [self.submit(fn, *args) for args in zip(*iterables)]
          ^^^^^^^^^^^^^^^^^^^^^^
  File "/usr/local/lib/python3.11/concurrent/futures/thread.py", line 169, in submit
    raise RuntimeError('cannot schedule new futures after '
RuntimeError: cannot schedule new futures after interpreter shutdown
2024-01-17 04:21:39,492 - django.utils.autoreload - INFO - /djangoapp/trigger_web_scraping_dou_api/scrapers.py changed, reloading.
2024-01-17 04:31:14,863 - django.request - WARNING - Not Found: /favicon.ico
2024-01-18 04:02:43,925 - ScraperUtil - ERROR - make_request_to_dou_journal_moreDetail_and_scraping_async: Erro: Server disconnected
2024-01-18 04:02:43,925 - ScraperUtil - ERROR - make_request_to_dou_journal_moreDetail_and_scraping_async: Erro: Server disconnected
2024-01-18 04:02:43,925 - ScraperUtil - ERROR - make_request_to_dou_journal_moreDetail_and_scraping_async: Erro: Server disconnected
2024-01-18 04:02:43,925 - ScraperUtil - ERROR - make_request_to_dou_journal_moreDetail_and_scraping_async: Erro: Server disconnected
2024-01-18 04:02:43,925 - ScraperUtil - ERROR - make_request_to_dou_journal_moreDetail_and_scraping_async: Erro: Server disconnected
2024-01-18 04:02:43,925 - ScraperUtil - ERROR - make_request_to_dou_journal_moreDetail_and_scraping_async: Erro: Server disconnected
2024-01-18 04:02:43,925 - ScraperUtil - ERROR - make_request_to_dou_journal_moreDetail_and_scraping_async: Erro: Server disconnected
2024-01-18 04:02:43,926 - ScraperUtil - ERROR - make_request_to_dou_journal_moreDetail_and_scraping_async: Erro: Server disconnected
2024-01-18 04:02:43,926 - ScraperUtil - ERROR - make_request_to_dou_journal_moreDetail_and_scraping_async: Erro: Server disconnected
2024-01-18 04:02:46,452 - ScraperUtil - ERROR - make_request_to_dou_journal_moreDetail_and_scraping_async: Erro: Server disconnected
2024-01-18 04:02:46,452 - ScraperUtil - ERROR - make_request_to_dou_journal_moreDetail_and_scraping_async: Erro: Server disconnected
2024-01-18 04:02:46,452 - ScraperUtil - ERROR - make_request_to_dou_journal_moreDetail_and_scraping_async: Erro: Server disconnected
2024-01-18 04:02:46,453 - ScraperUtil - ERROR - make_request_to_dou_journal_moreDetail_and_scraping_async: Erro: Server disconnected
2024-01-18 04:02:46,453 - ScraperUtil - ERROR - make_request_to_dou_journal_moreDetail_and_scraping_async: Erro: Server disconnected
2024-01-18 04:02:46,453 - ScraperUtil - ERROR - make_request_to_dou_journal_moreDetail_and_scraping_async: Erro: Server disconnected
2024-01-18 04:02:46,453 - ScraperUtil - ERROR - make_request_to_dou_journal_moreDetail_and_scraping_async: Erro: Server disconnected
2024-01-18 04:02:46,453 - ScraperUtil - ERROR - make_request_to_dou_journal_moreDetail_and_scraping_async: Erro: Server disconnected
2024-01-18 04:02:46,453 - ScraperUtil - ERROR - make_request_to_dou_journal_moreDetail_and_scraping_async: Erro: Server disconnected
2024-01-18 04:02:46,453 - ScraperUtil - ERROR - make_request_to_dou_journal_moreDetail_and_scraping_async: Erro: Server disconnected
2024-01-18 04:02:46,453 - ScraperUtil - ERROR - make_request_to_dou_journal_moreDetail_and_scraping_async: Erro: Server disconnected
2024-01-18 04:02:46,453 - ScraperUtil - ERROR - make_request_to_dou_journal_moreDetail_and_scraping_async: Erro: Server disconnected
2024-01-18 04:02:46,453 - ScraperUtil - ERROR - make_request_to_dou_journal_moreDetail_and_scraping_async: Erro: Server disconnected
2024-01-18 04:02:46,453 - ScraperUtil - ERROR - make_request_to_dou_journal_moreDetail_and_scraping_async: Erro: Server disconnected
2024-01-18 04:02:46,453 - ScraperUtil - ERROR - make_request_to_dou_journal_moreDetail_and_scraping_async: Erro: Server disconnected
2024-01-18 04:02:46,453 - ScraperUtil - ERROR - make_request_to_dou_journal_moreDetail_and_scraping_async: Erro: Server disconnected
2024-01-18 04:02:46,453 - ScraperUtil - ERROR - make_request_to_dou_journal_moreDetail_and_scraping_async: Erro: Server disconnected
2024-01-18 04:02:46,453 - ScraperUtil - ERROR - make_request_to_dou_journal_moreDetail_and_scraping_async: Erro: Server disconnected
2024-01-18 04:02:46,453 - ScraperUtil - ERROR - make_request_to_dou_journal_moreDetail_and_scraping_async: Erro: Server disconnected
2024-01-18 04:02:46,453 - ScraperUtil - ERROR - make_request_to_dou_journal_moreDetail_and_scraping_async: Erro: Server disconnected
2024-01-18 04:02:46,454 - ScraperUtil - ERROR - make_request_to_dou_journal_moreDetail_and_scraping_async: Erro: Server disconnected
2024-01-18 04:02:46,454 - ScraperUtil - ERROR - make_request_to_dou_journal_moreDetail_and_scraping_async: Erro: Server disconnected
2024-01-18 04:02:46,454 - ScraperUtil - ERROR - make_request_to_dou_journal_moreDetail_and_scraping_async: Erro: Server disconnected
2024-01-18 04:02:46,454 - ScraperUtil - ERROR - make_request_to_dou_journal_moreDetail_and_scraping_async: Erro: Server disconnected
2024-01-18 04:02:46,454 - ScraperUtil - ERROR - make_request_to_dou_journal_moreDetail_and_scraping_async: Erro: Server disconnected
2024-01-18 04:02:46,454 - ScraperUtil - ERROR - make_request_to_dou_journal_moreDetail_and_scraping_async: Erro: Server disconnected
2024-01-18 04:02:46,454 - ScraperUtil - ERROR - make_request_to_dou_journal_moreDetail_and_scraping_async: Erro: Server disconnected
2024-01-18 04:02:46,454 - ScraperUtil - ERROR - make_request_to_dou_journal_moreDetail_and_scraping_async: Erro: Server disconnected
2024-01-18 04:02:46,454 - ScraperUtil - ERROR - make_request_to_dou_journal_moreDetail_and_scraping_async: Erro: Server disconnected
2024-01-18 04:02:46,454 - ScraperUtil - ERROR - make_request_to_dou_journal_moreDetail_and_scraping_async: Erro: Server disconnected
2024-01-18 04:02:46,454 - ScraperUtil - ERROR - make_request_to_dou_journal_moreDetail_and_scraping_async: Erro: Server disconnected
2024-01-18 04:02:46,454 - ScraperUtil - ERROR - make_request_to_dou_journal_moreDetail_and_scraping_async: Erro: Server disconnected
2024-01-18 04:02:46,454 - ScraperUtil - ERROR - make_request_to_dou_journal_moreDetail_and_scraping_async: Erro: Server disconnected
2024-01-18 04:02:46,454 - ScraperUtil - ERROR - make_request_to_dou_journal_moreDetail_and_scraping_async: Erro: Server disconnected
2024-01-18 04:02:46,454 - ScraperUtil - ERROR - make_request_to_dou_journal_moreDetail_and_scraping_async: Erro: Server disconnected
2024-01-18 04:02:46,454 - ScraperUtil - ERROR - make_request_to_dou_journal_moreDetail_and_scraping_async: Erro: Server disconnected
2024-01-18 04:02:46,454 - ScraperUtil - ERROR - make_request_to_dou_journal_moreDetail_and_scraping_async: Erro: Server disconnected
2024-01-18 04:02:46,455 - ScraperUtil - ERROR - make_request_to_dou_journal_moreDetail_and_scraping_async: Erro: Server disconnected
2024-01-18 04:02:46,455 - ScraperUtil - ERROR - make_request_to_dou_journal_moreDetail_and_scraping_async: Erro: Server disconnected
2024-01-18 04:02:46,455 - ScraperUtil - ERROR - make_request_to_dou_journal_moreDetail_and_scraping_async: Erro: Server disconnected
2024-01-18 04:02:46,455 - ScraperUtil - ERROR - make_request_to_dou_journal_moreDetail_and_scraping_async: Erro: Server disconnected
2024-01-18 04:02:46,455 - ScraperUtil - ERROR - make_request_to_dou_journal_moreDetail_and_scraping_async: Erro: Server disconnected
2024-01-18 04:02:46,455 - ScraperUtil - ERROR - make_request_to_dou_journal_moreDetail_and_scraping_async: Erro: Server disconnected
2024-01-18 04:02:46,455 - ScraperUtil - ERROR - make_request_to_dou_journal_moreDetail_and_scraping_async: Erro: Server disconnected
2024-01-18 04:02:46,455 - ScraperUtil - ERROR - make_request_to_dou_journal_moreDetail_and_scraping_async: Erro: Server disconnected
2024-01-18 04:02:46,455 - ScraperUtil - ERROR - make_request_to_dou_journal_moreDetail_and_scraping_async: Erro: Server disconnected
2024-01-18 04:02:46,455 - ScraperUtil - ERROR - make_request_to_dou_journal_moreDetail_and_scraping_async: Erro: Server disconnected
2024-01-18 04:02:46,455 - ScraperUtil - ERROR - make_request_to_dou_journal_moreDetail_and_scraping_async: Erro: Server disconnected
2024-01-18 04:02:46,455 - ScraperUtil - ERROR - make_request_to_dou_journal_moreDetail_and_scraping_async: Erro: Server disconnected
2024-01-18 04:02:46,455 - ScraperUtil - ERROR - make_request_to_dou_journal_moreDetail_and_scraping_async: Erro: Server disconnected
2024-01-18 04:02:46,593 - ScraperUtil - ERROR - make_request_to_dou_journal_moreDetail_and_scraping_async: Erro: Server disconnected
2024-01-18 04:02:46,593 - ScraperUtil - ERROR - make_request_to_dou_journal_moreDetail_and_scraping_async: Erro: Server disconnected
2024-01-18 04:02:46,593 - ScraperUtil - ERROR - make_request_to_dou_journal_moreDetail_and_scraping_async: Erro: Server disconnected
2024-01-18 04:02:46,593 - ScraperUtil - ERROR - make_request_to_dou_journal_moreDetail_and_scraping_async: Erro: Server disconnected
2024-01-18 04:02:46,593 - ScraperUtil - ERROR - make_request_to_dou_journal_moreDetail_and_scraping_async: Erro: Server disconnected
2024-01-18 04:02:50,486 - ScraperUtil - ERROR - make_request_to_dou_journal_moreDetail_and_scraping_async: Erro: Server disconnected
2024-01-18 04:02:50,486 - ScraperUtil - ERROR - make_request_to_dou_journal_moreDetail_and_scraping_async: Erro: Server disconnected
2024-01-18 04:02:50,486 - ScraperUtil - ERROR - make_request_to_dou_journal_moreDetail_and_scraping_async: Erro: Server disconnected
2024-01-18 04:02:50,486 - ScraperUtil - ERROR - make_request_to_dou_journal_moreDetail_and_scraping_async: Erro: Server disconnected
2024-01-18 04:02:50,487 - ScraperUtil - ERROR - make_request_to_dou_journal_moreDetail_and_scraping_async: Erro: Server disconnected
2024-01-18 04:02:50,487 - ScraperUtil - ERROR - make_request_to_dou_journal_moreDetail_and_scraping_async: Erro: Server disconnected
2024-01-18 04:02:51,592 - ScraperUtil - ERROR - make_request_to_dou_journal_moreDetail_and_scraping_async: Erro: Server disconnected
2024-01-18 04:02:51,592 - ScraperUtil - ERROR - make_request_to_dou_journal_moreDetail_and_scraping_async: Erro: Server disconnected
2024-01-18 04:02:51,592 - ScraperUtil - ERROR - make_request_to_dou_journal_moreDetail_and_scraping_async: Erro: Server disconnected
2024-01-18 04:02:51,593 - ScraperUtil - ERROR - make_request_to_dou_journal_moreDetail_and_scraping_async: Erro: Server disconnected
2024-01-18 04:02:51,593 - ScraperUtil - ERROR - make_request_to_dou_journal_moreDetail_and_scraping_async: Erro: Server disconnected
2024-01-18 04:02:51,593 - ScraperUtil - ERROR - make_request_to_dou_journal_moreDetail_and_scraping_async: Erro: Server disconnected
2024-01-18 04:02:51,593 - ScraperUtil - ERROR - make_request_to_dou_journal_moreDetail_and_scraping_async: Erro: Server disconnected
2024-01-18 04:02:51,593 - ScraperUtil - ERROR - make_request_to_dou_journal_moreDetail_and_scraping_async: Erro: Server disconnected
2024-01-18 04:02:51,593 - ScraperUtil - ERROR - make_request_to_dou_journal_moreDetail_and_scraping_async: Erro: Server disconnected
2024-01-18 04:02:51,593 - ScraperUtil - ERROR - make_request_to_dou_journal_moreDetail_and_scraping_async: Erro: Server disconnected
2024-01-18 04:02:51,593 - ScraperUtil - ERROR - make_request_to_dou_journal_moreDetail_and_scraping_async: Erro: Server disconnected
2024-01-18 04:02:51,593 - ScraperUtil - ERROR - make_request_to_dou_journal_moreDetail_and_scraping_async: Erro: Server disconnected
2024-01-18 04:02:51,593 - ScraperUtil - ERROR - make_request_to_dou_journal_moreDetail_and_scraping_async: Erro: Server disconnected
2024-01-18 04:02:51,593 - ScraperUtil - ERROR - make_request_to_dou_journal_moreDetail_and_scraping_async: Erro: Server disconnected
2024-01-18 04:02:51,593 - ScraperUtil - ERROR - make_request_to_dou_journal_moreDetail_and_scraping_async: Erro: Server disconnected
2024-01-18 04:02:51,593 - ScraperUtil - ERROR - make_request_to_dou_journal_moreDetail_and_scraping_async: Erro: Server disconnected
2024-01-18 04:02:51,594 - ScraperUtil - ERROR - make_request_to_dou_journal_moreDetail_and_scraping_async: Erro: Server disconnected
2024-01-18 04:02:51,594 - ScraperUtil - ERROR - make_request_to_dou_journal_moreDetail_and_scraping_async: Erro: Server disconnected
2024-01-18 04:02:51,594 - ScraperUtil - ERROR - make_request_to_dou_journal_moreDetail_and_scraping_async: Erro: Server disconnected
2024-01-18 04:02:51,594 - ScraperUtil - ERROR - make_request_to_dou_journal_moreDetail_and_scraping_async: Erro: Server disconnected
2024-01-18 04:02:51,594 - ScraperUtil - ERROR - make_request_to_dou_journal_moreDetail_and_scraping_async: Erro: Server disconnected
2024-01-18 04:02:51,594 - ScraperUtil - ERROR - make_request_to_dou_journal_moreDetail_and_scraping_async: Erro: Server disconnected
2024-01-18 04:02:51,594 - ScraperUtil - ERROR - make_request_to_dou_journal_moreDetail_and_scraping_async: Erro: Server disconnected
2024-01-18 04:02:51,612 - ScraperUtil - ERROR - make_request_to_dou_journal_moreDetail_and_scraping_async: Erro: Server disconnected
2024-01-18 04:02:51,612 - ScraperUtil - ERROR - make_request_to_dou_journal_moreDetail_and_scraping_async: Erro: Server disconnected
2024-01-18 04:02:51,612 - ScraperUtil - ERROR - make_request_to_dou_journal_moreDetail_and_scraping_async: Erro: Server disconnected
2024-01-18 04:02:51,612 - ScraperUtil - ERROR - make_request_to_dou_journal_moreDetail_and_scraping_async: Erro: Server disconnected
2024-01-18 04:02:51,612 - ScraperUtil - ERROR - make_request_to_dou_journal_moreDetail_and_scraping_async: Erro: Server disconnected
2024-01-18 04:02:51,612 - ScraperUtil - ERROR - make_request_to_dou_journal_moreDetail_and_scraping_async: Erro: Server disconnected
2024-01-18 04:02:51,612 - ScraperUtil - ERROR - make_request_to_dou_journal_moreDetail_and_scraping_async: Erro: Server disconnected
2024-01-18 04:02:51,612 - ScraperUtil - ERROR - make_request_to_dou_journal_moreDetail_and_scraping_async: Erro: Server disconnected
2024-01-18 04:02:51,612 - ScraperUtil - ERROR - make_request_to_dou_journal_moreDetail_and_scraping_async: Erro: Server disconnected
2024-01-18 04:02:51,612 - ScraperUtil - ERROR - make_request_to_dou_journal_moreDetail_and_scraping_async: Erro: Server disconnected
2024-01-18 04:02:51,612 - ScraperUtil - ERROR - make_request_to_dou_journal_moreDetail_and_scraping_async: Erro: Server disconnected
2024-01-18 04:02:51,612 - ScraperUtil - ERROR - make_request_to_dou_journal_moreDetail_and_scraping_async: Erro: Server disconnected
2024-01-18 04:02:51,612 - ScraperUtil - ERROR - make_request_to_dou_journal_moreDetail_and_scraping_async: Erro: Server disconnected
2024-01-18 04:02:51,612 - ScraperUtil - ERROR - make_request_to_dou_journal_moreDetail_and_scraping_async: Erro: Server disconnected
2024-01-18 04:02:51,612 - ScraperUtil - ERROR - make_request_to_dou_journal_moreDetail_and_scraping_async: Erro: Server disconnected
2024-01-18 04:02:51,613 - ScraperUtil - ERROR - make_request_to_dou_journal_moreDetail_and_scraping_async: Erro: Server disconnected
2024-01-18 04:02:51,613 - ScraperUtil - ERROR - make_request_to_dou_journal_moreDetail_and_scraping_async: Erro: Server disconnected
2024-01-18 04:02:51,613 - ScraperUtil - ERROR - make_request_to_dou_journal_moreDetail_and_scraping_async: Erro: Server disconnected
2024-01-18 04:02:51,613 - ScraperUtil - ERROR - make_request_to_dou_journal_moreDetail_and_scraping_async: Erro: Server disconnected
2024-01-18 04:02:54,291 - ScraperUtil - ERROR - make_request_to_dou_journal_moreDetail_and_scraping_async: Erro: Server disconnected
2024-01-18 04:02:54,292 - ScraperUtil - ERROR - make_request_to_dou_journal_moreDetail_and_scraping_async: Erro: Server disconnected
2024-01-18 04:02:54,292 - ScraperUtil - ERROR - make_request_to_dou_journal_moreDetail_and_scraping_async: Erro: Server disconnected
2024-01-18 04:02:54,292 - ScraperUtil - ERROR - make_request_to_dou_journal_moreDetail_and_scraping_async: Erro: Server disconnected
2024-01-18 04:02:54,292 - ScraperUtil - ERROR - make_request_to_dou_journal_moreDetail_and_scraping_async: Erro: Server disconnected
2024-01-18 04:02:54,292 - ScraperUtil - ERROR - make_request_to_dou_journal_moreDetail_and_scraping_async: Erro: Server disconnected
2024-01-18 04:02:54,292 - ScraperUtil - ERROR - make_request_to_dou_journal_moreDetail_and_scraping_async: Erro: Server disconnected
2024-01-18 04:02:54,292 - ScraperUtil - ERROR - make_request_to_dou_journal_moreDetail_and_scraping_async: Erro: Server disconnected
2024-01-18 04:02:54,292 - ScraperUtil - ERROR - make_request_to_dou_journal_moreDetail_and_scraping_async: Erro: Server disconnected
2024-01-18 04:02:54,292 - ScraperUtil - ERROR - make_request_to_dou_journal_moreDetail_and_scraping_async: Erro: Server disconnected
2024-01-18 04:02:54,293 - ScraperUtil - ERROR - make_request_to_dou_journal_moreDetail_and_scraping_async: Erro: Server disconnected
2024-01-18 04:02:54,293 - ScraperUtil - ERROR - make_request_to_dou_journal_moreDetail_and_scraping_async: Erro: Server disconnected
2024-01-18 04:02:54,293 - ScraperUtil - ERROR - make_request_to_dou_journal_moreDetail_and_scraping_async: Erro: Server disconnected
2024-01-18 04:02:54,293 - ScraperUtil - ERROR - make_request_to_dou_journal_moreDetail_and_scraping_async: Erro: Server disconnected
2024-01-18 04:02:54,293 - ScraperUtil - ERROR - make_request_to_dou_journal_moreDetail_and_scraping_async: Erro: Server disconnected
2024-01-18 04:02:54,293 - ScraperUtil - ERROR - make_request_to_dou_journal_moreDetail_and_scraping_async: Erro: Server disconnected
2024-01-18 04:02:54,350 - ScraperUtil - ERROR - make_request_to_dou_journal_moreDetail_and_scraping_async: Erro: Server disconnected
2024-01-18 04:02:54,351 - ScraperUtil - ERROR - make_request_to_dou_journal_moreDetail_and_scraping_async: Erro: Server disconnected
2024-01-18 16:02:43,671 - django.utils.autoreload - INFO - /djangoapp/trigger_web_scraping_dou_api/services.py changed, reloading.
2024-01-18 16:08:15,370 - django.utils.autoreload - INFO - /djangoapp/trigger_web_scraping_dou_api/services.py changed, reloading.
2024-01-18 16:08:36,161 - django.utils.autoreload - INFO - /djangoapp/trigger_web_scraping_dou_api/services.py changed, reloading.
2024-01-18 16:11:30,446 - django.request - WARNING - Not Found: /favicon.ico
2024-01-18 16:12:49,847 - django.utils.autoreload - INFO - /djangoapp/trigger_web_scraping_dou_api/services.py changed, reloading.
2024-01-18 16:17:53,773 - django.utils.autoreload - INFO - /djangoapp/trigger_web_scraping_dou_api/services.py changed, reloading.
2024-01-18 16:20:41,706 - ScraperUtil - ERROR - make_request_to_dou_journal_moreDetail_and_scraping_async: Erro: Cannot connect to host www.in.gov.br:443 ssl:default [Connect call failed ('200.198.216.40', 443)]
2024-01-18 16:20:41,707 - ScraperUtil - ERROR - make_request_to_dou_journal_moreDetail_and_scraping_async: Erro: Cannot connect to host www.in.gov.br:443 ssl:default [Connect call failed ('200.198.216.40', 443)]
2024-01-18 16:23:26,306 - django.utils.autoreload - INFO - /djangoapp/trigger_web_scraping_dou_api/services.py changed, reloading.
2024-01-18 16:23:37,505 - django.utils.autoreload - INFO - /djangoapp/trigger_web_scraping_dou_api/services.py changed, reloading.
2024-01-18 16:25:51,458 - django.request - ERROR - Internal Server Error: /trigger_web_scraping_dou_api/
Traceback (most recent call last):
  File "/venv/lib/python3.11/site-packages/urllib3/connection.py", line 174, in _new_conn
    conn = connection.create_connection(
           ^^^^^^^^^^^^^^^^^^^^^^^^^^^^^
  File "/venv/lib/python3.11/site-packages/urllib3/util/connection.py", line 73, in create_connection
    for res in socket.getaddrinfo(host, port, family, socket.SOCK_STREAM):
               ^^^^^^^^^^^^^^^^^^^^^^^^^^^^^^^^^^^^^^^^^^^^^^^^^^^^^^^^^^
  File "/usr/local/lib/python3.11/socket.py", line 962, in getaddrinfo
    for res in _socket.getaddrinfo(host, port, family, type, proto, flags):
               ^^^^^^^^^^^^^^^^^^^^^^^^^^^^^^^^^^^^^^^^^^^^^^^^^^^^^^^^^^^
socket.gaierror: [Errno -3] Try again

During handling of the above exception, another exception occurred:

Traceback (most recent call last):
  File "/venv/lib/python3.11/site-packages/urllib3/connectionpool.py", line 699, in urlopen
    httplib_response = self._make_request(
                       ^^^^^^^^^^^^^^^^^^^
  File "/venv/lib/python3.11/site-packages/urllib3/connectionpool.py", line 382, in _make_request
    self._validate_conn(conn)
  File "/venv/lib/python3.11/site-packages/urllib3/connectionpool.py", line 1010, in _validate_conn
    conn.connect()
  File "/venv/lib/python3.11/site-packages/urllib3/connection.py", line 358, in connect
    conn = self._new_conn()
           ^^^^^^^^^^^^^^^^
  File "/venv/lib/python3.11/site-packages/urllib3/connection.py", line 186, in _new_conn
    raise NewConnectionError(
urllib3.exceptions.NewConnectionError: <urllib3.connection.HTTPSConnection object at 0x7fd4c0d44b50>: Failed to establish a new connection: [Errno -3] Try again

During handling of the above exception, another exception occurred:

Traceback (most recent call last):
  File "/venv/lib/python3.11/site-packages/requests/adapters.py", line 486, in send
    resp = conn.urlopen(
           ^^^^^^^^^^^^^
  File "/venv/lib/python3.11/site-packages/urllib3/connectionpool.py", line 755, in urlopen
    retries = retries.increment(
              ^^^^^^^^^^^^^^^^^^
  File "/venv/lib/python3.11/site-packages/urllib3/util/retry.py", line 574, in increment
    raise MaxRetryError(_pool, url, error or ResponseError(cause))
urllib3.exceptions.MaxRetryError: HTTPSConnectionPool(host='www.in.gov.br', port=443): Max retries exceeded with url: /leiturajornal?data=18-01-2024&secao=do1 (Caused by NewConnectionError('<urllib3.connection.HTTPSConnection object at 0x7fd4c0d44b50>: Failed to establish a new connection: [Errno -3] Try again'))

During handling of the above exception, another exception occurred:

Traceback (most recent call last):
  File "/venv/lib/python3.11/site-packages/django/core/handlers/exception.py", line 55, in inner
    response = get_response(request)
               ^^^^^^^^^^^^^^^^^^^^^
  File "/venv/lib/python3.11/site-packages/django/core/handlers/base.py", line 197, in _get_response
    response = wrapped_callback(request, *callback_args, **callback_kwargs)
               ^^^^^^^^^^^^^^^^^^^^^^^^^^^^^^^^^^^^^^^^^^^^^^^^^^^^^^^^^^^^
  File "/venv/lib/python3.11/site-packages/django/views/decorators/csrf.py", line 56, in wrapper_view
    return view_func(*args, **kwargs)
           ^^^^^^^^^^^^^^^^^^^^^^^^^^
  File "/venv/lib/python3.11/site-packages/django/views/generic/base.py", line 104, in view
    return self.dispatch(request, *args, **kwargs)
           ^^^^^^^^^^^^^^^^^^^^^^^^^^^^^^^^^^^^^^^
  File "/venv/lib/python3.11/site-packages/rest_framework/views.py", line 509, in dispatch
    response = self.handle_exception(exc)
               ^^^^^^^^^^^^^^^^^^^^^^^^^^
  File "/venv/lib/python3.11/site-packages/rest_framework/views.py", line 469, in handle_exception
    self.raise_uncaught_exception(exc)
  File "/venv/lib/python3.11/site-packages/rest_framework/views.py", line 480, in raise_uncaught_exception
    raise exc
  File "/venv/lib/python3.11/site-packages/rest_framework/views.py", line 506, in dispatch
    response = handler(request, *args, **kwargs)
               ^^^^^^^^^^^^^^^^^^^^^^^^^^^^^^^^^
  File "/djangoapp/trigger_web_scraping_dou_api/views.py", line 66, in get
    return self.handle_secaoURLQueryString_single_param(secaoURLQueryString,
          ^^^^^^^^^^^^^^^^^^^^^^^^^^^^^^^^^^^^^^^^^^^^^^^^^^^^^^^^^^^^^^^^^^
  File "/djangoapp/trigger_web_scraping_dou_api/views.py", line 203, in handle_secaoURLQueryString_single_param
    response = ScraperUtil.run_scraper_with_section(secaoURLQueryString_param,
              ^^^^^^^^^^^^^^^^^^^^^^^^^^^^^^^^^^^^^^^^^^^^^^^^^^^^^^^^^^^^^^^^
  File "/djangoapp/trigger_web_scraping_dou_api/scrapers.py", line 231, in run_scraper_with_section
    dou_dontDetails_list_with_jsonArrayField = ScraperUtil.run_dontDetailsPage_scraper(url_param)
                                               ^^^^^^^^^^^^^^^^^^^^^^^^^^^^^^^^^^^^^^^^^^^^^^^^^^
  File "/djangoapp/trigger_web_scraping_dou_api/scrapers.py", line 52, in run_dontDetailsPage_scraper
    response = scraper.get(url_param)
               ^^^^^^^^^^^^^^^^^^^^^^
  File "/venv/lib/python3.11/site-packages/requests/sessions.py", line 602, in get
    return self.request("GET", url, **kwargs)
           ^^^^^^^^^^^^^^^^^^^^^^^^^^^^^^^^^^
  File "/venv/lib/python3.11/site-packages/cfscrape/__init__.py", line 121, in request
    resp = super(CloudflareScraper, self).request(method, url, *args, **kwargs)
           ^^^^^^^^^^^^^^^^^^^^^^^^^^^^^^^^^^^^^^^^^^^^^^^^^^^^^^^^^^^^^^^^^^^^
  File "/venv/lib/python3.11/site-packages/requests/sessions.py", line 589, in request
    resp = self.send(prep, **send_kwargs)
           ^^^^^^^^^^^^^^^^^^^^^^^^^^^^^^
  File "/venv/lib/python3.11/site-packages/requests/sessions.py", line 703, in send
    r = adapter.send(request, **kwargs)
        ^^^^^^^^^^^^^^^^^^^^^^^^^^^^^^^
  File "/venv/lib/python3.11/site-packages/requests/adapters.py", line 519, in send
    raise ConnectionError(e, request=request)
requests.exceptions.ConnectionError: HTTPSConnectionPool(host='www.in.gov.br', port=443): Max retries exceeded with url: /leiturajornal?data=18-01-2024&secao=do1 (Caused by NewConnectionError('<urllib3.connection.HTTPSConnection object at 0x7fd4c0d44b50>: Failed to establish a new connection: [Errno -3] Try again'))
2024-01-18 16:28:23,346 - django.request - WARNING - Not Found: /favicon.ico
2024-01-18 17:25:14,686 - django.utils.autoreload - INFO - /djangoapp/trigger_web_scraping_dou_api/services.py changed, reloading.
2024-01-18 17:28:50,129 - django.request - WARNING - Not Found: /favicon.ico
2024-01-18 17:32:53,010 - django.utils.autoreload - INFO - /djangoapp/trigger_web_scraping_dou_api/services.py changed, reloading.
2024-01-18 17:36:53,380 - django.request - WARNING - Not Found: /favicon.ico
2024-01-18 17:43:26,612 - django.utils.autoreload - INFO - /djangoapp/trigger_web_scraping_dou_api/services.py changed, reloading.
2024-01-18 17:46:51,337 - django.request - WARNING - Not Found: /favicon.ico
2024-01-18 17:52:04,096 - django.utils.autoreload - INFO - /djangoapp/trigger_web_scraping_dou_api/models.py changed, reloading.
2024-01-18 17:53:48,969 - django.utils.autoreload - INFO - /djangoapp/trigger_web_scraping_dou_api/models.py changed, reloading.
2024-01-18 17:53:55,022 - django.utils.autoreload - INFO - /djangoapp/trigger_web_scraping_dou_api/models.py changed, reloading.
2024-01-18 17:57:32,746 - django.request - WARNING - Not Found: /favicon.ico
2024-01-18 17:59:17,952 - django.request - WARNING - Not Found: /db_dou_api/detailsinglejournalofdouviewset/
2024-01-18 17:59:21,697 - django.request - WARNING - Not Found: /db_dou_api/detailsinglejournalofdouviewset/
2024-01-18 17:59:26,475 - django.request - WARNING - Not Found: /db_dou_api/detailsinglejournalofdouviewset/
2024-01-18 18:01:42,202 - django.utils.autoreload - INFO - /djangoapp/trigger_web_scraping_dou_api/services.py changed, reloading.
2024-01-18 18:06:31,230 - django.utils.autoreload - INFO - /djangoapp/trigger_web_scraping_dou_api/services.py changed, reloading.
2024-01-18 18:17:45,014 - django.request - WARNING - Not Found: /favicon.ico
2024-01-18 18:24:14,184 - django.utils.autoreload - INFO - /djangoapp/trigger_web_scraping_dou_api/services.py changed, reloading.
2024-01-18 18:26:14,253 - django.request - WARNING - Not Found: /favicon.ico
2024-01-18 18:27:14,872 - django.utils.autoreload - INFO - /djangoapp/trigger_web_scraping_dou_api/services.py changed, reloading.
2024-01-18 18:30:38,052 - django.utils.autoreload - INFO - /djangoapp/trigger_web_scraping_dou_api/services.py changed, reloading.
2024-01-18 18:35:32,091 - django.utils.autoreload - INFO - /djangoapp/trigger_web_scraping_dou_api/services.py changed, reloading.
2024-01-18 18:42:59,938 - django.utils.autoreload - INFO - /djangoapp/trigger_web_scraping_dou_api/services.py changed, reloading.
2024-01-18 18:43:06,380 - django.utils.autoreload - INFO - /djangoapp/trigger_web_scraping_dou_api/services.py changed, reloading.
2024-01-18 18:45:37,266 - django.utils.autoreload - INFO - /djangoapp/trigger_web_scraping_dou_api/services.py changed, reloading.
2024-01-18 19:02:04,631 - django.request - ERROR - Internal Server Error: /trigger_web_scraping_dou_api/
Traceback (most recent call last):
  File "/venv/lib/python3.11/site-packages/django/core/handlers/exception.py", line 55, in inner
    response = get_response(request)
               ^^^^^^^^^^^^^^^^^^^^^
  File "/venv/lib/python3.11/site-packages/django/core/handlers/base.py", line 197, in _get_response
    response = wrapped_callback(request, *callback_args, **callback_kwargs)
               ^^^^^^^^^^^^^^^^^^^^^^^^^^^^^^^^^^^^^^^^^^^^^^^^^^^^^^^^^^^^
  File "/venv/lib/python3.11/site-packages/django/views/decorators/csrf.py", line 56, in wrapper_view
    return view_func(*args, **kwargs)
           ^^^^^^^^^^^^^^^^^^^^^^^^^^
  File "/venv/lib/python3.11/site-packages/django/views/generic/base.py", line 104, in view
    return self.dispatch(request, *args, **kwargs)
           ^^^^^^^^^^^^^^^^^^^^^^^^^^^^^^^^^^^^^^^
  File "/venv/lib/python3.11/site-packages/rest_framework/views.py", line 509, in dispatch
    response = self.handle_exception(exc)
               ^^^^^^^^^^^^^^^^^^^^^^^^^^
  File "/venv/lib/python3.11/site-packages/rest_framework/views.py", line 469, in handle_exception
    self.raise_uncaught_exception(exc)
  File "/venv/lib/python3.11/site-packages/rest_framework/views.py", line 480, in raise_uncaught_exception
    raise exc
  File "/venv/lib/python3.11/site-packages/rest_framework/views.py", line 506, in dispatch
    response = handler(request, *args, **kwargs)
               ^^^^^^^^^^^^^^^^^^^^^^^^^^^^^^^^^
  File "/djangoapp/trigger_web_scraping_dou_api/views.py", line 58, in get
    return self.handle_URL_empty_params(saveInDBFlag, detailDOUJournalFlag)
           ^^^^^^^^^^^^^^^^^^^^^^^^^^^^^^^^^^^^^^^^^^^^^^^^^^^^^^^^^^^^^^^^
  File "/djangoapp/trigger_web_scraping_dou_api/views.py", line 192, in handle_URL_empty_params
    response = ScraperUtil.run_scraper_with_empty_params_using_clone_instances(detailDOUJournalFlag)
               ^^^^^^^^^^^^^^^^^^^^^^^^^^^^^^^^^^^^^^^^^^^^^^^^^^^^^^^^^^^^^^^^^^^^^^^^^^^^^^^^^^^^^
  File "/djangoapp/trigger_web_scraping_dou_api/scrapers.py", line 292, in run_scraper_with_empty_params_using_clone_instances
    return ScraperUtil.run_scraper_using_clone_instances_when_secao_do1_do2_and_do3(date_now_db_and_brazilian_format,
          ^^^^^^^^^^^^^^^^^^^^^^^^^^^^^^^^^^^^^^^^^^^^^^^^^^^^^^^^^^^^^^^^^^^^^^^^^^^^^^^^^^^^^^^^^^^^^^^^^^^^^^^^^^^
  File "/djangoapp/trigger_web_scraping_dou_api/scrapers.py", line 334, in run_scraper_using_clone_instances_when_secao_do1_do2_and_do3
    all_dous_response = list(executor.map(ScraperUtil.make_request_for_others_clone_api,
                       ^^^^^^^^^^^^^^^^^^^^^^^^^^^^^^^^^^^^^^^^^^^^^^^^^^^^^^^^^^^^^^^^^
  File "/usr/local/lib/python3.11/concurrent/futures/_base.py", line 619, in result_iterator
    yield _result_or_cancel(fs.pop())
          ^^^^^^^^^^^^^^^^^^^^^^^^^^^
  File "/usr/local/lib/python3.11/concurrent/futures/_base.py", line 317, in _result_or_cancel
    return fut.result(timeout)
           ^^^^^^^^^^^^^^^^^^^
  File "/usr/local/lib/python3.11/concurrent/futures/_base.py", line 456, in result
    return self.__get_result()
           ^^^^^^^^^^^^^^^^^^^
  File "/usr/local/lib/python3.11/concurrent/futures/_base.py", line 401, in __get_result
    raise self._exception
  File "/usr/local/lib/python3.11/concurrent/futures/thread.py", line 58, in run
    result = self.fn(*self.args, **self.kwargs)
             ^^^^^^^^^^^^^^^^^^^^^^^^^^^^^^^^^^
  File "/djangoapp/trigger_web_scraping_dou_api/scrapers.py", line 351, in make_request_for_others_clone_api
    raise Exception(f"Erro na requisição para {url}. Status code: {response.status_code}")
Exception: Erro na requisição para http://djangoappcloneone:8001/trigger_web_scraping_dou_api/?secao=do1&data=18-01-2024&detailDOUJournalFlag=True. Status code: 500
2024-01-18 19:03:18,025 - django.request - WARNING - Not Found: /favicon.ico
2024-01-18 19:04:22,611 - django.utils.autoreload - INFO - /djangoapp/trigger_web_scraping_dou_api/services.py changed, reloading.
2024-01-18 19:04:43,172 - django.utils.autoreload - INFO - /djangoapp/trigger_web_scraping_dou_api/services.py changed, reloading.
2024-01-18 19:50:12,529 - django.request - WARNING - Not Found: /favicon.ico
2024-01-18 20:32:02,327 - django.request - WARNING - Not Found: /favicon.ico
2024-01-18 20:45:33,163 - django.request - WARNING - Not Found: /favicon.ico
2024-01-18 20:48:42,441 - django.request - WARNING - Not Found: /favicon.ico
2024-01-18 22:58:21,707 - django.utils.autoreload - INFO - /djangoapp/trigger_web_scraping_dou_api/scrapers.py changed, reloading.
2024-01-18 23:46:00,191 - django.request - ERROR - Internal Server Error: /trigger_web_scraping_dou_api/
Traceback (most recent call last):
  File "/venv/lib/python3.11/site-packages/django/core/handlers/exception.py", line 55, in inner
    response = get_response(request)
               ^^^^^^^^^^^^^^^^^^^^^
  File "/venv/lib/python3.11/site-packages/django/core/handlers/base.py", line 197, in _get_response
    response = wrapped_callback(request, *callback_args, **callback_kwargs)
               ^^^^^^^^^^^^^^^^^^^^^^^^^^^^^^^^^^^^^^^^^^^^^^^^^^^^^^^^^^^^
  File "/venv/lib/python3.11/site-packages/django/views/decorators/csrf.py", line 56, in wrapper_view
    return view_func(*args, **kwargs)
           ^^^^^^^^^^^^^^^^^^^^^^^^^^
  File "/venv/lib/python3.11/site-packages/django/views/generic/base.py", line 104, in view
    return self.dispatch(request, *args, **kwargs)
           ^^^^^^^^^^^^^^^^^^^^^^^^^^^^^^^^^^^^^^^
  File "/venv/lib/python3.11/site-packages/rest_framework/views.py", line 509, in dispatch
    response = self.handle_exception(exc)
               ^^^^^^^^^^^^^^^^^^^^^^^^^^
  File "/venv/lib/python3.11/site-packages/rest_framework/views.py", line 469, in handle_exception
    self.raise_uncaught_exception(exc)
  File "/venv/lib/python3.11/site-packages/rest_framework/views.py", line 480, in raise_uncaught_exception
    raise exc
  File "/venv/lib/python3.11/site-packages/rest_framework/views.py", line 506, in dispatch
    response = handler(request, *args, **kwargs)
               ^^^^^^^^^^^^^^^^^^^^^^^^^^^^^^^^^
  File "/djangoapp/trigger_web_scraping_dou_api/views.py", line 58, in get
    return self.handle_URL_empty_params(saveInDBFlag, detailDOUJournalFlag)
           ^^^^^^^^^^^^^^^^^^^^^^^^^^^^^^^^^^^^^^^^^^^^^^^^^^^^^^^^^^^^^^^^
  File "/djangoapp/trigger_web_scraping_dou_api/views.py", line 192, in handle_URL_empty_params
    response = ScraperUtil.run_scraper_with_empty_params_using_clone_instances(detailDOUJournalFlag)
               ^^^^^^^^^^^^^^^^^^^^^^^^^^^^^^^^^^^^^^^^^^^^^^^^^^^^^^^^^^^^^^^^^^^^^^^^^^^^^^^^^^^^^
  File "/djangoapp/trigger_web_scraping_dou_api/scrapers.py", line 292, in run_scraper_with_empty_params_using_clone_instances
    return ScraperUtil.run_scraper_using_clone_instances_when_secao_do1_do2_and_do3(date_now_db_and_brazilian_format,
          ^^^^^^^^^^^^^^^^^^^^^^^^^^^^^^^^^^^^^^^^^^^^^^^^^^^^^^^^^^^^^^^^^^^^^^^^^^^^^^^^^^^^^^^^^^^^^^^^^^^^^^^^^^^
  File "/djangoapp/trigger_web_scraping_dou_api/scrapers.py", line 334, in run_scraper_using_clone_instances_when_secao_do1_do2_and_do3
    all_dous_response = list(executor.map(ScraperUtil.make_request_for_others_clone_api,
                       ^^^^^^^^^^^^^^^^^^^^^^^^^^^^^^^^^^^^^^^^^^^^^^^^^^^^^^^^^^^^^^^^^
  File "/usr/local/lib/python3.11/concurrent/futures/_base.py", line 619, in result_iterator
    yield _result_or_cancel(fs.pop())
          ^^^^^^^^^^^^^^^^^^^^^^^^^^^
  File "/usr/local/lib/python3.11/concurrent/futures/_base.py", line 317, in _result_or_cancel
    return fut.result(timeout)
           ^^^^^^^^^^^^^^^^^^^
  File "/usr/local/lib/python3.11/concurrent/futures/_base.py", line 456, in result
    return self.__get_result()
           ^^^^^^^^^^^^^^^^^^^
  File "/usr/local/lib/python3.11/concurrent/futures/_base.py", line 401, in __get_result
    raise self._exception
  File "/usr/local/lib/python3.11/concurrent/futures/thread.py", line 58, in run
    result = self.fn(*self.args, **self.kwargs)
             ^^^^^^^^^^^^^^^^^^^^^^^^^^^^^^^^^^
  File "/djangoapp/trigger_web_scraping_dou_api/scrapers.py", line 351, in make_request_for_others_clone_api
    raise Exception(f"Erro na requisição para {url}. Status code: {response.status_code}")
Exception: Erro na requisição para http://djangoappcloneone:8001/trigger_web_scraping_dou_api/?secao=do1&data=18-01-2024&detailDOUJournalFlag=True. Status code: 500
2024-01-18 23:59:24,973 - django.request - ERROR - Internal Server Error: /trigger_web_scraping_dou_api/
Traceback (most recent call last):
  File "/venv/lib/python3.11/site-packages/urllib3/connection.py", line 174, in _new_conn
    conn = connection.create_connection(
           ^^^^^^^^^^^^^^^^^^^^^^^^^^^^^
  File "/venv/lib/python3.11/site-packages/urllib3/util/connection.py", line 96, in create_connection
    raise err
  File "/venv/lib/python3.11/site-packages/urllib3/util/connection.py", line 86, in create_connection
    sock.connect(sa)
ConnectionRefusedError: [Errno 111] Connection refused

During handling of the above exception, another exception occurred:

Traceback (most recent call last):
  File "/venv/lib/python3.11/site-packages/urllib3/connectionpool.py", line 699, in urlopen
    httplib_response = self._make_request(
                       ^^^^^^^^^^^^^^^^^^^
  File "/venv/lib/python3.11/site-packages/urllib3/connectionpool.py", line 394, in _make_request
    conn.request(method, url, **httplib_request_kw)
  File "/venv/lib/python3.11/site-packages/urllib3/connection.py", line 239, in request
    super(HTTPConnection, self).request(method, url, body=body, headers=headers)
  File "/usr/local/lib/python3.11/http/client.py", line 1283, in request
    self._send_request(method, url, body, headers, encode_chunked)
  File "/usr/local/lib/python3.11/http/client.py", line 1329, in _send_request
    self.endheaders(body, encode_chunked=encode_chunked)
  File "/usr/local/lib/python3.11/http/client.py", line 1278, in endheaders
    self._send_output(message_body, encode_chunked=encode_chunked)
  File "/usr/local/lib/python3.11/http/client.py", line 1038, in _send_output
    self.send(msg)
  File "/usr/local/lib/python3.11/http/client.py", line 976, in send
    self.connect()
  File "/venv/lib/python3.11/site-packages/urllib3/connection.py", line 205, in connect
    conn = self._new_conn()
           ^^^^^^^^^^^^^^^^
  File "/venv/lib/python3.11/site-packages/urllib3/connection.py", line 186, in _new_conn
    raise NewConnectionError(
urllib3.exceptions.NewConnectionError: <urllib3.connection.HTTPConnection object at 0x7f4d98c740d0>: Failed to establish a new connection: [Errno 111] Connection refused

During handling of the above exception, another exception occurred:

Traceback (most recent call last):
  File "/venv/lib/python3.11/site-packages/requests/adapters.py", line 486, in send
    resp = conn.urlopen(
           ^^^^^^^^^^^^^
  File "/venv/lib/python3.11/site-packages/urllib3/connectionpool.py", line 755, in urlopen
    retries = retries.increment(
              ^^^^^^^^^^^^^^^^^^
  File "/venv/lib/python3.11/site-packages/urllib3/util/retry.py", line 574, in increment
    raise MaxRetryError(_pool, url, error or ResponseError(cause))
urllib3.exceptions.MaxRetryError: HTTPConnectionPool(host='djangoappclonethree', port=8003): Max retries exceeded with url: /trigger_web_scraping_dou_api/?secao=do3&data=18-01-2024&detailDOUJournalFlag=True (Caused by NewConnectionError('<urllib3.connection.HTTPConnection object at 0x7f4d98c740d0>: Failed to establish a new connection: [Errno 111] Connection refused'))

During handling of the above exception, another exception occurred:

Traceback (most recent call last):
  File "/venv/lib/python3.11/site-packages/django/core/handlers/exception.py", line 55, in inner
    response = get_response(request)
               ^^^^^^^^^^^^^^^^^^^^^
  File "/venv/lib/python3.11/site-packages/django/core/handlers/base.py", line 197, in _get_response
    response = wrapped_callback(request, *callback_args, **callback_kwargs)
               ^^^^^^^^^^^^^^^^^^^^^^^^^^^^^^^^^^^^^^^^^^^^^^^^^^^^^^^^^^^^
  File "/venv/lib/python3.11/site-packages/django/views/decorators/csrf.py", line 56, in wrapper_view
    return view_func(*args, **kwargs)
           ^^^^^^^^^^^^^^^^^^^^^^^^^^
  File "/venv/lib/python3.11/site-packages/django/views/generic/base.py", line 104, in view
    return self.dispatch(request, *args, **kwargs)
           ^^^^^^^^^^^^^^^^^^^^^^^^^^^^^^^^^^^^^^^
  File "/venv/lib/python3.11/site-packages/rest_framework/views.py", line 509, in dispatch
    response = self.handle_exception(exc)
               ^^^^^^^^^^^^^^^^^^^^^^^^^^
  File "/venv/lib/python3.11/site-packages/rest_framework/views.py", line 469, in handle_exception
    self.raise_uncaught_exception(exc)
  File "/venv/lib/python3.11/site-packages/rest_framework/views.py", line 480, in raise_uncaught_exception
    raise exc
  File "/venv/lib/python3.11/site-packages/rest_framework/views.py", line 506, in dispatch
    response = handler(request, *args, **kwargs)
               ^^^^^^^^^^^^^^^^^^^^^^^^^^^^^^^^^
  File "/djangoapp/trigger_web_scraping_dou_api/views.py", line 58, in get
    return self.handle_URL_empty_params(saveInDBFlag, detailDOUJournalFlag)
           ^^^^^^^^^^^^^^^^^^^^^^^^^^^^^^^^^^^^^^^^^^^^^^^^^^^^^^^^^^^^^^^^
  File "/djangoapp/trigger_web_scraping_dou_api/views.py", line 192, in handle_URL_empty_params
    response = ScraperUtil.run_scraper_with_empty_params_using_clone_instances(detailDOUJournalFlag)
               ^^^^^^^^^^^^^^^^^^^^^^^^^^^^^^^^^^^^^^^^^^^^^^^^^^^^^^^^^^^^^^^^^^^^^^^^^^^^^^^^^^^^^
  File "/djangoapp/trigger_web_scraping_dou_api/scrapers.py", line 292, in run_scraper_with_empty_params_using_clone_instances
    return ScraperUtil.run_scraper_using_clone_instances_when_secao_do1_do2_and_do3(date_now_db_and_brazilian_format,
          ^^^^^^^^^^^^^^^^^^^^^^^^^^^^^^^^^^^^^^^^^^^^^^^^^^^^^^^^^^^^^^^^^^^^^^^^^^^^^^^^^^^^^^^^^^^^^^^^^^^^^^^^^^^
  File "/djangoapp/trigger_web_scraping_dou_api/scrapers.py", line 334, in run_scraper_using_clone_instances_when_secao_do1_do2_and_do3
    all_dous_response = list(executor.map(ScraperUtil.make_request_for_others_clone_api,
                       ^^^^^^^^^^^^^^^^^^^^^^^^^^^^^^^^^^^^^^^^^^^^^^^^^^^^^^^^^^^^^^^^^
  File "/usr/local/lib/python3.11/concurrent/futures/_base.py", line 619, in result_iterator
    yield _result_or_cancel(fs.pop())
          ^^^^^^^^^^^^^^^^^^^^^^^^^^^
  File "/usr/local/lib/python3.11/concurrent/futures/_base.py", line 317, in _result_or_cancel
    return fut.result(timeout)
           ^^^^^^^^^^^^^^^^^^^
  File "/usr/local/lib/python3.11/concurrent/futures/_base.py", line 449, in result
    return self.__get_result()
           ^^^^^^^^^^^^^^^^^^^
  File "/usr/local/lib/python3.11/concurrent/futures/_base.py", line 401, in __get_result
    raise self._exception
  File "/usr/local/lib/python3.11/concurrent/futures/thread.py", line 58, in run
    result = self.fn(*self.args, **self.kwargs)
             ^^^^^^^^^^^^^^^^^^^^^^^^^^^^^^^^^^
  File "/djangoapp/trigger_web_scraping_dou_api/scrapers.py", line 344, in make_request_for_others_clone_api
    response = requests.get(url)
               ^^^^^^^^^^^^^^^^^
  File "/venv/lib/python3.11/site-packages/requests/api.py", line 73, in get
    return request("get", url, params=params, **kwargs)
           ^^^^^^^^^^^^^^^^^^^^^^^^^^^^^^^^^^^^^^^^^^^^
  File "/venv/lib/python3.11/site-packages/requests/api.py", line 59, in request
    return session.request(method=method, url=url, **kwargs)
           ^^^^^^^^^^^^^^^^^^^^^^^^^^^^^^^^^^^^^^^^^^^^^^^^^
  File "/venv/lib/python3.11/site-packages/requests/sessions.py", line 589, in request
    resp = self.send(prep, **send_kwargs)
           ^^^^^^^^^^^^^^^^^^^^^^^^^^^^^^
  File "/venv/lib/python3.11/site-packages/requests/sessions.py", line 703, in send
    r = adapter.send(request, **kwargs)
        ^^^^^^^^^^^^^^^^^^^^^^^^^^^^^^^
  File "/venv/lib/python3.11/site-packages/requests/adapters.py", line 519, in send
    raise ConnectionError(e, request=request)
requests.exceptions.ConnectionError: HTTPConnectionPool(host='djangoappclonethree', port=8003): Max retries exceeded with url: /trigger_web_scraping_dou_api/?secao=do3&data=18-01-2024&detailDOUJournalFlag=True (Caused by NewConnectionError('<urllib3.connection.HTTPConnection object at 0x7f4d98c740d0>: Failed to establish a new connection: [Errno 111] Connection refused'))
2024-01-19 01:17:10,885 - django.utils.autoreload - INFO - /djangoapp/trigger_web_scraping_dou_api/services.py changed, reloading.
2024-01-19 01:18:18,329 - django.request - ERROR - Internal Server Error: /trigger_web_scraping_dou_api/
Traceback (most recent call last):
  File "/venv/lib/python3.11/site-packages/django/core/handlers/exception.py", line 55, in inner
    response = get_response(request)
               ^^^^^^^^^^^^^^^^^^^^^
  File "/venv/lib/python3.11/site-packages/django/core/handlers/base.py", line 197, in _get_response
    response = wrapped_callback(request, *callback_args, **callback_kwargs)
               ^^^^^^^^^^^^^^^^^^^^^^^^^^^^^^^^^^^^^^^^^^^^^^^^^^^^^^^^^^^^
  File "/venv/lib/python3.11/site-packages/django/views/decorators/csrf.py", line 56, in wrapper_view
    return view_func(*args, **kwargs)
           ^^^^^^^^^^^^^^^^^^^^^^^^^^
  File "/venv/lib/python3.11/site-packages/django/views/generic/base.py", line 104, in view
    return self.dispatch(request, *args, **kwargs)
           ^^^^^^^^^^^^^^^^^^^^^^^^^^^^^^^^^^^^^^^
  File "/venv/lib/python3.11/site-packages/rest_framework/views.py", line 509, in dispatch
    response = self.handle_exception(exc)
               ^^^^^^^^^^^^^^^^^^^^^^^^^^
  File "/venv/lib/python3.11/site-packages/rest_framework/views.py", line 469, in handle_exception
    self.raise_uncaught_exception(exc)
  File "/venv/lib/python3.11/site-packages/rest_framework/views.py", line 480, in raise_uncaught_exception
    raise exc
  File "/venv/lib/python3.11/site-packages/rest_framework/views.py", line 506, in dispatch
    response = handler(request, *args, **kwargs)
               ^^^^^^^^^^^^^^^^^^^^^^^^^^^^^^^^^
  File "/djangoapp/trigger_web_scraping_dou_api/views.py", line 58, in get
    return self.handle_URL_empty_params(saveInDBFlag, detailDOUJournalFlag)
           ^^^^^^^^^^^^^^^^^^^^^^^^^^^^^^^^^^^^^^^^^^^^^^^^^^^^^^^^^^^^^^^^
  File "/djangoapp/trigger_web_scraping_dou_api/views.py", line 192, in handle_URL_empty_params
    response = ScraperUtil.run_scraper_with_empty_params_using_clone_instances(detailDOUJournalFlag)
               ^^^^^^^^^^^^^^^^^^^^^^^^^^^^^^^^^^^^^^^^^^^^^^^^^^^^^^^^^^^^^^^^^^^^^^^^^^^^^^^^^^^^^
  File "/djangoapp/trigger_web_scraping_dou_api/scrapers.py", line 292, in run_scraper_with_empty_params_using_clone_instances
    return ScraperUtil.run_scraper_using_clone_instances_when_secao_do1_do2_and_do3(date_now_db_and_brazilian_format,
          ^^^^^^^^^^^^^^^^^^^^^^^^^^^^^^^^^^^^^^^^^^^^^^^^^^^^^^^^^^^^^^^^^^^^^^^^^^^^^^^^^^^^^^^^^^^^^^^^^^^^^^^^^^^
  File "/djangoapp/trigger_web_scraping_dou_api/scrapers.py", line 334, in run_scraper_using_clone_instances_when_secao_do1_do2_and_do3
    all_dous_response = list(executor.map(ScraperUtil.make_request_for_others_clone_api,
                       ^^^^^^^^^^^^^^^^^^^^^^^^^^^^^^^^^^^^^^^^^^^^^^^^^^^^^^^^^^^^^^^^^
  File "/usr/local/lib/python3.11/concurrent/futures/_base.py", line 619, in result_iterator
    yield _result_or_cancel(fs.pop())
          ^^^^^^^^^^^^^^^^^^^^^^^^^^^
  File "/usr/local/lib/python3.11/concurrent/futures/_base.py", line 317, in _result_or_cancel
    return fut.result(timeout)
           ^^^^^^^^^^^^^^^^^^^
  File "/usr/local/lib/python3.11/concurrent/futures/_base.py", line 456, in result
    return self.__get_result()
           ^^^^^^^^^^^^^^^^^^^
  File "/usr/local/lib/python3.11/concurrent/futures/_base.py", line 401, in __get_result
    raise self._exception
  File "/usr/local/lib/python3.11/concurrent/futures/thread.py", line 58, in run
    result = self.fn(*self.args, **self.kwargs)
             ^^^^^^^^^^^^^^^^^^^^^^^^^^^^^^^^^^
  File "/djangoapp/trigger_web_scraping_dou_api/scrapers.py", line 351, in make_request_for_others_clone_api
    raise Exception(f"Erro na requisição para {url}. Status code: {response.status_code}")
Exception: Erro na requisição para http://djangoappcloneone:8001/trigger_web_scraping_dou_api/?secao=do1&data=19-01-2024&detailDOUJournalFlag=True. Status code: 500
2024-01-19 01:19:18,216 - django.request - ERROR - Internal Server Error: /trigger_web_scraping_dou_api/
Traceback (most recent call last):
  File "/venv/lib/python3.11/site-packages/django/core/handlers/exception.py", line 55, in inner
    response = get_response(request)
               ^^^^^^^^^^^^^^^^^^^^^
  File "/venv/lib/python3.11/site-packages/django/core/handlers/base.py", line 197, in _get_response
    response = wrapped_callback(request, *callback_args, **callback_kwargs)
               ^^^^^^^^^^^^^^^^^^^^^^^^^^^^^^^^^^^^^^^^^^^^^^^^^^^^^^^^^^^^
  File "/venv/lib/python3.11/site-packages/django/views/decorators/csrf.py", line 56, in wrapper_view
    return view_func(*args, **kwargs)
           ^^^^^^^^^^^^^^^^^^^^^^^^^^
  File "/venv/lib/python3.11/site-packages/django/views/generic/base.py", line 104, in view
    return self.dispatch(request, *args, **kwargs)
           ^^^^^^^^^^^^^^^^^^^^^^^^^^^^^^^^^^^^^^^
  File "/venv/lib/python3.11/site-packages/rest_framework/views.py", line 509, in dispatch
    response = self.handle_exception(exc)
               ^^^^^^^^^^^^^^^^^^^^^^^^^^
  File "/venv/lib/python3.11/site-packages/rest_framework/views.py", line 469, in handle_exception
    self.raise_uncaught_exception(exc)
  File "/venv/lib/python3.11/site-packages/rest_framework/views.py", line 480, in raise_uncaught_exception
    raise exc
  File "/venv/lib/python3.11/site-packages/rest_framework/views.py", line 506, in dispatch
    response = handler(request, *args, **kwargs)
               ^^^^^^^^^^^^^^^^^^^^^^^^^^^^^^^^^
  File "/djangoapp/trigger_web_scraping_dou_api/views.py", line 58, in get
    return self.handle_URL_empty_params(saveInDBFlag, detailDOUJournalFlag)
           ^^^^^^^^^^^^^^^^^^^^^^^^^^^^^^^^^^^^^^^^^^^^^^^^^^^^^^^^^^^^^^^^
  File "/djangoapp/trigger_web_scraping_dou_api/views.py", line 192, in handle_URL_empty_params
    response = ScraperUtil.run_scraper_with_empty_params_using_clone_instances(detailDOUJournalFlag)
               ^^^^^^^^^^^^^^^^^^^^^^^^^^^^^^^^^^^^^^^^^^^^^^^^^^^^^^^^^^^^^^^^^^^^^^^^^^^^^^^^^^^^^
  File "/djangoapp/trigger_web_scraping_dou_api/scrapers.py", line 292, in run_scraper_with_empty_params_using_clone_instances
    return ScraperUtil.run_scraper_using_clone_instances_when_secao_do1_do2_and_do3(date_now_db_and_brazilian_format,
          ^^^^^^^^^^^^^^^^^^^^^^^^^^^^^^^^^^^^^^^^^^^^^^^^^^^^^^^^^^^^^^^^^^^^^^^^^^^^^^^^^^^^^^^^^^^^^^^^^^^^^^^^^^^
  File "/djangoapp/trigger_web_scraping_dou_api/scrapers.py", line 334, in run_scraper_using_clone_instances_when_secao_do1_do2_and_do3
    all_dous_response = list(executor.map(ScraperUtil.make_request_for_others_clone_api,
                       ^^^^^^^^^^^^^^^^^^^^^^^^^^^^^^^^^^^^^^^^^^^^^^^^^^^^^^^^^^^^^^^^^
  File "/usr/local/lib/python3.11/concurrent/futures/_base.py", line 619, in result_iterator
    yield _result_or_cancel(fs.pop())
          ^^^^^^^^^^^^^^^^^^^^^^^^^^^
  File "/usr/local/lib/python3.11/concurrent/futures/_base.py", line 317, in _result_or_cancel
    return fut.result(timeout)
           ^^^^^^^^^^^^^^^^^^^
  File "/usr/local/lib/python3.11/concurrent/futures/_base.py", line 456, in result
    return self.__get_result()
           ^^^^^^^^^^^^^^^^^^^
  File "/usr/local/lib/python3.11/concurrent/futures/_base.py", line 401, in __get_result
    raise self._exception
  File "/usr/local/lib/python3.11/concurrent/futures/thread.py", line 58, in run
    result = self.fn(*self.args, **self.kwargs)
             ^^^^^^^^^^^^^^^^^^^^^^^^^^^^^^^^^^
  File "/djangoapp/trigger_web_scraping_dou_api/scrapers.py", line 351, in make_request_for_others_clone_api
    raise Exception(f"Erro na requisição para {url}. Status code: {response.status_code}")
Exception: Erro na requisição para http://djangoappcloneone:8001/trigger_web_scraping_dou_api/?secao=do1&data=19-01-2024&detailDOUJournalFlag=True. Status code: 500
2024-01-19 01:20:36,603 - django.request - ERROR - Internal Server Error: /trigger_web_scraping_dou_api/
Traceback (most recent call last):
  File "/venv/lib/python3.11/site-packages/django/core/handlers/exception.py", line 55, in inner
    response = get_response(request)
               ^^^^^^^^^^^^^^^^^^^^^
  File "/venv/lib/python3.11/site-packages/django/core/handlers/base.py", line 197, in _get_response
    response = wrapped_callback(request, *callback_args, **callback_kwargs)
               ^^^^^^^^^^^^^^^^^^^^^^^^^^^^^^^^^^^^^^^^^^^^^^^^^^^^^^^^^^^^
  File "/venv/lib/python3.11/site-packages/django/views/decorators/csrf.py", line 56, in wrapper_view
    return view_func(*args, **kwargs)
           ^^^^^^^^^^^^^^^^^^^^^^^^^^
  File "/venv/lib/python3.11/site-packages/django/views/generic/base.py", line 104, in view
    return self.dispatch(request, *args, **kwargs)
           ^^^^^^^^^^^^^^^^^^^^^^^^^^^^^^^^^^^^^^^
  File "/venv/lib/python3.11/site-packages/rest_framework/views.py", line 509, in dispatch
    response = self.handle_exception(exc)
               ^^^^^^^^^^^^^^^^^^^^^^^^^^
  File "/venv/lib/python3.11/site-packages/rest_framework/views.py", line 469, in handle_exception
    self.raise_uncaught_exception(exc)
  File "/venv/lib/python3.11/site-packages/rest_framework/views.py", line 480, in raise_uncaught_exception
    raise exc
  File "/venv/lib/python3.11/site-packages/rest_framework/views.py", line 506, in dispatch
    response = handler(request, *args, **kwargs)
               ^^^^^^^^^^^^^^^^^^^^^^^^^^^^^^^^^
  File "/djangoapp/trigger_web_scraping_dou_api/views.py", line 58, in get
    return self.handle_URL_empty_params(saveInDBFlag, detailDOUJournalFlag)
           ^^^^^^^^^^^^^^^^^^^^^^^^^^^^^^^^^^^^^^^^^^^^^^^^^^^^^^^^^^^^^^^^
  File "/djangoapp/trigger_web_scraping_dou_api/views.py", line 192, in handle_URL_empty_params
    response = ScraperUtil.run_scraper_with_empty_params_using_clone_instances(detailDOUJournalFlag)
               ^^^^^^^^^^^^^^^^^^^^^^^^^^^^^^^^^^^^^^^^^^^^^^^^^^^^^^^^^^^^^^^^^^^^^^^^^^^^^^^^^^^^^
  File "/djangoapp/trigger_web_scraping_dou_api/scrapers.py", line 292, in run_scraper_with_empty_params_using_clone_instances
    return ScraperUtil.run_scraper_using_clone_instances_when_secao_do1_do2_and_do3(date_now_db_and_brazilian_format,
          ^^^^^^^^^^^^^^^^^^^^^^^^^^^^^^^^^^^^^^^^^^^^^^^^^^^^^^^^^^^^^^^^^^^^^^^^^^^^^^^^^^^^^^^^^^^^^^^^^^^^^^^^^^^
  File "/djangoapp/trigger_web_scraping_dou_api/scrapers.py", line 334, in run_scraper_using_clone_instances_when_secao_do1_do2_and_do3
    all_dous_response = list(executor.map(ScraperUtil.make_request_for_others_clone_api,
                       ^^^^^^^^^^^^^^^^^^^^^^^^^^^^^^^^^^^^^^^^^^^^^^^^^^^^^^^^^^^^^^^^^
  File "/usr/local/lib/python3.11/concurrent/futures/_base.py", line 619, in result_iterator
    yield _result_or_cancel(fs.pop())
          ^^^^^^^^^^^^^^^^^^^^^^^^^^^
  File "/usr/local/lib/python3.11/concurrent/futures/_base.py", line 317, in _result_or_cancel
    return fut.result(timeout)
           ^^^^^^^^^^^^^^^^^^^
  File "/usr/local/lib/python3.11/concurrent/futures/_base.py", line 456, in result
    return self.__get_result()
           ^^^^^^^^^^^^^^^^^^^
  File "/usr/local/lib/python3.11/concurrent/futures/_base.py", line 401, in __get_result
    raise self._exception
  File "/usr/local/lib/python3.11/concurrent/futures/thread.py", line 58, in run
    result = self.fn(*self.args, **self.kwargs)
             ^^^^^^^^^^^^^^^^^^^^^^^^^^^^^^^^^^
  File "/djangoapp/trigger_web_scraping_dou_api/scrapers.py", line 351, in make_request_for_others_clone_api
    raise Exception(f"Erro na requisição para {url}. Status code: {response.status_code}")
Exception: Erro na requisição para http://djangoappcloneone:8001/trigger_web_scraping_dou_api/?secao=do1&data=19-01-2024&detailDOUJournalFlag=True. Status code: 500
2024-01-19 01:23:42,164 - django.request - ERROR - Internal Server Error: /trigger_web_scraping_dou_api/
Traceback (most recent call last):
  File "/venv/lib/python3.11/site-packages/django/core/handlers/exception.py", line 55, in inner
    response = get_response(request)
               ^^^^^^^^^^^^^^^^^^^^^
  File "/venv/lib/python3.11/site-packages/django/core/handlers/base.py", line 197, in _get_response
    response = wrapped_callback(request, *callback_args, **callback_kwargs)
               ^^^^^^^^^^^^^^^^^^^^^^^^^^^^^^^^^^^^^^^^^^^^^^^^^^^^^^^^^^^^
  File "/venv/lib/python3.11/site-packages/django/views/decorators/csrf.py", line 56, in wrapper_view
    return view_func(*args, **kwargs)
           ^^^^^^^^^^^^^^^^^^^^^^^^^^
  File "/venv/lib/python3.11/site-packages/django/views/generic/base.py", line 104, in view
    return self.dispatch(request, *args, **kwargs)
           ^^^^^^^^^^^^^^^^^^^^^^^^^^^^^^^^^^^^^^^
  File "/venv/lib/python3.11/site-packages/rest_framework/views.py", line 509, in dispatch
    response = self.handle_exception(exc)
               ^^^^^^^^^^^^^^^^^^^^^^^^^^
  File "/venv/lib/python3.11/site-packages/rest_framework/views.py", line 469, in handle_exception
    self.raise_uncaught_exception(exc)
  File "/venv/lib/python3.11/site-packages/rest_framework/views.py", line 480, in raise_uncaught_exception
    raise exc
  File "/venv/lib/python3.11/site-packages/rest_framework/views.py", line 506, in dispatch
    response = handler(request, *args, **kwargs)
               ^^^^^^^^^^^^^^^^^^^^^^^^^^^^^^^^^
  File "/djangoapp/trigger_web_scraping_dou_api/views.py", line 58, in get
    return self.handle_URL_empty_params(saveInDBFlag, detailDOUJournalFlag)
           ^^^^^^^^^^^^^^^^^^^^^^^^^^^^^^^^^^^^^^^^^^^^^^^^^^^^^^^^^^^^^^^^
  File "/djangoapp/trigger_web_scraping_dou_api/views.py", line 192, in handle_URL_empty_params
    response = ScraperUtil.run_scraper_with_empty_params_using_clone_instances(detailDOUJournalFlag)
               ^^^^^^^^^^^^^^^^^^^^^^^^^^^^^^^^^^^^^^^^^^^^^^^^^^^^^^^^^^^^^^^^^^^^^^^^^^^^^^^^^^^^^
  File "/djangoapp/trigger_web_scraping_dou_api/scrapers.py", line 292, in run_scraper_with_empty_params_using_clone_instances
    return ScraperUtil.run_scraper_using_clone_instances_when_secao_do1_do2_and_do3(date_now_db_and_brazilian_format,
          ^^^^^^^^^^^^^^^^^^^^^^^^^^^^^^^^^^^^^^^^^^^^^^^^^^^^^^^^^^^^^^^^^^^^^^^^^^^^^^^^^^^^^^^^^^^^^^^^^^^^^^^^^^^
  File "/djangoapp/trigger_web_scraping_dou_api/scrapers.py", line 334, in run_scraper_using_clone_instances_when_secao_do1_do2_and_do3
    all_dous_response = list(executor.map(ScraperUtil.make_request_for_others_clone_api,
                       ^^^^^^^^^^^^^^^^^^^^^^^^^^^^^^^^^^^^^^^^^^^^^^^^^^^^^^^^^^^^^^^^^
  File "/usr/local/lib/python3.11/concurrent/futures/_base.py", line 619, in result_iterator
    yield _result_or_cancel(fs.pop())
          ^^^^^^^^^^^^^^^^^^^^^^^^^^^
  File "/usr/local/lib/python3.11/concurrent/futures/_base.py", line 317, in _result_or_cancel
    return fut.result(timeout)
           ^^^^^^^^^^^^^^^^^^^
  File "/usr/local/lib/python3.11/concurrent/futures/_base.py", line 456, in result
    return self.__get_result()
           ^^^^^^^^^^^^^^^^^^^
  File "/usr/local/lib/python3.11/concurrent/futures/_base.py", line 401, in __get_result
    raise self._exception
  File "/usr/local/lib/python3.11/concurrent/futures/thread.py", line 58, in run
    result = self.fn(*self.args, **self.kwargs)
             ^^^^^^^^^^^^^^^^^^^^^^^^^^^^^^^^^^
  File "/djangoapp/trigger_web_scraping_dou_api/scrapers.py", line 351, in make_request_for_others_clone_api
    raise Exception(f"Erro na requisição para {url}. Status code: {response.status_code}")
Exception: Erro na requisição para http://djangoappcloneone:8001/trigger_web_scraping_dou_api/?secao=do1&data=19-01-2024&detailDOUJournalFlag=True. Status code: 500
2024-01-19 01:25:48,345 - django.request - ERROR - Internal Server Error: /trigger_web_scraping_dou_api/
Traceback (most recent call last):
  File "/venv/lib/python3.11/site-packages/django/core/handlers/exception.py", line 55, in inner
    response = get_response(request)
               ^^^^^^^^^^^^^^^^^^^^^
  File "/venv/lib/python3.11/site-packages/django/core/handlers/base.py", line 197, in _get_response
    response = wrapped_callback(request, *callback_args, **callback_kwargs)
               ^^^^^^^^^^^^^^^^^^^^^^^^^^^^^^^^^^^^^^^^^^^^^^^^^^^^^^^^^^^^
  File "/venv/lib/python3.11/site-packages/django/views/decorators/csrf.py", line 56, in wrapper_view
    return view_func(*args, **kwargs)
           ^^^^^^^^^^^^^^^^^^^^^^^^^^
  File "/venv/lib/python3.11/site-packages/django/views/generic/base.py", line 104, in view
    return self.dispatch(request, *args, **kwargs)
           ^^^^^^^^^^^^^^^^^^^^^^^^^^^^^^^^^^^^^^^
  File "/venv/lib/python3.11/site-packages/rest_framework/views.py", line 509, in dispatch
    response = self.handle_exception(exc)
               ^^^^^^^^^^^^^^^^^^^^^^^^^^
  File "/venv/lib/python3.11/site-packages/rest_framework/views.py", line 469, in handle_exception
    self.raise_uncaught_exception(exc)
  File "/venv/lib/python3.11/site-packages/rest_framework/views.py", line 480, in raise_uncaught_exception
    raise exc
  File "/venv/lib/python3.11/site-packages/rest_framework/views.py", line 506, in dispatch
    response = handler(request, *args, **kwargs)
               ^^^^^^^^^^^^^^^^^^^^^^^^^^^^^^^^^
  File "/djangoapp/trigger_web_scraping_dou_api/views.py", line 58, in get
    return self.handle_URL_empty_params(saveInDBFlag, detailDOUJournalFlag)
           ^^^^^^^^^^^^^^^^^^^^^^^^^^^^^^^^^^^^^^^^^^^^^^^^^^^^^^^^^^^^^^^^
  File "/djangoapp/trigger_web_scraping_dou_api/views.py", line 192, in handle_URL_empty_params
    response = ScraperUtil.run_scraper_with_empty_params_using_clone_instances(detailDOUJournalFlag)
               ^^^^^^^^^^^^^^^^^^^^^^^^^^^^^^^^^^^^^^^^^^^^^^^^^^^^^^^^^^^^^^^^^^^^^^^^^^^^^^^^^^^^^
  File "/djangoapp/trigger_web_scraping_dou_api/scrapers.py", line 292, in run_scraper_with_empty_params_using_clone_instances
    return ScraperUtil.run_scraper_using_clone_instances_when_secao_do1_do2_and_do3(date_now_db_and_brazilian_format,
          ^^^^^^^^^^^^^^^^^^^^^^^^^^^^^^^^^^^^^^^^^^^^^^^^^^^^^^^^^^^^^^^^^^^^^^^^^^^^^^^^^^^^^^^^^^^^^^^^^^^^^^^^^^^
  File "/djangoapp/trigger_web_scraping_dou_api/scrapers.py", line 334, in run_scraper_using_clone_instances_when_secao_do1_do2_and_do3
    all_dous_response = list(executor.map(ScraperUtil.make_request_for_others_clone_api,
                       ^^^^^^^^^^^^^^^^^^^^^^^^^^^^^^^^^^^^^^^^^^^^^^^^^^^^^^^^^^^^^^^^^
  File "/usr/local/lib/python3.11/concurrent/futures/_base.py", line 619, in result_iterator
    yield _result_or_cancel(fs.pop())
          ^^^^^^^^^^^^^^^^^^^^^^^^^^^
  File "/usr/local/lib/python3.11/concurrent/futures/_base.py", line 317, in _result_or_cancel
    return fut.result(timeout)
           ^^^^^^^^^^^^^^^^^^^
  File "/usr/local/lib/python3.11/concurrent/futures/_base.py", line 456, in result
    return self.__get_result()
           ^^^^^^^^^^^^^^^^^^^
  File "/usr/local/lib/python3.11/concurrent/futures/_base.py", line 401, in __get_result
    raise self._exception
  File "/usr/local/lib/python3.11/concurrent/futures/thread.py", line 58, in run
    result = self.fn(*self.args, **self.kwargs)
             ^^^^^^^^^^^^^^^^^^^^^^^^^^^^^^^^^^
  File "/djangoapp/trigger_web_scraping_dou_api/scrapers.py", line 351, in make_request_for_others_clone_api
    raise Exception(f"Erro na requisição para {url}. Status code: {response.status_code}")
Exception: Erro na requisição para http://djangoappcloneone:8001/trigger_web_scraping_dou_api/?secao=do1&data=19-01-2024&detailDOUJournalFlag=True. Status code: 500
2024-01-19 01:28:17,335 - django.request - ERROR - Internal Server Error: /trigger_web_scraping_dou_api/
Traceback (most recent call last):
  File "/venv/lib/python3.11/site-packages/urllib3/connection.py", line 174, in _new_conn
    conn = connection.create_connection(
           ^^^^^^^^^^^^^^^^^^^^^^^^^^^^^
  File "/venv/lib/python3.11/site-packages/urllib3/util/connection.py", line 96, in create_connection
    raise err
  File "/venv/lib/python3.11/site-packages/urllib3/util/connection.py", line 86, in create_connection
    sock.connect(sa)
ConnectionRefusedError: [Errno 111] Connection refused

During handling of the above exception, another exception occurred:

Traceback (most recent call last):
  File "/venv/lib/python3.11/site-packages/urllib3/connectionpool.py", line 699, in urlopen
    httplib_response = self._make_request(
                       ^^^^^^^^^^^^^^^^^^^
  File "/venv/lib/python3.11/site-packages/urllib3/connectionpool.py", line 394, in _make_request
    conn.request(method, url, **httplib_request_kw)
  File "/venv/lib/python3.11/site-packages/urllib3/connection.py", line 239, in request
    super(HTTPConnection, self).request(method, url, body=body, headers=headers)
  File "/usr/local/lib/python3.11/http/client.py", line 1283, in request
    self._send_request(method, url, body, headers, encode_chunked)
  File "/usr/local/lib/python3.11/http/client.py", line 1329, in _send_request
    self.endheaders(body, encode_chunked=encode_chunked)
  File "/usr/local/lib/python3.11/http/client.py", line 1278, in endheaders
    self._send_output(message_body, encode_chunked=encode_chunked)
  File "/usr/local/lib/python3.11/http/client.py", line 1038, in _send_output
    self.send(msg)
  File "/usr/local/lib/python3.11/http/client.py", line 976, in send
    self.connect()
  File "/venv/lib/python3.11/site-packages/urllib3/connection.py", line 205, in connect
    conn = self._new_conn()
           ^^^^^^^^^^^^^^^^
  File "/venv/lib/python3.11/site-packages/urllib3/connection.py", line 186, in _new_conn
    raise NewConnectionError(
urllib3.exceptions.NewConnectionError: <urllib3.connection.HTTPConnection object at 0x7f452c0cd1d0>: Failed to establish a new connection: [Errno 111] Connection refused

During handling of the above exception, another exception occurred:

Traceback (most recent call last):
  File "/venv/lib/python3.11/site-packages/requests/adapters.py", line 486, in send
    resp = conn.urlopen(
           ^^^^^^^^^^^^^
  File "/venv/lib/python3.11/site-packages/urllib3/connectionpool.py", line 755, in urlopen
    retries = retries.increment(
              ^^^^^^^^^^^^^^^^^^
  File "/venv/lib/python3.11/site-packages/urllib3/util/retry.py", line 574, in increment
    raise MaxRetryError(_pool, url, error or ResponseError(cause))
urllib3.exceptions.MaxRetryError: HTTPConnectionPool(host='djangoappcloneone', port=8001): Max retries exceeded with url: /trigger_web_scraping_dou_api/?secao=do1&data=19-01-2024&detailDOUJournalFlag=True (Caused by NewConnectionError('<urllib3.connection.HTTPConnection object at 0x7f452c0cd1d0>: Failed to establish a new connection: [Errno 111] Connection refused'))

During handling of the above exception, another exception occurred:

Traceback (most recent call last):
  File "/venv/lib/python3.11/site-packages/django/core/handlers/exception.py", line 55, in inner
    response = get_response(request)
               ^^^^^^^^^^^^^^^^^^^^^
  File "/venv/lib/python3.11/site-packages/django/core/handlers/base.py", line 197, in _get_response
    response = wrapped_callback(request, *callback_args, **callback_kwargs)
               ^^^^^^^^^^^^^^^^^^^^^^^^^^^^^^^^^^^^^^^^^^^^^^^^^^^^^^^^^^^^
  File "/venv/lib/python3.11/site-packages/django/views/decorators/csrf.py", line 56, in wrapper_view
    return view_func(*args, **kwargs)
           ^^^^^^^^^^^^^^^^^^^^^^^^^^
  File "/venv/lib/python3.11/site-packages/django/views/generic/base.py", line 104, in view
    return self.dispatch(request, *args, **kwargs)
           ^^^^^^^^^^^^^^^^^^^^^^^^^^^^^^^^^^^^^^^
  File "/venv/lib/python3.11/site-packages/rest_framework/views.py", line 509, in dispatch
    response = self.handle_exception(exc)
               ^^^^^^^^^^^^^^^^^^^^^^^^^^
  File "/venv/lib/python3.11/site-packages/rest_framework/views.py", line 469, in handle_exception
    self.raise_uncaught_exception(exc)
  File "/venv/lib/python3.11/site-packages/rest_framework/views.py", line 480, in raise_uncaught_exception
    raise exc
  File "/venv/lib/python3.11/site-packages/rest_framework/views.py", line 506, in dispatch
    response = handler(request, *args, **kwargs)
               ^^^^^^^^^^^^^^^^^^^^^^^^^^^^^^^^^
  File "/djangoapp/trigger_web_scraping_dou_api/views.py", line 58, in get
    return self.handle_URL_empty_params(saveInDBFlag, detailDOUJournalFlag)
           ^^^^^^^^^^^^^^^^^^^^^^^^^^^^^^^^^^^^^^^^^^^^^^^^^^^^^^^^^^^^^^^^
  File "/djangoapp/trigger_web_scraping_dou_api/views.py", line 192, in handle_URL_empty_params
    response = ScraperUtil.run_scraper_with_empty_params_using_clone_instances(detailDOUJournalFlag)
               ^^^^^^^^^^^^^^^^^^^^^^^^^^^^^^^^^^^^^^^^^^^^^^^^^^^^^^^^^^^^^^^^^^^^^^^^^^^^^^^^^^^^^
  File "/djangoapp/trigger_web_scraping_dou_api/scrapers.py", line 292, in run_scraper_with_empty_params_using_clone_instances
    return ScraperUtil.run_scraper_using_clone_instances_when_secao_do1_do2_and_do3(date_now_db_and_brazilian_format,
          ^^^^^^^^^^^^^^^^^^^^^^^^^^^^^^^^^^^^^^^^^^^^^^^^^^^^^^^^^^^^^^^^^^^^^^^^^^^^^^^^^^^^^^^^^^^^^^^^^^^^^^^^^^^
  File "/djangoapp/trigger_web_scraping_dou_api/scrapers.py", line 334, in run_scraper_using_clone_instances_when_secao_do1_do2_and_do3
    all_dous_response = list(executor.map(ScraperUtil.make_request_for_others_clone_api,
                       ^^^^^^^^^^^^^^^^^^^^^^^^^^^^^^^^^^^^^^^^^^^^^^^^^^^^^^^^^^^^^^^^^
  File "/usr/local/lib/python3.11/concurrent/futures/_base.py", line 619, in result_iterator
    yield _result_or_cancel(fs.pop())
          ^^^^^^^^^^^^^^^^^^^^^^^^^^^
  File "/usr/local/lib/python3.11/concurrent/futures/_base.py", line 317, in _result_or_cancel
    return fut.result(timeout)
           ^^^^^^^^^^^^^^^^^^^
  File "/usr/local/lib/python3.11/concurrent/futures/_base.py", line 449, in result
    return self.__get_result()
           ^^^^^^^^^^^^^^^^^^^
  File "/usr/local/lib/python3.11/concurrent/futures/_base.py", line 401, in __get_result
    raise self._exception
  File "/usr/local/lib/python3.11/concurrent/futures/thread.py", line 58, in run
    result = self.fn(*self.args, **self.kwargs)
             ^^^^^^^^^^^^^^^^^^^^^^^^^^^^^^^^^^
  File "/djangoapp/trigger_web_scraping_dou_api/scrapers.py", line 344, in make_request_for_others_clone_api
    response = requests.get(url)
               ^^^^^^^^^^^^^^^^^
  File "/venv/lib/python3.11/site-packages/requests/api.py", line 73, in get
    return request("get", url, params=params, **kwargs)
           ^^^^^^^^^^^^^^^^^^^^^^^^^^^^^^^^^^^^^^^^^^^^
  File "/venv/lib/python3.11/site-packages/requests/api.py", line 59, in request
    return session.request(method=method, url=url, **kwargs)
           ^^^^^^^^^^^^^^^^^^^^^^^^^^^^^^^^^^^^^^^^^^^^^^^^^
  File "/venv/lib/python3.11/site-packages/requests/sessions.py", line 589, in request
    resp = self.send(prep, **send_kwargs)
           ^^^^^^^^^^^^^^^^^^^^^^^^^^^^^^
  File "/venv/lib/python3.11/site-packages/requests/sessions.py", line 703, in send
    r = adapter.send(request, **kwargs)
        ^^^^^^^^^^^^^^^^^^^^^^^^^^^^^^^
  File "/venv/lib/python3.11/site-packages/requests/adapters.py", line 519, in send
    raise ConnectionError(e, request=request)
requests.exceptions.ConnectionError: HTTPConnectionPool(host='djangoappcloneone', port=8001): Max retries exceeded with url: /trigger_web_scraping_dou_api/?secao=do1&data=19-01-2024&detailDOUJournalFlag=True (Caused by NewConnectionError('<urllib3.connection.HTTPConnection object at 0x7f452c0cd1d0>: Failed to establish a new connection: [Errno 111] Connection refused'))
2024-01-19 01:28:47,252 - django.request - ERROR - Internal Server Error: /trigger_web_scraping_dou_api/
Traceback (most recent call last):
  File "/venv/lib/python3.11/site-packages/django/core/handlers/exception.py", line 55, in inner
    response = get_response(request)
               ^^^^^^^^^^^^^^^^^^^^^
  File "/venv/lib/python3.11/site-packages/django/core/handlers/base.py", line 197, in _get_response
    response = wrapped_callback(request, *callback_args, **callback_kwargs)
               ^^^^^^^^^^^^^^^^^^^^^^^^^^^^^^^^^^^^^^^^^^^^^^^^^^^^^^^^^^^^
  File "/venv/lib/python3.11/site-packages/django/views/decorators/csrf.py", line 56, in wrapper_view
    return view_func(*args, **kwargs)
           ^^^^^^^^^^^^^^^^^^^^^^^^^^
  File "/venv/lib/python3.11/site-packages/django/views/generic/base.py", line 104, in view
    return self.dispatch(request, *args, **kwargs)
           ^^^^^^^^^^^^^^^^^^^^^^^^^^^^^^^^^^^^^^^
  File "/venv/lib/python3.11/site-packages/rest_framework/views.py", line 509, in dispatch
    response = self.handle_exception(exc)
               ^^^^^^^^^^^^^^^^^^^^^^^^^^
  File "/venv/lib/python3.11/site-packages/rest_framework/views.py", line 469, in handle_exception
    self.raise_uncaught_exception(exc)
  File "/venv/lib/python3.11/site-packages/rest_framework/views.py", line 480, in raise_uncaught_exception
    raise exc
  File "/venv/lib/python3.11/site-packages/rest_framework/views.py", line 506, in dispatch
    response = handler(request, *args, **kwargs)
               ^^^^^^^^^^^^^^^^^^^^^^^^^^^^^^^^^
  File "/djangoapp/trigger_web_scraping_dou_api/views.py", line 58, in get
    return self.handle_URL_empty_params(saveInDBFlag, detailDOUJournalFlag)
           ^^^^^^^^^^^^^^^^^^^^^^^^^^^^^^^^^^^^^^^^^^^^^^^^^^^^^^^^^^^^^^^^
  File "/djangoapp/trigger_web_scraping_dou_api/views.py", line 192, in handle_URL_empty_params
    response = ScraperUtil.run_scraper_with_empty_params_using_clone_instances(detailDOUJournalFlag)
               ^^^^^^^^^^^^^^^^^^^^^^^^^^^^^^^^^^^^^^^^^^^^^^^^^^^^^^^^^^^^^^^^^^^^^^^^^^^^^^^^^^^^^
  File "/djangoapp/trigger_web_scraping_dou_api/scrapers.py", line 292, in run_scraper_with_empty_params_using_clone_instances
    return ScraperUtil.run_scraper_using_clone_instances_when_secao_do1_do2_and_do3(date_now_db_and_brazilian_format,
          ^^^^^^^^^^^^^^^^^^^^^^^^^^^^^^^^^^^^^^^^^^^^^^^^^^^^^^^^^^^^^^^^^^^^^^^^^^^^^^^^^^^^^^^^^^^^^^^^^^^^^^^^^^^
  File "/djangoapp/trigger_web_scraping_dou_api/scrapers.py", line 334, in run_scraper_using_clone_instances_when_secao_do1_do2_and_do3
    all_dous_response = list(executor.map(ScraperUtil.make_request_for_others_clone_api,
                       ^^^^^^^^^^^^^^^^^^^^^^^^^^^^^^^^^^^^^^^^^^^^^^^^^^^^^^^^^^^^^^^^^
  File "/usr/local/lib/python3.11/concurrent/futures/_base.py", line 619, in result_iterator
    yield _result_or_cancel(fs.pop())
          ^^^^^^^^^^^^^^^^^^^^^^^^^^^
  File "/usr/local/lib/python3.11/concurrent/futures/_base.py", line 317, in _result_or_cancel
    return fut.result(timeout)
           ^^^^^^^^^^^^^^^^^^^
  File "/usr/local/lib/python3.11/concurrent/futures/_base.py", line 449, in result
    return self.__get_result()
           ^^^^^^^^^^^^^^^^^^^
  File "/usr/local/lib/python3.11/concurrent/futures/_base.py", line 401, in __get_result
    raise self._exception
  File "/usr/local/lib/python3.11/concurrent/futures/thread.py", line 58, in run
    result = self.fn(*self.args, **self.kwargs)
             ^^^^^^^^^^^^^^^^^^^^^^^^^^^^^^^^^^
  File "/djangoapp/trigger_web_scraping_dou_api/scrapers.py", line 351, in make_request_for_others_clone_api
    raise Exception(f"Erro na requisição para {url}. Status code: {response.status_code}")
Exception: Erro na requisição para http://djangoappclonetwo:8002/trigger_web_scraping_dou_api/?secao=do2&data=19-01-2024&detailDOUJournalFlag=True. Status code: 500
2024-01-19 01:30:20,115 - django.request - ERROR - Internal Server Error: /trigger_web_scraping_dou_api/
Traceback (most recent call last):
  File "/venv/lib/python3.11/site-packages/django/core/handlers/exception.py", line 55, in inner
    response = get_response(request)
               ^^^^^^^^^^^^^^^^^^^^^
  File "/venv/lib/python3.11/site-packages/django/core/handlers/base.py", line 197, in _get_response
    response = wrapped_callback(request, *callback_args, **callback_kwargs)
               ^^^^^^^^^^^^^^^^^^^^^^^^^^^^^^^^^^^^^^^^^^^^^^^^^^^^^^^^^^^^
  File "/venv/lib/python3.11/site-packages/django/views/decorators/csrf.py", line 56, in wrapper_view
    return view_func(*args, **kwargs)
           ^^^^^^^^^^^^^^^^^^^^^^^^^^
  File "/venv/lib/python3.11/site-packages/django/views/generic/base.py", line 104, in view
    return self.dispatch(request, *args, **kwargs)
           ^^^^^^^^^^^^^^^^^^^^^^^^^^^^^^^^^^^^^^^
  File "/venv/lib/python3.11/site-packages/rest_framework/views.py", line 509, in dispatch
    response = self.handle_exception(exc)
               ^^^^^^^^^^^^^^^^^^^^^^^^^^
  File "/venv/lib/python3.11/site-packages/rest_framework/views.py", line 469, in handle_exception
    self.raise_uncaught_exception(exc)
  File "/venv/lib/python3.11/site-packages/rest_framework/views.py", line 480, in raise_uncaught_exception
    raise exc
  File "/venv/lib/python3.11/site-packages/rest_framework/views.py", line 506, in dispatch
    response = handler(request, *args, **kwargs)
               ^^^^^^^^^^^^^^^^^^^^^^^^^^^^^^^^^
  File "/djangoapp/trigger_web_scraping_dou_api/views.py", line 58, in get
    return self.handle_URL_empty_params(saveInDBFlag, detailDOUJournalFlag)
           ^^^^^^^^^^^^^^^^^^^^^^^^^^^^^^^^^^^^^^^^^^^^^^^^^^^^^^^^^^^^^^^^
  File "/djangoapp/trigger_web_scraping_dou_api/views.py", line 192, in handle_URL_empty_params
    response = ScraperUtil.run_scraper_with_empty_params_using_clone_instances(detailDOUJournalFlag)
               ^^^^^^^^^^^^^^^^^^^^^^^^^^^^^^^^^^^^^^^^^^^^^^^^^^^^^^^^^^^^^^^^^^^^^^^^^^^^^^^^^^^^^
  File "/djangoapp/trigger_web_scraping_dou_api/scrapers.py", line 292, in run_scraper_with_empty_params_using_clone_instances
    return ScraperUtil.run_scraper_using_clone_instances_when_secao_do1_do2_and_do3(date_now_db_and_brazilian_format,
          ^^^^^^^^^^^^^^^^^^^^^^^^^^^^^^^^^^^^^^^^^^^^^^^^^^^^^^^^^^^^^^^^^^^^^^^^^^^^^^^^^^^^^^^^^^^^^^^^^^^^^^^^^^^
  File "/djangoapp/trigger_web_scraping_dou_api/scrapers.py", line 334, in run_scraper_using_clone_instances_when_secao_do1_do2_and_do3
    all_dous_response = list(executor.map(ScraperUtil.make_request_for_others_clone_api,
                       ^^^^^^^^^^^^^^^^^^^^^^^^^^^^^^^^^^^^^^^^^^^^^^^^^^^^^^^^^^^^^^^^^
  File "/usr/local/lib/python3.11/concurrent/futures/_base.py", line 619, in result_iterator
    yield _result_or_cancel(fs.pop())
          ^^^^^^^^^^^^^^^^^^^^^^^^^^^
  File "/usr/local/lib/python3.11/concurrent/futures/_base.py", line 317, in _result_or_cancel
    return fut.result(timeout)
           ^^^^^^^^^^^^^^^^^^^
  File "/usr/local/lib/python3.11/concurrent/futures/_base.py", line 456, in result
    return self.__get_result()
           ^^^^^^^^^^^^^^^^^^^
  File "/usr/local/lib/python3.11/concurrent/futures/_base.py", line 401, in __get_result
    raise self._exception
  File "/usr/local/lib/python3.11/concurrent/futures/thread.py", line 58, in run
    result = self.fn(*self.args, **self.kwargs)
             ^^^^^^^^^^^^^^^^^^^^^^^^^^^^^^^^^^
  File "/djangoapp/trigger_web_scraping_dou_api/scrapers.py", line 351, in make_request_for_others_clone_api
    raise Exception(f"Erro na requisição para {url}. Status code: {response.status_code}")
Exception: Erro na requisição para http://djangoappcloneone:8001/trigger_web_scraping_dou_api/?secao=do1&data=19-01-2024&detailDOUJournalFlag=True. Status code: 500
2024-01-19 01:30:22,777 - django.request - ERROR - Internal Server Error: /trigger_web_scraping_dou_api/
Traceback (most recent call last):
  File "/venv/lib/python3.11/site-packages/django/core/handlers/exception.py", line 55, in inner
    response = get_response(request)
               ^^^^^^^^^^^^^^^^^^^^^
  File "/venv/lib/python3.11/site-packages/django/core/handlers/base.py", line 197, in _get_response
    response = wrapped_callback(request, *callback_args, **callback_kwargs)
               ^^^^^^^^^^^^^^^^^^^^^^^^^^^^^^^^^^^^^^^^^^^^^^^^^^^^^^^^^^^^
  File "/venv/lib/python3.11/site-packages/django/views/decorators/csrf.py", line 56, in wrapper_view
    return view_func(*args, **kwargs)
           ^^^^^^^^^^^^^^^^^^^^^^^^^^
  File "/venv/lib/python3.11/site-packages/django/views/generic/base.py", line 104, in view
    return self.dispatch(request, *args, **kwargs)
           ^^^^^^^^^^^^^^^^^^^^^^^^^^^^^^^^^^^^^^^
  File "/venv/lib/python3.11/site-packages/rest_framework/views.py", line 509, in dispatch
    response = self.handle_exception(exc)
               ^^^^^^^^^^^^^^^^^^^^^^^^^^
  File "/venv/lib/python3.11/site-packages/rest_framework/views.py", line 469, in handle_exception
    self.raise_uncaught_exception(exc)
  File "/venv/lib/python3.11/site-packages/rest_framework/views.py", line 480, in raise_uncaught_exception
    raise exc
  File "/venv/lib/python3.11/site-packages/rest_framework/views.py", line 506, in dispatch
    response = handler(request, *args, **kwargs)
               ^^^^^^^^^^^^^^^^^^^^^^^^^^^^^^^^^
  File "/djangoapp/trigger_web_scraping_dou_api/views.py", line 58, in get
    return self.handle_URL_empty_params(saveInDBFlag, detailDOUJournalFlag)
           ^^^^^^^^^^^^^^^^^^^^^^^^^^^^^^^^^^^^^^^^^^^^^^^^^^^^^^^^^^^^^^^^
  File "/djangoapp/trigger_web_scraping_dou_api/views.py", line 192, in handle_URL_empty_params
    response = ScraperUtil.run_scraper_with_empty_params_using_clone_instances(detailDOUJournalFlag)
               ^^^^^^^^^^^^^^^^^^^^^^^^^^^^^^^^^^^^^^^^^^^^^^^^^^^^^^^^^^^^^^^^^^^^^^^^^^^^^^^^^^^^^
  File "/djangoapp/trigger_web_scraping_dou_api/scrapers.py", line 292, in run_scraper_with_empty_params_using_clone_instances
    return ScraperUtil.run_scraper_using_clone_instances_when_secao_do1_do2_and_do3(date_now_db_and_brazilian_format,
          ^^^^^^^^^^^^^^^^^^^^^^^^^^^^^^^^^^^^^^^^^^^^^^^^^^^^^^^^^^^^^^^^^^^^^^^^^^^^^^^^^^^^^^^^^^^^^^^^^^^^^^^^^^^
  File "/djangoapp/trigger_web_scraping_dou_api/scrapers.py", line 334, in run_scraper_using_clone_instances_when_secao_do1_do2_and_do3
    all_dous_response = list(executor.map(ScraperUtil.make_request_for_others_clone_api,
                       ^^^^^^^^^^^^^^^^^^^^^^^^^^^^^^^^^^^^^^^^^^^^^^^^^^^^^^^^^^^^^^^^^
  File "/usr/local/lib/python3.11/concurrent/futures/_base.py", line 619, in result_iterator
    yield _result_or_cancel(fs.pop())
          ^^^^^^^^^^^^^^^^^^^^^^^^^^^
  File "/usr/local/lib/python3.11/concurrent/futures/_base.py", line 317, in _result_or_cancel
    return fut.result(timeout)
           ^^^^^^^^^^^^^^^^^^^
  File "/usr/local/lib/python3.11/concurrent/futures/_base.py", line 456, in result
    return self.__get_result()
           ^^^^^^^^^^^^^^^^^^^
  File "/usr/local/lib/python3.11/concurrent/futures/_base.py", line 401, in __get_result
    raise self._exception
  File "/usr/local/lib/python3.11/concurrent/futures/thread.py", line 58, in run
    result = self.fn(*self.args, **self.kwargs)
             ^^^^^^^^^^^^^^^^^^^^^^^^^^^^^^^^^^
  File "/djangoapp/trigger_web_scraping_dou_api/scrapers.py", line 351, in make_request_for_others_clone_api
    raise Exception(f"Erro na requisição para {url}. Status code: {response.status_code}")
Exception: Erro na requisição para http://djangoappcloneone:8001/trigger_web_scraping_dou_api/?secao=do1&data=19-01-2024&detailDOUJournalFlag=True. Status code: 500
2024-01-19 01:31:21,994 - django.request - ERROR - Internal Server Error: /trigger_web_scraping_dou_api/
Traceback (most recent call last):
  File "/venv/lib/python3.11/site-packages/django/core/handlers/exception.py", line 55, in inner
    response = get_response(request)
               ^^^^^^^^^^^^^^^^^^^^^
  File "/venv/lib/python3.11/site-packages/django/core/handlers/base.py", line 197, in _get_response
    response = wrapped_callback(request, *callback_args, **callback_kwargs)
               ^^^^^^^^^^^^^^^^^^^^^^^^^^^^^^^^^^^^^^^^^^^^^^^^^^^^^^^^^^^^
  File "/venv/lib/python3.11/site-packages/django/views/decorators/csrf.py", line 56, in wrapper_view
    return view_func(*args, **kwargs)
           ^^^^^^^^^^^^^^^^^^^^^^^^^^
  File "/venv/lib/python3.11/site-packages/django/views/generic/base.py", line 104, in view
    return self.dispatch(request, *args, **kwargs)
           ^^^^^^^^^^^^^^^^^^^^^^^^^^^^^^^^^^^^^^^
  File "/venv/lib/python3.11/site-packages/rest_framework/views.py", line 509, in dispatch
    response = self.handle_exception(exc)
               ^^^^^^^^^^^^^^^^^^^^^^^^^^
  File "/venv/lib/python3.11/site-packages/rest_framework/views.py", line 469, in handle_exception
    self.raise_uncaught_exception(exc)
  File "/venv/lib/python3.11/site-packages/rest_framework/views.py", line 480, in raise_uncaught_exception
    raise exc
  File "/venv/lib/python3.11/site-packages/rest_framework/views.py", line 506, in dispatch
    response = handler(request, *args, **kwargs)
               ^^^^^^^^^^^^^^^^^^^^^^^^^^^^^^^^^
  File "/djangoapp/trigger_web_scraping_dou_api/views.py", line 58, in get
    return self.handle_URL_empty_params(saveInDBFlag, detailDOUJournalFlag)
           ^^^^^^^^^^^^^^^^^^^^^^^^^^^^^^^^^^^^^^^^^^^^^^^^^^^^^^^^^^^^^^^^
  File "/djangoapp/trigger_web_scraping_dou_api/views.py", line 192, in handle_URL_empty_params
    response = ScraperUtil.run_scraper_with_empty_params_using_clone_instances(detailDOUJournalFlag)
               ^^^^^^^^^^^^^^^^^^^^^^^^^^^^^^^^^^^^^^^^^^^^^^^^^^^^^^^^^^^^^^^^^^^^^^^^^^^^^^^^^^^^^
  File "/djangoapp/trigger_web_scraping_dou_api/scrapers.py", line 292, in run_scraper_with_empty_params_using_clone_instances
    return ScraperUtil.run_scraper_using_clone_instances_when_secao_do1_do2_and_do3(date_now_db_and_brazilian_format,
          ^^^^^^^^^^^^^^^^^^^^^^^^^^^^^^^^^^^^^^^^^^^^^^^^^^^^^^^^^^^^^^^^^^^^^^^^^^^^^^^^^^^^^^^^^^^^^^^^^^^^^^^^^^^
  File "/djangoapp/trigger_web_scraping_dou_api/scrapers.py", line 334, in run_scraper_using_clone_instances_when_secao_do1_do2_and_do3
    all_dous_response = list(executor.map(ScraperUtil.make_request_for_others_clone_api,
                       ^^^^^^^^^^^^^^^^^^^^^^^^^^^^^^^^^^^^^^^^^^^^^^^^^^^^^^^^^^^^^^^^^
  File "/usr/local/lib/python3.11/concurrent/futures/_base.py", line 619, in result_iterator
    yield _result_or_cancel(fs.pop())
          ^^^^^^^^^^^^^^^^^^^^^^^^^^^
  File "/usr/local/lib/python3.11/concurrent/futures/_base.py", line 317, in _result_or_cancel
    return fut.result(timeout)
           ^^^^^^^^^^^^^^^^^^^
  File "/usr/local/lib/python3.11/concurrent/futures/_base.py", line 456, in result
    return self.__get_result()
           ^^^^^^^^^^^^^^^^^^^
  File "/usr/local/lib/python3.11/concurrent/futures/_base.py", line 401, in __get_result
    raise self._exception
  File "/usr/local/lib/python3.11/concurrent/futures/thread.py", line 58, in run
    result = self.fn(*self.args, **self.kwargs)
             ^^^^^^^^^^^^^^^^^^^^^^^^^^^^^^^^^^
  File "/djangoapp/trigger_web_scraping_dou_api/scrapers.py", line 351, in make_request_for_others_clone_api
    raise Exception(f"Erro na requisição para {url}. Status code: {response.status_code}")
Exception: Erro na requisição para http://djangoappcloneone:8001/trigger_web_scraping_dou_api/?secao=do1&data=19-01-2024&detailDOUJournalFlag=True. Status code: 500
2024-01-19 01:32:56,615 - django.request - ERROR - Internal Server Error: /trigger_web_scraping_dou_api/
Traceback (most recent call last):
  File "/venv/lib/python3.11/site-packages/urllib3/connection.py", line 174, in _new_conn
    conn = connection.create_connection(
           ^^^^^^^^^^^^^^^^^^^^^^^^^^^^^
  File "/venv/lib/python3.11/site-packages/urllib3/util/connection.py", line 96, in create_connection
    raise err
  File "/venv/lib/python3.11/site-packages/urllib3/util/connection.py", line 86, in create_connection
    sock.connect(sa)
ConnectionRefusedError: [Errno 111] Connection refused

During handling of the above exception, another exception occurred:

Traceback (most recent call last):
  File "/venv/lib/python3.11/site-packages/urllib3/connectionpool.py", line 699, in urlopen
    httplib_response = self._make_request(
                       ^^^^^^^^^^^^^^^^^^^
  File "/venv/lib/python3.11/site-packages/urllib3/connectionpool.py", line 394, in _make_request
    conn.request(method, url, **httplib_request_kw)
  File "/venv/lib/python3.11/site-packages/urllib3/connection.py", line 239, in request
    super(HTTPConnection, self).request(method, url, body=body, headers=headers)
  File "/usr/local/lib/python3.11/http/client.py", line 1283, in request
    self._send_request(method, url, body, headers, encode_chunked)
  File "/usr/local/lib/python3.11/http/client.py", line 1329, in _send_request
    self.endheaders(body, encode_chunked=encode_chunked)
  File "/usr/local/lib/python3.11/http/client.py", line 1278, in endheaders
    self._send_output(message_body, encode_chunked=encode_chunked)
  File "/usr/local/lib/python3.11/http/client.py", line 1038, in _send_output
    self.send(msg)
  File "/usr/local/lib/python3.11/http/client.py", line 976, in send
    self.connect()
  File "/venv/lib/python3.11/site-packages/urllib3/connection.py", line 205, in connect
    conn = self._new_conn()
           ^^^^^^^^^^^^^^^^
  File "/venv/lib/python3.11/site-packages/urllib3/connection.py", line 186, in _new_conn
    raise NewConnectionError(
urllib3.exceptions.NewConnectionError: <urllib3.connection.HTTPConnection object at 0x7f452b7bec10>: Failed to establish a new connection: [Errno 111] Connection refused

During handling of the above exception, another exception occurred:

Traceback (most recent call last):
  File "/venv/lib/python3.11/site-packages/requests/adapters.py", line 486, in send
    resp = conn.urlopen(
           ^^^^^^^^^^^^^
  File "/venv/lib/python3.11/site-packages/urllib3/connectionpool.py", line 755, in urlopen
    retries = retries.increment(
              ^^^^^^^^^^^^^^^^^^
  File "/venv/lib/python3.11/site-packages/urllib3/util/retry.py", line 574, in increment
    raise MaxRetryError(_pool, url, error or ResponseError(cause))
urllib3.exceptions.MaxRetryError: HTTPConnectionPool(host='djangoappcloneone', port=8001): Max retries exceeded with url: /trigger_web_scraping_dou_api/?secao=do1&data=19-01-2024&detailDOUJournalFlag=True (Caused by NewConnectionError('<urllib3.connection.HTTPConnection object at 0x7f452b7bec10>: Failed to establish a new connection: [Errno 111] Connection refused'))

During handling of the above exception, another exception occurred:

Traceback (most recent call last):
  File "/venv/lib/python3.11/site-packages/django/core/handlers/exception.py", line 55, in inner
    response = get_response(request)
               ^^^^^^^^^^^^^^^^^^^^^
  File "/venv/lib/python3.11/site-packages/django/core/handlers/base.py", line 197, in _get_response
    response = wrapped_callback(request, *callback_args, **callback_kwargs)
               ^^^^^^^^^^^^^^^^^^^^^^^^^^^^^^^^^^^^^^^^^^^^^^^^^^^^^^^^^^^^
  File "/venv/lib/python3.11/site-packages/django/views/decorators/csrf.py", line 56, in wrapper_view
    return view_func(*args, **kwargs)
           ^^^^^^^^^^^^^^^^^^^^^^^^^^
  File "/venv/lib/python3.11/site-packages/django/views/generic/base.py", line 104, in view
    return self.dispatch(request, *args, **kwargs)
           ^^^^^^^^^^^^^^^^^^^^^^^^^^^^^^^^^^^^^^^
  File "/venv/lib/python3.11/site-packages/rest_framework/views.py", line 509, in dispatch
    response = self.handle_exception(exc)
               ^^^^^^^^^^^^^^^^^^^^^^^^^^
  File "/venv/lib/python3.11/site-packages/rest_framework/views.py", line 469, in handle_exception
    self.raise_uncaught_exception(exc)
  File "/venv/lib/python3.11/site-packages/rest_framework/views.py", line 480, in raise_uncaught_exception
    raise exc
  File "/venv/lib/python3.11/site-packages/rest_framework/views.py", line 506, in dispatch
    response = handler(request, *args, **kwargs)
               ^^^^^^^^^^^^^^^^^^^^^^^^^^^^^^^^^
  File "/djangoapp/trigger_web_scraping_dou_api/views.py", line 58, in get
    return self.handle_URL_empty_params(saveInDBFlag, detailDOUJournalFlag)
           ^^^^^^^^^^^^^^^^^^^^^^^^^^^^^^^^^^^^^^^^^^^^^^^^^^^^^^^^^^^^^^^^
  File "/djangoapp/trigger_web_scraping_dou_api/views.py", line 192, in handle_URL_empty_params
    response = ScraperUtil.run_scraper_with_empty_params_using_clone_instances(detailDOUJournalFlag)
               ^^^^^^^^^^^^^^^^^^^^^^^^^^^^^^^^^^^^^^^^^^^^^^^^^^^^^^^^^^^^^^^^^^^^^^^^^^^^^^^^^^^^^
  File "/djangoapp/trigger_web_scraping_dou_api/scrapers.py", line 292, in run_scraper_with_empty_params_using_clone_instances
    return ScraperUtil.run_scraper_using_clone_instances_when_secao_do1_do2_and_do3(date_now_db_and_brazilian_format,
          ^^^^^^^^^^^^^^^^^^^^^^^^^^^^^^^^^^^^^^^^^^^^^^^^^^^^^^^^^^^^^^^^^^^^^^^^^^^^^^^^^^^^^^^^^^^^^^^^^^^^^^^^^^^
  File "/djangoapp/trigger_web_scraping_dou_api/scrapers.py", line 334, in run_scraper_using_clone_instances_when_secao_do1_do2_and_do3
    all_dous_response = list(executor.map(ScraperUtil.make_request_for_others_clone_api,
                       ^^^^^^^^^^^^^^^^^^^^^^^^^^^^^^^^^^^^^^^^^^^^^^^^^^^^^^^^^^^^^^^^^
  File "/usr/local/lib/python3.11/concurrent/futures/_base.py", line 619, in result_iterator
    yield _result_or_cancel(fs.pop())
          ^^^^^^^^^^^^^^^^^^^^^^^^^^^
  File "/usr/local/lib/python3.11/concurrent/futures/_base.py", line 317, in _result_or_cancel
    return fut.result(timeout)
           ^^^^^^^^^^^^^^^^^^^
  File "/usr/local/lib/python3.11/concurrent/futures/_base.py", line 456, in result
    return self.__get_result()
           ^^^^^^^^^^^^^^^^^^^
  File "/usr/local/lib/python3.11/concurrent/futures/_base.py", line 401, in __get_result
    raise self._exception
  File "/usr/local/lib/python3.11/concurrent/futures/thread.py", line 58, in run
    result = self.fn(*self.args, **self.kwargs)
             ^^^^^^^^^^^^^^^^^^^^^^^^^^^^^^^^^^
  File "/djangoapp/trigger_web_scraping_dou_api/scrapers.py", line 344, in make_request_for_others_clone_api
    response = requests.get(url)
               ^^^^^^^^^^^^^^^^^
  File "/venv/lib/python3.11/site-packages/requests/api.py", line 73, in get
    return request("get", url, params=params, **kwargs)
           ^^^^^^^^^^^^^^^^^^^^^^^^^^^^^^^^^^^^^^^^^^^^
  File "/venv/lib/python3.11/site-packages/requests/api.py", line 59, in request
    return session.request(method=method, url=url, **kwargs)
           ^^^^^^^^^^^^^^^^^^^^^^^^^^^^^^^^^^^^^^^^^^^^^^^^^
  File "/venv/lib/python3.11/site-packages/requests/sessions.py", line 589, in request
    resp = self.send(prep, **send_kwargs)
           ^^^^^^^^^^^^^^^^^^^^^^^^^^^^^^
  File "/venv/lib/python3.11/site-packages/requests/sessions.py", line 703, in send
    r = adapter.send(request, **kwargs)
        ^^^^^^^^^^^^^^^^^^^^^^^^^^^^^^^
  File "/venv/lib/python3.11/site-packages/requests/adapters.py", line 519, in send
    raise ConnectionError(e, request=request)
requests.exceptions.ConnectionError: HTTPConnectionPool(host='djangoappcloneone', port=8001): Max retries exceeded with url: /trigger_web_scraping_dou_api/?secao=do1&data=19-01-2024&detailDOUJournalFlag=True (Caused by NewConnectionError('<urllib3.connection.HTTPConnection object at 0x7f452b7bec10>: Failed to establish a new connection: [Errno 111] Connection refused'))
2024-01-19 01:34:11,841 - django.request - ERROR - Internal Server Error: /trigger_web_scraping_dou_api/
Traceback (most recent call last):
  File "/venv/lib/python3.11/site-packages/django/core/handlers/exception.py", line 55, in inner
    response = get_response(request)
               ^^^^^^^^^^^^^^^^^^^^^
  File "/venv/lib/python3.11/site-packages/django/core/handlers/base.py", line 197, in _get_response
    response = wrapped_callback(request, *callback_args, **callback_kwargs)
               ^^^^^^^^^^^^^^^^^^^^^^^^^^^^^^^^^^^^^^^^^^^^^^^^^^^^^^^^^^^^
  File "/venv/lib/python3.11/site-packages/django/views/decorators/csrf.py", line 56, in wrapper_view
    return view_func(*args, **kwargs)
           ^^^^^^^^^^^^^^^^^^^^^^^^^^
  File "/venv/lib/python3.11/site-packages/django/views/generic/base.py", line 104, in view
    return self.dispatch(request, *args, **kwargs)
           ^^^^^^^^^^^^^^^^^^^^^^^^^^^^^^^^^^^^^^^
  File "/venv/lib/python3.11/site-packages/rest_framework/views.py", line 509, in dispatch
    response = self.handle_exception(exc)
               ^^^^^^^^^^^^^^^^^^^^^^^^^^
  File "/venv/lib/python3.11/site-packages/rest_framework/views.py", line 469, in handle_exception
    self.raise_uncaught_exception(exc)
  File "/venv/lib/python3.11/site-packages/rest_framework/views.py", line 480, in raise_uncaught_exception
    raise exc
  File "/venv/lib/python3.11/site-packages/rest_framework/views.py", line 506, in dispatch
    response = handler(request, *args, **kwargs)
               ^^^^^^^^^^^^^^^^^^^^^^^^^^^^^^^^^
  File "/djangoapp/trigger_web_scraping_dou_api/views.py", line 58, in get
    return self.handle_URL_empty_params(saveInDBFlag, detailDOUJournalFlag)
           ^^^^^^^^^^^^^^^^^^^^^^^^^^^^^^^^^^^^^^^^^^^^^^^^^^^^^^^^^^^^^^^^
  File "/djangoapp/trigger_web_scraping_dou_api/views.py", line 192, in handle_URL_empty_params
    response = ScraperUtil.run_scraper_with_empty_params_using_clone_instances(detailDOUJournalFlag)
               ^^^^^^^^^^^^^^^^^^^^^^^^^^^^^^^^^^^^^^^^^^^^^^^^^^^^^^^^^^^^^^^^^^^^^^^^^^^^^^^^^^^^^
  File "/djangoapp/trigger_web_scraping_dou_api/scrapers.py", line 292, in run_scraper_with_empty_params_using_clone_instances
    return ScraperUtil.run_scraper_using_clone_instances_when_secao_do1_do2_and_do3(date_now_db_and_brazilian_format,
          ^^^^^^^^^^^^^^^^^^^^^^^^^^^^^^^^^^^^^^^^^^^^^^^^^^^^^^^^^^^^^^^^^^^^^^^^^^^^^^^^^^^^^^^^^^^^^^^^^^^^^^^^^^^
  File "/djangoapp/trigger_web_scraping_dou_api/scrapers.py", line 334, in run_scraper_using_clone_instances_when_secao_do1_do2_and_do3
    all_dous_response = list(executor.map(ScraperUtil.make_request_for_others_clone_api,
                       ^^^^^^^^^^^^^^^^^^^^^^^^^^^^^^^^^^^^^^^^^^^^^^^^^^^^^^^^^^^^^^^^^
  File "/usr/local/lib/python3.11/concurrent/futures/_base.py", line 619, in result_iterator
    yield _result_or_cancel(fs.pop())
          ^^^^^^^^^^^^^^^^^^^^^^^^^^^
  File "/usr/local/lib/python3.11/concurrent/futures/_base.py", line 317, in _result_or_cancel
    return fut.result(timeout)
           ^^^^^^^^^^^^^^^^^^^
  File "/usr/local/lib/python3.11/concurrent/futures/_base.py", line 456, in result
    return self.__get_result()
           ^^^^^^^^^^^^^^^^^^^
  File "/usr/local/lib/python3.11/concurrent/futures/_base.py", line 401, in __get_result
    raise self._exception
  File "/usr/local/lib/python3.11/concurrent/futures/thread.py", line 58, in run
    result = self.fn(*self.args, **self.kwargs)
             ^^^^^^^^^^^^^^^^^^^^^^^^^^^^^^^^^^
  File "/djangoapp/trigger_web_scraping_dou_api/scrapers.py", line 351, in make_request_for_others_clone_api
    raise Exception(f"Erro na requisição para {url}. Status code: {response.status_code}")
Exception: Erro na requisição para http://djangoappcloneone:8001/trigger_web_scraping_dou_api/?secao=do1&data=19-01-2024&detailDOUJournalFlag=True. Status code: 500
2024-01-19 01:35:19,292 - django.utils.autoreload - INFO - /djangoapp/trigger_web_scraping_dou_api/scrapers.py changed, reloading.
2024-01-19 01:35:55,135 - django.request - ERROR - Internal Server Error: /trigger_web_scraping_dou_api/
Traceback (most recent call last):
  File "/venv/lib/python3.11/site-packages/urllib3/connection.py", line 174, in _new_conn
    conn = connection.create_connection(
           ^^^^^^^^^^^^^^^^^^^^^^^^^^^^^
  File "/venv/lib/python3.11/site-packages/urllib3/util/connection.py", line 96, in create_connection
    raise err
  File "/venv/lib/python3.11/site-packages/urllib3/util/connection.py", line 86, in create_connection
    sock.connect(sa)
ConnectionRefusedError: [Errno 111] Connection refused

During handling of the above exception, another exception occurred:

Traceback (most recent call last):
  File "/venv/lib/python3.11/site-packages/urllib3/connectionpool.py", line 699, in urlopen
    httplib_response = self._make_request(
                       ^^^^^^^^^^^^^^^^^^^
  File "/venv/lib/python3.11/site-packages/urllib3/connectionpool.py", line 394, in _make_request
    conn.request(method, url, **httplib_request_kw)
  File "/venv/lib/python3.11/site-packages/urllib3/connection.py", line 239, in request
    super(HTTPConnection, self).request(method, url, body=body, headers=headers)
  File "/usr/local/lib/python3.11/http/client.py", line 1283, in request
    self._send_request(method, url, body, headers, encode_chunked)
  File "/usr/local/lib/python3.11/http/client.py", line 1329, in _send_request
    self.endheaders(body, encode_chunked=encode_chunked)
  File "/usr/local/lib/python3.11/http/client.py", line 1278, in endheaders
    self._send_output(message_body, encode_chunked=encode_chunked)
  File "/usr/local/lib/python3.11/http/client.py", line 1038, in _send_output
    self.send(msg)
  File "/usr/local/lib/python3.11/http/client.py", line 976, in send
    self.connect()
  File "/venv/lib/python3.11/site-packages/urllib3/connection.py", line 205, in connect
    conn = self._new_conn()
           ^^^^^^^^^^^^^^^^
  File "/venv/lib/python3.11/site-packages/urllib3/connection.py", line 186, in _new_conn
    raise NewConnectionError(
urllib3.exceptions.NewConnectionError: <urllib3.connection.HTTPConnection object at 0x7f74a9905550>: Failed to establish a new connection: [Errno 111] Connection refused

During handling of the above exception, another exception occurred:

Traceback (most recent call last):
  File "/venv/lib/python3.11/site-packages/requests/adapters.py", line 486, in send
    resp = conn.urlopen(
           ^^^^^^^^^^^^^
  File "/venv/lib/python3.11/site-packages/urllib3/connectionpool.py", line 755, in urlopen
    retries = retries.increment(
              ^^^^^^^^^^^^^^^^^^
  File "/venv/lib/python3.11/site-packages/urllib3/util/retry.py", line 574, in increment
    raise MaxRetryError(_pool, url, error or ResponseError(cause))
urllib3.exceptions.MaxRetryError: HTTPConnectionPool(host='djangoappclonetwo', port=8002): Max retries exceeded with url: /trigger_web_scraping_dou_api/?secao=do2&data=19-01-2024&detailDOUJournalFlag=True (Caused by NewConnectionError('<urllib3.connection.HTTPConnection object at 0x7f74a9905550>: Failed to establish a new connection: [Errno 111] Connection refused'))

During handling of the above exception, another exception occurred:

Traceback (most recent call last):
  File "/venv/lib/python3.11/site-packages/django/core/handlers/exception.py", line 55, in inner
    response = get_response(request)
               ^^^^^^^^^^^^^^^^^^^^^
  File "/venv/lib/python3.11/site-packages/django/core/handlers/base.py", line 197, in _get_response
    response = wrapped_callback(request, *callback_args, **callback_kwargs)
               ^^^^^^^^^^^^^^^^^^^^^^^^^^^^^^^^^^^^^^^^^^^^^^^^^^^^^^^^^^^^
  File "/venv/lib/python3.11/site-packages/django/views/decorators/csrf.py", line 56, in wrapper_view
    return view_func(*args, **kwargs)
           ^^^^^^^^^^^^^^^^^^^^^^^^^^
  File "/venv/lib/python3.11/site-packages/django/views/generic/base.py", line 104, in view
    return self.dispatch(request, *args, **kwargs)
           ^^^^^^^^^^^^^^^^^^^^^^^^^^^^^^^^^^^^^^^
  File "/venv/lib/python3.11/site-packages/rest_framework/views.py", line 509, in dispatch
    response = self.handle_exception(exc)
               ^^^^^^^^^^^^^^^^^^^^^^^^^^
  File "/venv/lib/python3.11/site-packages/rest_framework/views.py", line 469, in handle_exception
    self.raise_uncaught_exception(exc)
  File "/venv/lib/python3.11/site-packages/rest_framework/views.py", line 480, in raise_uncaught_exception
    raise exc
  File "/venv/lib/python3.11/site-packages/rest_framework/views.py", line 506, in dispatch
    response = handler(request, *args, **kwargs)
               ^^^^^^^^^^^^^^^^^^^^^^^^^^^^^^^^^
  File "/djangoapp/trigger_web_scraping_dou_api/views.py", line 58, in get
    return self.handle_URL_empty_params(saveInDBFlag, detailDOUJournalFlag)
           ^^^^^^^^^^^^^^^^^^^^^^^^^^^^^^^^^^^^^^^^^^^^^^^^^^^^^^^^^^^^^^^^
  File "/djangoapp/trigger_web_scraping_dou_api/views.py", line 192, in handle_URL_empty_params
    response = ScraperUtil.run_scraper_with_empty_params_using_clone_instances(detailDOUJournalFlag)
               ^^^^^^^^^^^^^^^^^^^^^^^^^^^^^^^^^^^^^^^^^^^^^^^^^^^^^^^^^^^^^^^^^^^^^^^^^^^^^^^^^^^^^
  File "/djangoapp/trigger_web_scraping_dou_api/scrapers.py", line 292, in run_scraper_with_empty_params_using_clone_instances
    return ScraperUtil.run_scraper_using_clone_instances_when_secao_do1_do2_and_do3(date_now_db_and_brazilian_format,
          ^^^^^^^^^^^^^^^^^^^^^^^^^^^^^^^^^^^^^^^^^^^^^^^^^^^^^^^^^^^^^^^^^^^^^^^^^^^^^^^^^^^^^^^^^^^^^^^^^^^^^^^^^^^
  File "/djangoapp/trigger_web_scraping_dou_api/scrapers.py", line 334, in run_scraper_using_clone_instances_when_secao_do1_do2_and_do3
    all_dous_response = list(executor.map(ScraperUtil.make_request_for_others_clone_api,
                       ^^^^^^^^^^^^^^^^^^^^^^^^^^^^^^^^^^^^^^^^^^^^^^^^^^^^^^^^^^^^^^^^^
  File "/usr/local/lib/python3.11/concurrent/futures/_base.py", line 619, in result_iterator
    yield _result_or_cancel(fs.pop())
          ^^^^^^^^^^^^^^^^^^^^^^^^^^^
  File "/usr/local/lib/python3.11/concurrent/futures/_base.py", line 317, in _result_or_cancel
    return fut.result(timeout)
           ^^^^^^^^^^^^^^^^^^^
  File "/usr/local/lib/python3.11/concurrent/futures/_base.py", line 449, in result
    return self.__get_result()
           ^^^^^^^^^^^^^^^^^^^
  File "/usr/local/lib/python3.11/concurrent/futures/_base.py", line 401, in __get_result
    raise self._exception
  File "/usr/local/lib/python3.11/concurrent/futures/thread.py", line 58, in run
    result = self.fn(*self.args, **self.kwargs)
             ^^^^^^^^^^^^^^^^^^^^^^^^^^^^^^^^^^
  File "/djangoapp/trigger_web_scraping_dou_api/scrapers.py", line 344, in make_request_for_others_clone_api
    response = requests.get(url)
               ^^^^^^^^^^^^^^^^^
  File "/venv/lib/python3.11/site-packages/requests/api.py", line 73, in get
    return request("get", url, params=params, **kwargs)
           ^^^^^^^^^^^^^^^^^^^^^^^^^^^^^^^^^^^^^^^^^^^^
  File "/venv/lib/python3.11/site-packages/requests/api.py", line 59, in request
    return session.request(method=method, url=url, **kwargs)
           ^^^^^^^^^^^^^^^^^^^^^^^^^^^^^^^^^^^^^^^^^^^^^^^^^
  File "/venv/lib/python3.11/site-packages/requests/sessions.py", line 589, in request
    resp = self.send(prep, **send_kwargs)
           ^^^^^^^^^^^^^^^^^^^^^^^^^^^^^^
  File "/venv/lib/python3.11/site-packages/requests/sessions.py", line 703, in send
    r = adapter.send(request, **kwargs)
        ^^^^^^^^^^^^^^^^^^^^^^^^^^^^^^^
  File "/venv/lib/python3.11/site-packages/requests/adapters.py", line 519, in send
    raise ConnectionError(e, request=request)
requests.exceptions.ConnectionError: HTTPConnectionPool(host='djangoappclonetwo', port=8002): Max retries exceeded with url: /trigger_web_scraping_dou_api/?secao=do2&data=19-01-2024&detailDOUJournalFlag=True (Caused by NewConnectionError('<urllib3.connection.HTTPConnection object at 0x7f74a9905550>: Failed to establish a new connection: [Errno 111] Connection refused'))
2024-01-19 01:37:37,636 - django.utils.autoreload - INFO - /djangoapp/trigger_web_scraping_dou_api/scrapers.py changed, reloading.
2024-01-19 01:39:21,778 - django.utils.autoreload - INFO - /djangoapp/trigger_web_scraping_dou_api/scrapers.py changed, reloading.
2024-01-19 01:40:24,881 - django.request - ERROR - Internal Server Error: /trigger_web_scraping_dou_api/
Traceback (most recent call last):
  File "/venv/lib/python3.11/site-packages/django/core/handlers/exception.py", line 55, in inner
    response = get_response(request)
               ^^^^^^^^^^^^^^^^^^^^^
  File "/venv/lib/python3.11/site-packages/django/core/handlers/base.py", line 197, in _get_response
    response = wrapped_callback(request, *callback_args, **callback_kwargs)
               ^^^^^^^^^^^^^^^^^^^^^^^^^^^^^^^^^^^^^^^^^^^^^^^^^^^^^^^^^^^^
  File "/venv/lib/python3.11/site-packages/django/views/decorators/csrf.py", line 56, in wrapper_view
    return view_func(*args, **kwargs)
           ^^^^^^^^^^^^^^^^^^^^^^^^^^
  File "/venv/lib/python3.11/site-packages/django/views/generic/base.py", line 104, in view
    return self.dispatch(request, *args, **kwargs)
           ^^^^^^^^^^^^^^^^^^^^^^^^^^^^^^^^^^^^^^^
  File "/venv/lib/python3.11/site-packages/rest_framework/views.py", line 509, in dispatch
    response = self.handle_exception(exc)
               ^^^^^^^^^^^^^^^^^^^^^^^^^^
  File "/venv/lib/python3.11/site-packages/rest_framework/views.py", line 469, in handle_exception
    self.raise_uncaught_exception(exc)
  File "/venv/lib/python3.11/site-packages/rest_framework/views.py", line 480, in raise_uncaught_exception
    raise exc
  File "/venv/lib/python3.11/site-packages/rest_framework/views.py", line 506, in dispatch
    response = handler(request, *args, **kwargs)
               ^^^^^^^^^^^^^^^^^^^^^^^^^^^^^^^^^
  File "/djangoapp/trigger_web_scraping_dou_api/views.py", line 58, in get
    return self.handle_URL_empty_params(saveInDBFlag, detailDOUJournalFlag)
           ^^^^^^^^^^^^^^^^^^^^^^^^^^^^^^^^^^^^^^^^^^^^^^^^^^^^^^^^^^^^^^^^
  File "/djangoapp/trigger_web_scraping_dou_api/views.py", line 192, in handle_URL_empty_params
    response = ScraperUtil.run_scraper_with_empty_params_using_clone_instances(detailDOUJournalFlag)
               ^^^^^^^^^^^^^^^^^^^^^^^^^^^^^^^^^^^^^^^^^^^^^^^^^^^^^^^^^^^^^^^^^^^^^^^^^^^^^^^^^^^^^
  File "/djangoapp/trigger_web_scraping_dou_api/scrapers.py", line 292, in run_scraper_with_empty_params_using_clone_instances
    return ScraperUtil.run_scraper_using_clone_instances_when_secao_do1_do2_and_do3(date_now_db_and_brazilian_format,
          ^^^^^^^^^^^^^^^^^^^^^^^^^^^^^^^^^^^^^^^^^^^^^^^^^^^^^^^^^^^^^^^^^^^^^^^^^^^^^^^^^^^^^^^^^^^^^^^^^^^^^^^^^^^
  File "/djangoapp/trigger_web_scraping_dou_api/scrapers.py", line 334, in run_scraper_using_clone_instances_when_secao_do1_do2_and_do3
    all_dous_response = list(executor.map(ScraperUtil.make_request_for_others_clone_api,
                       ^^^^^^^^^^^^^^^^^^^^^^^^^^^^^^^^^^^^^^^^^^^^^^^^^^^^^^^^^^^^^^^^^
  File "/usr/local/lib/python3.11/concurrent/futures/_base.py", line 619, in result_iterator
    yield _result_or_cancel(fs.pop())
          ^^^^^^^^^^^^^^^^^^^^^^^^^^^
  File "/usr/local/lib/python3.11/concurrent/futures/_base.py", line 317, in _result_or_cancel
    return fut.result(timeout)
           ^^^^^^^^^^^^^^^^^^^
  File "/usr/local/lib/python3.11/concurrent/futures/_base.py", line 456, in result
    return self.__get_result()
           ^^^^^^^^^^^^^^^^^^^
  File "/usr/local/lib/python3.11/concurrent/futures/_base.py", line 401, in __get_result
    raise self._exception
  File "/usr/local/lib/python3.11/concurrent/futures/thread.py", line 58, in run
    result = self.fn(*self.args, **self.kwargs)
             ^^^^^^^^^^^^^^^^^^^^^^^^^^^^^^^^^^
  File "/djangoapp/trigger_web_scraping_dou_api/scrapers.py", line 353, in make_request_for_others_clone_api
    raise Exception(f"Erro na requisição para {url}. Status code: {response.status_code}")
Exception: Erro na requisição para http://djangoappcloneone:8001/trigger_web_scraping_dou_api/?secao=do1&data=19-01-2024&detailDOUJournalFlag=True. Status code: 500
2024-01-19 01:43:15,160 - django.utils.autoreload - INFO - /djangoapp/trigger_web_scraping_dou_api/scrapers.py changed, reloading.
2024-01-19 01:45:27,820 - django.request - WARNING - Not Found: /favicon.ico
2024-01-19 01:47:48,424 - django.utils.autoreload - INFO - /djangoapp/trigger_web_scraping_dou_api/scrapers.py changed, reloading.
2024-01-19 01:49:03,469 - django.request - ERROR - Internal Server Error: /trigger_web_scraping_dou_api/
Traceback (most recent call last):
  File "/venv/lib/python3.11/site-packages/requests/models.py", line 971, in json
    return complexjson.loads(self.text, **kwargs)
           ^^^^^^^^^^^^^^^^^^^^^^^^^^^^^^^^^^^^^^
  File "/usr/local/lib/python3.11/json/__init__.py", line 346, in loads
    return _default_decoder.decode(s)
           ^^^^^^^^^^^^^^^^^^^^^^^^^^
  File "/usr/local/lib/python3.11/json/decoder.py", line 337, in decode
    obj, end = self.raw_decode(s, idx=_w(s, 0).end())
               ^^^^^^^^^^^^^^^^^^^^^^^^^^^^^^^^^^^^^^
  File "/usr/local/lib/python3.11/json/decoder.py", line 355, in raw_decode
    raise JSONDecodeError("Expecting value", s, err.value) from None
json.decoder.JSONDecodeError: Expecting value: line 2 column 1 (char 1)

During handling of the above exception, another exception occurred:

Traceback (most recent call last):
  File "/venv/lib/python3.11/site-packages/django/core/handlers/exception.py", line 55, in inner
    response = get_response(request)
               ^^^^^^^^^^^^^^^^^^^^^
  File "/venv/lib/python3.11/site-packages/django/core/handlers/base.py", line 197, in _get_response
    response = wrapped_callback(request, *callback_args, **callback_kwargs)
               ^^^^^^^^^^^^^^^^^^^^^^^^^^^^^^^^^^^^^^^^^^^^^^^^^^^^^^^^^^^^
  File "/venv/lib/python3.11/site-packages/django/views/decorators/csrf.py", line 56, in wrapper_view
    return view_func(*args, **kwargs)
           ^^^^^^^^^^^^^^^^^^^^^^^^^^
  File "/venv/lib/python3.11/site-packages/django/views/generic/base.py", line 104, in view
    return self.dispatch(request, *args, **kwargs)
           ^^^^^^^^^^^^^^^^^^^^^^^^^^^^^^^^^^^^^^^
  File "/venv/lib/python3.11/site-packages/rest_framework/views.py", line 509, in dispatch
    response = self.handle_exception(exc)
               ^^^^^^^^^^^^^^^^^^^^^^^^^^
  File "/venv/lib/python3.11/site-packages/rest_framework/views.py", line 469, in handle_exception
    self.raise_uncaught_exception(exc)
  File "/venv/lib/python3.11/site-packages/rest_framework/views.py", line 480, in raise_uncaught_exception
    raise exc
  File "/venv/lib/python3.11/site-packages/rest_framework/views.py", line 506, in dispatch
    response = handler(request, *args, **kwargs)
               ^^^^^^^^^^^^^^^^^^^^^^^^^^^^^^^^^
  File "/djangoapp/trigger_web_scraping_dou_api/views.py", line 58, in get
    return self.handle_URL_empty_params(saveInDBFlag, detailDOUJournalFlag)
           ^^^^^^^^^^^^^^^^^^^^^^^^^^^^^^^^^^^^^^^^^^^^^^^^^^^^^^^^^^^^^^^^
  File "/djangoapp/trigger_web_scraping_dou_api/views.py", line 192, in handle_URL_empty_params
    response = ScraperUtil.run_scraper_with_empty_params_using_clone_instances(detailDOUJournalFlag)
               ^^^^^^^^^^^^^^^^^^^^^^^^^^^^^^^^^^^^^^^^^^^^^^^^^^^^^^^^^^^^^^^^^^^^^^^^^^^^^^^^^^^^^
  File "/djangoapp/trigger_web_scraping_dou_api/scrapers.py", line 292, in run_scraper_with_empty_params_using_clone_instances
    return ScraperUtil.run_scraper_using_clone_instances_when_secao_do1_do2_and_do3(date_now_db_and_brazilian_format,
          ^^^^^^^^^^^^^^^^^^^^^^^^^^^^^^^^^^^^^^^^^^^^^^^^^^^^^^^^^^^^^^^^^^^^^^^^^^^^^^^^^^^^^^^^^^^^^^^^^^^^^^^^^^^
  File "/djangoapp/trigger_web_scraping_dou_api/scrapers.py", line 334, in run_scraper_using_clone_instances_when_secao_do1_do2_and_do3
    all_dous_response = list(executor.map(ScraperUtil.make_request_for_others_clone_api,
                       ^^^^^^^^^^^^^^^^^^^^^^^^^^^^^^^^^^^^^^^^^^^^^^^^^^^^^^^^^^^^^^^^^
  File "/usr/local/lib/python3.11/concurrent/futures/_base.py", line 619, in result_iterator
    yield _result_or_cancel(fs.pop())
          ^^^^^^^^^^^^^^^^^^^^^^^^^^^
  File "/usr/local/lib/python3.11/concurrent/futures/_base.py", line 317, in _result_or_cancel
    return fut.result(timeout)
           ^^^^^^^^^^^^^^^^^^^
  File "/usr/local/lib/python3.11/concurrent/futures/_base.py", line 456, in result
    return self.__get_result()
           ^^^^^^^^^^^^^^^^^^^
  File "/usr/local/lib/python3.11/concurrent/futures/_base.py", line 401, in __get_result
    raise self._exception
  File "/usr/local/lib/python3.11/concurrent/futures/thread.py", line 58, in run
    result = self.fn(*self.args, **self.kwargs)
             ^^^^^^^^^^^^^^^^^^^^^^^^^^^^^^^^^^
  File "/djangoapp/trigger_web_scraping_dou_api/scrapers.py", line 355, in make_request_for_others_clone_api
    return response.json()
           ^^^^^^^^^^^^^^^
  File "/venv/lib/python3.11/site-packages/requests/models.py", line 975, in json
    raise RequestsJSONDecodeError(e.msg, e.doc, e.pos)
requests.exceptions.JSONDecodeError: Expecting value: line 2 column 1 (char 1)
2024-01-19 01:49:03,622 - django.request - WARNING - Not Found: /favicon.ico
2024-01-19 01:52:04,004 - django.utils.autoreload - INFO - /djangoapp/trigger_web_scraping_dou_api/scrapers.py changed, reloading.
2024-01-19 01:54:34,548 - django.utils.autoreload - INFO - /djangoapp/trigger_web_scraping_dou_api/scrapers.py changed, reloading.
2024-01-19 01:56:13,872 - django.request - ERROR - Internal Server Error: /trigger_web_scraping_dou_api/
Traceback (most recent call last):
  File "/venv/lib/python3.11/site-packages/requests/models.py", line 971, in json
    return complexjson.loads(self.text, **kwargs)
           ^^^^^^^^^^^^^^^^^^^^^^^^^^^^^^^^^^^^^^
  File "/usr/local/lib/python3.11/json/__init__.py", line 346, in loads
    return _default_decoder.decode(s)
           ^^^^^^^^^^^^^^^^^^^^^^^^^^
  File "/usr/local/lib/python3.11/json/decoder.py", line 337, in decode
    obj, end = self.raw_decode(s, idx=_w(s, 0).end())
               ^^^^^^^^^^^^^^^^^^^^^^^^^^^^^^^^^^^^^^
  File "/usr/local/lib/python3.11/json/decoder.py", line 355, in raw_decode
    raise JSONDecodeError("Expecting value", s, err.value) from None
json.decoder.JSONDecodeError: Expecting value: line 2 column 1 (char 1)

During handling of the above exception, another exception occurred:

Traceback (most recent call last):
  File "/djangoapp/trigger_web_scraping_dou_api/scrapers.py", line 356, in make_request_for_others_clone_api
    return response.json()
           ^^^^^^^^^^^^^^^
  File "/venv/lib/python3.11/site-packages/requests/models.py", line 975, in json
    raise RequestsJSONDecodeError(e.msg, e.doc, e.pos)
requests.exceptions.JSONDecodeError: Expecting value: line 2 column 1 (char 1)

During handling of the above exception, another exception occurred:

Traceback (most recent call last):
  File "/venv/lib/python3.11/site-packages/django/core/handlers/exception.py", line 55, in inner
    response = get_response(request)
               ^^^^^^^^^^^^^^^^^^^^^
  File "/venv/lib/python3.11/site-packages/django/core/handlers/base.py", line 197, in _get_response
    response = wrapped_callback(request, *callback_args, **callback_kwargs)
               ^^^^^^^^^^^^^^^^^^^^^^^^^^^^^^^^^^^^^^^^^^^^^^^^^^^^^^^^^^^^
  File "/venv/lib/python3.11/site-packages/django/views/decorators/csrf.py", line 56, in wrapper_view
    return view_func(*args, **kwargs)
           ^^^^^^^^^^^^^^^^^^^^^^^^^^
  File "/venv/lib/python3.11/site-packages/django/views/generic/base.py", line 104, in view
    return self.dispatch(request, *args, **kwargs)
           ^^^^^^^^^^^^^^^^^^^^^^^^^^^^^^^^^^^^^^^
  File "/venv/lib/python3.11/site-packages/rest_framework/views.py", line 509, in dispatch
    response = self.handle_exception(exc)
               ^^^^^^^^^^^^^^^^^^^^^^^^^^
  File "/venv/lib/python3.11/site-packages/rest_framework/views.py", line 469, in handle_exception
    self.raise_uncaught_exception(exc)
  File "/venv/lib/python3.11/site-packages/rest_framework/views.py", line 480, in raise_uncaught_exception
    raise exc
  File "/venv/lib/python3.11/site-packages/rest_framework/views.py", line 506, in dispatch
    response = handler(request, *args, **kwargs)
               ^^^^^^^^^^^^^^^^^^^^^^^^^^^^^^^^^
  File "/djangoapp/trigger_web_scraping_dou_api/views.py", line 58, in get
    return self.handle_URL_empty_params(saveInDBFlag, detailDOUJournalFlag)
           ^^^^^^^^^^^^^^^^^^^^^^^^^^^^^^^^^^^^^^^^^^^^^^^^^^^^^^^^^^^^^^^^
  File "/djangoapp/trigger_web_scraping_dou_api/views.py", line 192, in handle_URL_empty_params
    response = ScraperUtil.run_scraper_with_empty_params_using_clone_instances(detailDOUJournalFlag)
               ^^^^^^^^^^^^^^^^^^^^^^^^^^^^^^^^^^^^^^^^^^^^^^^^^^^^^^^^^^^^^^^^^^^^^^^^^^^^^^^^^^^^^
  File "/djangoapp/trigger_web_scraping_dou_api/scrapers.py", line 292, in run_scraper_with_empty_params_using_clone_instances
    return ScraperUtil.run_scraper_using_clone_instances_when_secao_do1_do2_and_do3(date_now_db_and_brazilian_format,
          ^^^^^^^^^^^^^^^^^^^^^^^^^^^^^^^^^^^^^^^^^^^^^^^^^^^^^^^^^^^^^^^^^^^^^^^^^^^^^^^^^^^^^^^^^^^^^^^^^^^^^^^^^^^
  File "/djangoapp/trigger_web_scraping_dou_api/scrapers.py", line 334, in run_scraper_using_clone_instances_when_secao_do1_do2_and_do3
    all_dous_response = list(executor.map(ScraperUtil.make_request_for_others_clone_api,
                       ^^^^^^^^^^^^^^^^^^^^^^^^^^^^^^^^^^^^^^^^^^^^^^^^^^^^^^^^^^^^^^^^^
  File "/usr/local/lib/python3.11/concurrent/futures/_base.py", line 619, in result_iterator
    yield _result_or_cancel(fs.pop())
          ^^^^^^^^^^^^^^^^^^^^^^^^^^^
  File "/usr/local/lib/python3.11/concurrent/futures/_base.py", line 317, in _result_or_cancel
    return fut.result(timeout)
           ^^^^^^^^^^^^^^^^^^^
  File "/usr/local/lib/python3.11/concurrent/futures/_base.py", line 456, in result
    return self.__get_result()
           ^^^^^^^^^^^^^^^^^^^
  File "/usr/local/lib/python3.11/concurrent/futures/_base.py", line 401, in __get_result
    raise self._exception
  File "/usr/local/lib/python3.11/concurrent/futures/thread.py", line 58, in run
    result = self.fn(*self.args, **self.kwargs)
             ^^^^^^^^^^^^^^^^^^^^^^^^^^^^^^^^^^
  File "/djangoapp/trigger_web_scraping_dou_api/scrapers.py", line 362, in make_request_for_others_clone_api
    json_string_response = json.dumps(response)
                           ^^^^^^^^^^^^^^^^^^^^
  File "/usr/local/lib/python3.11/json/__init__.py", line 231, in dumps
    return _default_encoder.encode(obj)
           ^^^^^^^^^^^^^^^^^^^^^^^^^^^^
  File "/usr/local/lib/python3.11/json/encoder.py", line 200, in encode
    chunks = self.iterencode(o, _one_shot=True)
             ^^^^^^^^^^^^^^^^^^^^^^^^^^^^^^^^^^
  File "/usr/local/lib/python3.11/json/encoder.py", line 258, in iterencode
    return _iterencode(o, 0)
           ^^^^^^^^^^^^^^^^^
  File "/usr/local/lib/python3.11/json/encoder.py", line 180, in default
    raise TypeError(f'Object of type {o.__class__.__name__} '
TypeError: Object of type Response is not JSON serializable
2024-01-19 01:58:07,374 - django.request - ERROR - Internal Server Error: /trigger_web_scraping_dou_api/
Traceback (most recent call last):
  File "/venv/lib/python3.11/site-packages/requests/models.py", line 971, in json
    return complexjson.loads(self.text, **kwargs)
           ^^^^^^^^^^^^^^^^^^^^^^^^^^^^^^^^^^^^^^
  File "/usr/local/lib/python3.11/json/__init__.py", line 346, in loads
    return _default_decoder.decode(s)
           ^^^^^^^^^^^^^^^^^^^^^^^^^^
  File "/usr/local/lib/python3.11/json/decoder.py", line 337, in decode
    obj, end = self.raw_decode(s, idx=_w(s, 0).end())
               ^^^^^^^^^^^^^^^^^^^^^^^^^^^^^^^^^^^^^^
  File "/usr/local/lib/python3.11/json/decoder.py", line 355, in raw_decode
    raise JSONDecodeError("Expecting value", s, err.value) from None
json.decoder.JSONDecodeError: Expecting value: line 2 column 1 (char 1)

During handling of the above exception, another exception occurred:

Traceback (most recent call last):
  File "/djangoapp/trigger_web_scraping_dou_api/scrapers.py", line 356, in make_request_for_others_clone_api
    return response.json()
           ^^^^^^^^^^^^^^^
  File "/venv/lib/python3.11/site-packages/requests/models.py", line 975, in json
    raise RequestsJSONDecodeError(e.msg, e.doc, e.pos)
requests.exceptions.JSONDecodeError: Expecting value: line 2 column 1 (char 1)

During handling of the above exception, another exception occurred:

Traceback (most recent call last):
  File "/venv/lib/python3.11/site-packages/django/core/handlers/exception.py", line 55, in inner
    response = get_response(request)
               ^^^^^^^^^^^^^^^^^^^^^
  File "/venv/lib/python3.11/site-packages/django/core/handlers/base.py", line 197, in _get_response
    response = wrapped_callback(request, *callback_args, **callback_kwargs)
               ^^^^^^^^^^^^^^^^^^^^^^^^^^^^^^^^^^^^^^^^^^^^^^^^^^^^^^^^^^^^
  File "/venv/lib/python3.11/site-packages/django/views/decorators/csrf.py", line 56, in wrapper_view
    return view_func(*args, **kwargs)
           ^^^^^^^^^^^^^^^^^^^^^^^^^^
  File "/venv/lib/python3.11/site-packages/django/views/generic/base.py", line 104, in view
    return self.dispatch(request, *args, **kwargs)
           ^^^^^^^^^^^^^^^^^^^^^^^^^^^^^^^^^^^^^^^
  File "/venv/lib/python3.11/site-packages/rest_framework/views.py", line 509, in dispatch
    response = self.handle_exception(exc)
               ^^^^^^^^^^^^^^^^^^^^^^^^^^
  File "/venv/lib/python3.11/site-packages/rest_framework/views.py", line 469, in handle_exception
    self.raise_uncaught_exception(exc)
  File "/venv/lib/python3.11/site-packages/rest_framework/views.py", line 480, in raise_uncaught_exception
    raise exc
  File "/venv/lib/python3.11/site-packages/rest_framework/views.py", line 506, in dispatch
    response = handler(request, *args, **kwargs)
               ^^^^^^^^^^^^^^^^^^^^^^^^^^^^^^^^^
  File "/djangoapp/trigger_web_scraping_dou_api/views.py", line 58, in get
    return self.handle_URL_empty_params(saveInDBFlag, detailDOUJournalFlag)
           ^^^^^^^^^^^^^^^^^^^^^^^^^^^^^^^^^^^^^^^^^^^^^^^^^^^^^^^^^^^^^^^^
  File "/djangoapp/trigger_web_scraping_dou_api/views.py", line 192, in handle_URL_empty_params
    response = ScraperUtil.run_scraper_with_empty_params_using_clone_instances(detailDOUJournalFlag)
               ^^^^^^^^^^^^^^^^^^^^^^^^^^^^^^^^^^^^^^^^^^^^^^^^^^^^^^^^^^^^^^^^^^^^^^^^^^^^^^^^^^^^^
  File "/djangoapp/trigger_web_scraping_dou_api/scrapers.py", line 292, in run_scraper_with_empty_params_using_clone_instances
    return ScraperUtil.run_scraper_using_clone_instances_when_secao_do1_do2_and_do3(date_now_db_and_brazilian_format,
          ^^^^^^^^^^^^^^^^^^^^^^^^^^^^^^^^^^^^^^^^^^^^^^^^^^^^^^^^^^^^^^^^^^^^^^^^^^^^^^^^^^^^^^^^^^^^^^^^^^^^^^^^^^^
  File "/djangoapp/trigger_web_scraping_dou_api/scrapers.py", line 334, in run_scraper_using_clone_instances_when_secao_do1_do2_and_do3
    all_dous_response = list(executor.map(ScraperUtil.make_request_for_others_clone_api,
                       ^^^^^^^^^^^^^^^^^^^^^^^^^^^^^^^^^^^^^^^^^^^^^^^^^^^^^^^^^^^^^^^^^
  File "/usr/local/lib/python3.11/concurrent/futures/_base.py", line 619, in result_iterator
    yield _result_or_cancel(fs.pop())
          ^^^^^^^^^^^^^^^^^^^^^^^^^^^
  File "/usr/local/lib/python3.11/concurrent/futures/_base.py", line 317, in _result_or_cancel
    return fut.result(timeout)
           ^^^^^^^^^^^^^^^^^^^
  File "/usr/local/lib/python3.11/concurrent/futures/_base.py", line 449, in result
    return self.__get_result()
           ^^^^^^^^^^^^^^^^^^^
  File "/usr/local/lib/python3.11/concurrent/futures/_base.py", line 401, in __get_result
    raise self._exception
  File "/usr/local/lib/python3.11/concurrent/futures/thread.py", line 58, in run
    result = self.fn(*self.args, **self.kwargs)
             ^^^^^^^^^^^^^^^^^^^^^^^^^^^^^^^^^^
  File "/djangoapp/trigger_web_scraping_dou_api/scrapers.py", line 362, in make_request_for_others_clone_api
    json_string_response = json.dumps(response)
                           ^^^^^^^^^^^^^^^^^^^^
  File "/usr/local/lib/python3.11/json/__init__.py", line 231, in dumps
    return _default_encoder.encode(obj)
           ^^^^^^^^^^^^^^^^^^^^^^^^^^^^
  File "/usr/local/lib/python3.11/json/encoder.py", line 200, in encode
    chunks = self.iterencode(o, _one_shot=True)
             ^^^^^^^^^^^^^^^^^^^^^^^^^^^^^^^^^^
  File "/usr/local/lib/python3.11/json/encoder.py", line 258, in iterencode
    return _iterencode(o, 0)
           ^^^^^^^^^^^^^^^^^
  File "/usr/local/lib/python3.11/json/encoder.py", line 180, in default
    raise TypeError(f'Object of type {o.__class__.__name__} '
TypeError: Object of type Response is not JSON serializable
2024-01-19 01:58:07,509 - django.request - WARNING - Not Found: /favicon.ico
2024-01-19 02:03:58,425 - django.request - ERROR - Internal Server Error: /trigger_web_scraping_dou_api/
Traceback (most recent call last):
  File "/venv/lib/python3.11/site-packages/requests/models.py", line 971, in json
    return complexjson.loads(self.text, **kwargs)
           ^^^^^^^^^^^^^^^^^^^^^^^^^^^^^^^^^^^^^^
  File "/usr/local/lib/python3.11/json/__init__.py", line 346, in loads
    return _default_decoder.decode(s)
           ^^^^^^^^^^^^^^^^^^^^^^^^^^
  File "/usr/local/lib/python3.11/json/decoder.py", line 337, in decode
    obj, end = self.raw_decode(s, idx=_w(s, 0).end())
               ^^^^^^^^^^^^^^^^^^^^^^^^^^^^^^^^^^^^^^
  File "/usr/local/lib/python3.11/json/decoder.py", line 355, in raw_decode
    raise JSONDecodeError("Expecting value", s, err.value) from None
json.decoder.JSONDecodeError: Expecting value: line 2 column 1 (char 1)

During handling of the above exception, another exception occurred:

Traceback (most recent call last):
  File "/djangoapp/trigger_web_scraping_dou_api/scrapers.py", line 356, in make_request_for_others_clone_api
    return response.json()
           ^^^^^^^^^^^^^^^
  File "/venv/lib/python3.11/site-packages/requests/models.py", line 975, in json
    raise RequestsJSONDecodeError(e.msg, e.doc, e.pos)
requests.exceptions.JSONDecodeError: Expecting value: line 2 column 1 (char 1)

During handling of the above exception, another exception occurred:

Traceback (most recent call last):
  File "/venv/lib/python3.11/site-packages/django/core/handlers/exception.py", line 55, in inner
    response = get_response(request)
               ^^^^^^^^^^^^^^^^^^^^^
  File "/venv/lib/python3.11/site-packages/django/core/handlers/base.py", line 197, in _get_response
    response = wrapped_callback(request, *callback_args, **callback_kwargs)
               ^^^^^^^^^^^^^^^^^^^^^^^^^^^^^^^^^^^^^^^^^^^^^^^^^^^^^^^^^^^^
  File "/venv/lib/python3.11/site-packages/django/views/decorators/csrf.py", line 56, in wrapper_view
    return view_func(*args, **kwargs)
           ^^^^^^^^^^^^^^^^^^^^^^^^^^
  File "/venv/lib/python3.11/site-packages/django/views/generic/base.py", line 104, in view
    return self.dispatch(request, *args, **kwargs)
           ^^^^^^^^^^^^^^^^^^^^^^^^^^^^^^^^^^^^^^^
  File "/venv/lib/python3.11/site-packages/rest_framework/views.py", line 509, in dispatch
    response = self.handle_exception(exc)
               ^^^^^^^^^^^^^^^^^^^^^^^^^^
  File "/venv/lib/python3.11/site-packages/rest_framework/views.py", line 469, in handle_exception
    self.raise_uncaught_exception(exc)
  File "/venv/lib/python3.11/site-packages/rest_framework/views.py", line 480, in raise_uncaught_exception
    raise exc
  File "/venv/lib/python3.11/site-packages/rest_framework/views.py", line 506, in dispatch
    response = handler(request, *args, **kwargs)
               ^^^^^^^^^^^^^^^^^^^^^^^^^^^^^^^^^
  File "/djangoapp/trigger_web_scraping_dou_api/views.py", line 58, in get
    return self.handle_URL_empty_params(saveInDBFlag, detailDOUJournalFlag)
           ^^^^^^^^^^^^^^^^^^^^^^^^^^^^^^^^^^^^^^^^^^^^^^^^^^^^^^^^^^^^^^^^
  File "/djangoapp/trigger_web_scraping_dou_api/views.py", line 192, in handle_URL_empty_params
    response = ScraperUtil.run_scraper_with_empty_params_using_clone_instances(detailDOUJournalFlag)
               ^^^^^^^^^^^^^^^^^^^^^^^^^^^^^^^^^^^^^^^^^^^^^^^^^^^^^^^^^^^^^^^^^^^^^^^^^^^^^^^^^^^^^
  File "/djangoapp/trigger_web_scraping_dou_api/scrapers.py", line 292, in run_scraper_with_empty_params_using_clone_instances
    return ScraperUtil.run_scraper_using_clone_instances_when_secao_do1_do2_and_do3(date_now_db_and_brazilian_format,
          ^^^^^^^^^^^^^^^^^^^^^^^^^^^^^^^^^^^^^^^^^^^^^^^^^^^^^^^^^^^^^^^^^^^^^^^^^^^^^^^^^^^^^^^^^^^^^^^^^^^^^^^^^^^
  File "/djangoapp/trigger_web_scraping_dou_api/scrapers.py", line 334, in run_scraper_using_clone_instances_when_secao_do1_do2_and_do3
    all_dous_response = list(executor.map(ScraperUtil.make_request_for_others_clone_api,
                       ^^^^^^^^^^^^^^^^^^^^^^^^^^^^^^^^^^^^^^^^^^^^^^^^^^^^^^^^^^^^^^^^^
  File "/usr/local/lib/python3.11/concurrent/futures/_base.py", line 619, in result_iterator
    yield _result_or_cancel(fs.pop())
          ^^^^^^^^^^^^^^^^^^^^^^^^^^^
  File "/usr/local/lib/python3.11/concurrent/futures/_base.py", line 317, in _result_or_cancel
    return fut.result(timeout)
           ^^^^^^^^^^^^^^^^^^^
  File "/usr/local/lib/python3.11/concurrent/futures/_base.py", line 449, in result
    return self.__get_result()
           ^^^^^^^^^^^^^^^^^^^
  File "/usr/local/lib/python3.11/concurrent/futures/_base.py", line 401, in __get_result
    raise self._exception
  File "/usr/local/lib/python3.11/concurrent/futures/thread.py", line 58, in run
    result = self.fn(*self.args, **self.kwargs)
             ^^^^^^^^^^^^^^^^^^^^^^^^^^^^^^^^^^
  File "/djangoapp/trigger_web_scraping_dou_api/scrapers.py", line 362, in make_request_for_others_clone_api
    json_string_response = json.dumps(response)
                           ^^^^^^^^^^^^^^^^^^^^
  File "/usr/local/lib/python3.11/json/__init__.py", line 231, in dumps
    return _default_encoder.encode(obj)
           ^^^^^^^^^^^^^^^^^^^^^^^^^^^^
  File "/usr/local/lib/python3.11/json/encoder.py", line 200, in encode
    chunks = self.iterencode(o, _one_shot=True)
             ^^^^^^^^^^^^^^^^^^^^^^^^^^^^^^^^^^
  File "/usr/local/lib/python3.11/json/encoder.py", line 258, in iterencode
    return _iterencode(o, 0)
           ^^^^^^^^^^^^^^^^^
  File "/usr/local/lib/python3.11/json/encoder.py", line 180, in default
    raise TypeError(f'Object of type {o.__class__.__name__} '
TypeError: Object of type Response is not JSON serializable
2024-01-19 02:03:58,549 - django.request - WARNING - Not Found: /favicon.ico
2024-01-19 02:05:27,527 - django.utils.autoreload - INFO - /djangoapp/trigger_web_scraping_dou_api/scrapers.py changed, reloading.
2024-01-19 02:06:27,480 - django.utils.autoreload - INFO - /djangoapp/trigger_web_scraping_dou_api/scrapers.py changed, reloading.
2024-01-19 02:07:01,390 - django.request - ERROR - Internal Server Error: /trigger_web_scraping_dou_api/
Traceback (most recent call last):
  File "/venv/lib/python3.11/site-packages/requests/models.py", line 971, in json
    return complexjson.loads(self.text, **kwargs)
           ^^^^^^^^^^^^^^^^^^^^^^^^^^^^^^^^^^^^^^
  File "/usr/local/lib/python3.11/json/__init__.py", line 346, in loads
    return _default_decoder.decode(s)
           ^^^^^^^^^^^^^^^^^^^^^^^^^^
  File "/usr/local/lib/python3.11/json/decoder.py", line 337, in decode
    obj, end = self.raw_decode(s, idx=_w(s, 0).end())
               ^^^^^^^^^^^^^^^^^^^^^^^^^^^^^^^^^^^^^^
  File "/usr/local/lib/python3.11/json/decoder.py", line 355, in raw_decode
    raise JSONDecodeError("Expecting value", s, err.value) from None
json.decoder.JSONDecodeError: Expecting value: line 2 column 1 (char 1)

During handling of the above exception, another exception occurred:

Traceback (most recent call last):
  File "/djangoapp/trigger_web_scraping_dou_api/scrapers.py", line 358, in make_request_for_others_clone_api
    return response.json()
           ^^^^^^^^^^^^^^^
  File "/venv/lib/python3.11/site-packages/requests/models.py", line 975, in json
    raise RequestsJSONDecodeError(e.msg, e.doc, e.pos)
requests.exceptions.JSONDecodeError: Expecting value: line 2 column 1 (char 1)

During handling of the above exception, another exception occurred:

Traceback (most recent call last):
  File "/venv/lib/python3.11/site-packages/django/core/handlers/exception.py", line 55, in inner
    response = get_response(request)
               ^^^^^^^^^^^^^^^^^^^^^
  File "/venv/lib/python3.11/site-packages/django/core/handlers/base.py", line 197, in _get_response
    response = wrapped_callback(request, *callback_args, **callback_kwargs)
               ^^^^^^^^^^^^^^^^^^^^^^^^^^^^^^^^^^^^^^^^^^^^^^^^^^^^^^^^^^^^
  File "/venv/lib/python3.11/site-packages/django/views/decorators/csrf.py", line 56, in wrapper_view
    return view_func(*args, **kwargs)
           ^^^^^^^^^^^^^^^^^^^^^^^^^^
  File "/venv/lib/python3.11/site-packages/django/views/generic/base.py", line 104, in view
    return self.dispatch(request, *args, **kwargs)
           ^^^^^^^^^^^^^^^^^^^^^^^^^^^^^^^^^^^^^^^
  File "/venv/lib/python3.11/site-packages/rest_framework/views.py", line 509, in dispatch
    response = self.handle_exception(exc)
               ^^^^^^^^^^^^^^^^^^^^^^^^^^
  File "/venv/lib/python3.11/site-packages/rest_framework/views.py", line 469, in handle_exception
    self.raise_uncaught_exception(exc)
  File "/venv/lib/python3.11/site-packages/rest_framework/views.py", line 480, in raise_uncaught_exception
    raise exc
  File "/venv/lib/python3.11/site-packages/rest_framework/views.py", line 506, in dispatch
    response = handler(request, *args, **kwargs)
               ^^^^^^^^^^^^^^^^^^^^^^^^^^^^^^^^^
  File "/djangoapp/trigger_web_scraping_dou_api/views.py", line 58, in get
    return self.handle_URL_empty_params(saveInDBFlag, detailDOUJournalFlag)
           ^^^^^^^^^^^^^^^^^^^^^^^^^^^^^^^^^^^^^^^^^^^^^^^^^^^^^^^^^^^^^^^^
  File "/djangoapp/trigger_web_scraping_dou_api/views.py", line 192, in handle_URL_empty_params
    response = ScraperUtil.run_scraper_with_empty_params_using_clone_instances(detailDOUJournalFlag)
               ^^^^^^^^^^^^^^^^^^^^^^^^^^^^^^^^^^^^^^^^^^^^^^^^^^^^^^^^^^^^^^^^^^^^^^^^^^^^^^^^^^^^^
  File "/djangoapp/trigger_web_scraping_dou_api/scrapers.py", line 292, in run_scraper_with_empty_params_using_clone_instances
    return ScraperUtil.run_scraper_using_clone_instances_when_secao_do1_do2_and_do3(date_now_db_and_brazilian_format,
          ^^^^^^^^^^^^^^^^^^^^^^^^^^^^^^^^^^^^^^^^^^^^^^^^^^^^^^^^^^^^^^^^^^^^^^^^^^^^^^^^^^^^^^^^^^^^^^^^^^^^^^^^^^^
  File "/djangoapp/trigger_web_scraping_dou_api/scrapers.py", line 334, in run_scraper_using_clone_instances_when_secao_do1_do2_and_do3
    all_dous_response = list(executor.map(ScraperUtil.make_request_for_others_clone_api,
                       ^^^^^^^^^^^^^^^^^^^^^^^^^^^^^^^^^^^^^^^^^^^^^^^^^^^^^^^^^^^^^^^^^
  File "/usr/local/lib/python3.11/concurrent/futures/_base.py", line 619, in result_iterator
    yield _result_or_cancel(fs.pop())
          ^^^^^^^^^^^^^^^^^^^^^^^^^^^
  File "/usr/local/lib/python3.11/concurrent/futures/_base.py", line 317, in _result_or_cancel
    return fut.result(timeout)
           ^^^^^^^^^^^^^^^^^^^
  File "/usr/local/lib/python3.11/concurrent/futures/_base.py", line 456, in result
    return self.__get_result()
           ^^^^^^^^^^^^^^^^^^^
  File "/usr/local/lib/python3.11/concurrent/futures/_base.py", line 401, in __get_result
    raise self._exception
  File "/usr/local/lib/python3.11/concurrent/futures/thread.py", line 58, in run
    result = self.fn(*self.args, **self.kwargs)
             ^^^^^^^^^^^^^^^^^^^^^^^^^^^^^^^^^^
  File "/djangoapp/trigger_web_scraping_dou_api/scrapers.py", line 364, in make_request_for_others_clone_api
    json_string_response = json.dumps(response)
                           ^^^^^^^^^^^^^^^^^^^^
  File "/usr/local/lib/python3.11/json/__init__.py", line 231, in dumps
    return _default_encoder.encode(obj)
           ^^^^^^^^^^^^^^^^^^^^^^^^^^^^
  File "/usr/local/lib/python3.11/json/encoder.py", line 200, in encode
    chunks = self.iterencode(o, _one_shot=True)
             ^^^^^^^^^^^^^^^^^^^^^^^^^^^^^^^^^^
  File "/usr/local/lib/python3.11/json/encoder.py", line 258, in iterencode
    return _iterencode(o, 0)
           ^^^^^^^^^^^^^^^^^
  File "/usr/local/lib/python3.11/json/encoder.py", line 180, in default
    raise TypeError(f'Object of type {o.__class__.__name__} '
TypeError: Object of type Response is not JSON serializable
2024-01-19 02:08:43,047 - django.utils.autoreload - INFO - /djangoapp/trigger_web_scraping_dou_api/scrapers.py changed, reloading.
2024-01-19 02:16:20,143 - django.utils.autoreload - INFO - /djangoapp/trigger_web_scraping_dou_api/services.py changed, reloading.
2024-01-19 02:23:43,741 - django.utils.autoreload - INFO - /djangoapp/trigger_web_scraping_dou_api/scrapers.py changed, reloading.
2024-01-19 02:35:57,035 - django.utils.autoreload - INFO - /djangoapp/trigger_web_scraping_dou_api/scrapers.py changed, reloading.
2024-01-19 02:47:24,240 - django.utils.autoreload - INFO - /djangoapp/trigger_web_scraping_dou_api/scrapers.py changed, reloading.
2024-01-19 02:51:50,783 - django.request - ERROR - Internal Server Error: /trigger_web_scraping_dou_api/
Traceback (most recent call last):
  File "/venv/lib/python3.11/site-packages/requests/models.py", line 971, in json
    return complexjson.loads(self.text, **kwargs)
           ^^^^^^^^^^^^^^^^^^^^^^^^^^^^^^^^^^^^^^
  File "/usr/local/lib/python3.11/json/__init__.py", line 346, in loads
    return _default_decoder.decode(s)
           ^^^^^^^^^^^^^^^^^^^^^^^^^^
  File "/usr/local/lib/python3.11/json/decoder.py", line 337, in decode
    obj, end = self.raw_decode(s, idx=_w(s, 0).end())
               ^^^^^^^^^^^^^^^^^^^^^^^^^^^^^^^^^^^^^^
  File "/usr/local/lib/python3.11/json/decoder.py", line 355, in raw_decode
    raise JSONDecodeError("Expecting value", s, err.value) from None
json.decoder.JSONDecodeError: Expecting value: line 2 column 1 (char 1)

During handling of the above exception, another exception occurred:

Traceback (most recent call last):
  File "/djangoapp/trigger_web_scraping_dou_api/scrapers.py", line 357, in make_request_for_others_clone_api
    print(response.json())
          ^^^^^^^^^^^^^^^
  File "/venv/lib/python3.11/site-packages/requests/models.py", line 975, in json
    raise RequestsJSONDecodeError(e.msg, e.doc, e.pos)
requests.exceptions.JSONDecodeError: Expecting value: line 2 column 1 (char 1)

During handling of the above exception, another exception occurred:

Traceback (most recent call last):
  File "/venv/lib/python3.11/site-packages/django/core/handlers/exception.py", line 55, in inner
    response = get_response(request)
               ^^^^^^^^^^^^^^^^^^^^^
  File "/venv/lib/python3.11/site-packages/django/core/handlers/base.py", line 197, in _get_response
    response = wrapped_callback(request, *callback_args, **callback_kwargs)
               ^^^^^^^^^^^^^^^^^^^^^^^^^^^^^^^^^^^^^^^^^^^^^^^^^^^^^^^^^^^^
  File "/venv/lib/python3.11/site-packages/django/views/decorators/csrf.py", line 56, in wrapper_view
    return view_func(*args, **kwargs)
           ^^^^^^^^^^^^^^^^^^^^^^^^^^
  File "/venv/lib/python3.11/site-packages/django/views/generic/base.py", line 104, in view
    return self.dispatch(request, *args, **kwargs)
           ^^^^^^^^^^^^^^^^^^^^^^^^^^^^^^^^^^^^^^^
  File "/venv/lib/python3.11/site-packages/rest_framework/views.py", line 509, in dispatch
    response = self.handle_exception(exc)
               ^^^^^^^^^^^^^^^^^^^^^^^^^^
  File "/venv/lib/python3.11/site-packages/rest_framework/views.py", line 469, in handle_exception
    self.raise_uncaught_exception(exc)
  File "/venv/lib/python3.11/site-packages/rest_framework/views.py", line 480, in raise_uncaught_exception
    raise exc
  File "/venv/lib/python3.11/site-packages/rest_framework/views.py", line 506, in dispatch
    response = handler(request, *args, **kwargs)
               ^^^^^^^^^^^^^^^^^^^^^^^^^^^^^^^^^
  File "/djangoapp/trigger_web_scraping_dou_api/views.py", line 58, in get
    return self.handle_URL_empty_params(saveInDBFlag, detailDOUJournalFlag)
           ^^^^^^^^^^^^^^^^^^^^^^^^^^^^^^^^^^^^^^^^^^^^^^^^^^^^^^^^^^^^^^^^
  File "/djangoapp/trigger_web_scraping_dou_api/views.py", line 192, in handle_URL_empty_params
    response = ScraperUtil.run_scraper_with_empty_params_using_clone_instances(detailDOUJournalFlag)
               ^^^^^^^^^^^^^^^^^^^^^^^^^^^^^^^^^^^^^^^^^^^^^^^^^^^^^^^^^^^^^^^^^^^^^^^^^^^^^^^^^^^^^
  File "/djangoapp/trigger_web_scraping_dou_api/scrapers.py", line 294, in run_scraper_with_empty_params_using_clone_instances
    return ScraperUtil.run_scraper_using_clone_instances_when_secao_do1_do2_and_do3(date_now_db_and_brazilian_format,
          ^^^^^^^^^^^^^^^^^^^^^^^^^^^^^^^^^^^^^^^^^^^^^^^^^^^^^^^^^^^^^^^^^^^^^^^^^^^^^^^^^^^^^^^^^^^^^^^^^^^^^^^^^^^
  File "/djangoapp/trigger_web_scraping_dou_api/scrapers.py", line 336, in run_scraper_using_clone_instances_when_secao_do1_do2_and_do3
    all_dous_response = list(executor.map(ScraperUtil.make_request_for_others_clone_api,
                       ^^^^^^^^^^^^^^^^^^^^^^^^^^^^^^^^^^^^^^^^^^^^^^^^^^^^^^^^^^^^^^^^^
  File "/usr/local/lib/python3.11/concurrent/futures/_base.py", line 619, in result_iterator
    yield _result_or_cancel(fs.pop())
          ^^^^^^^^^^^^^^^^^^^^^^^^^^^
  File "/usr/local/lib/python3.11/concurrent/futures/_base.py", line 317, in _result_or_cancel
    return fut.result(timeout)
           ^^^^^^^^^^^^^^^^^^^
  File "/usr/local/lib/python3.11/concurrent/futures/_base.py", line 456, in result
    return self.__get_result()
           ^^^^^^^^^^^^^^^^^^^
  File "/usr/local/lib/python3.11/concurrent/futures/_base.py", line 401, in __get_result
    raise self._exception
  File "/usr/local/lib/python3.11/concurrent/futures/thread.py", line 58, in run
    result = self.fn(*self.args, **self.kwargs)
             ^^^^^^^^^^^^^^^^^^^^^^^^^^^^^^^^^^
  File "/djangoapp/trigger_web_scraping_dou_api/scrapers.py", line 367, in make_request_for_others_clone_api
    json_string_response = json.dumps({"text": response})
                           ^^^^^^^^^^^^^^^^^^^^^^^^^^^^^^
  File "/usr/local/lib/python3.11/json/__init__.py", line 231, in dumps
    return _default_encoder.encode(obj)
           ^^^^^^^^^^^^^^^^^^^^^^^^^^^^
  File "/usr/local/lib/python3.11/json/encoder.py", line 200, in encode
    chunks = self.iterencode(o, _one_shot=True)
             ^^^^^^^^^^^^^^^^^^^^^^^^^^^^^^^^^^
  File "/usr/local/lib/python3.11/json/encoder.py", line 258, in iterencode
    return _iterencode(o, 0)
           ^^^^^^^^^^^^^^^^^
  File "/usr/local/lib/python3.11/json/encoder.py", line 180, in default
    raise TypeError(f'Object of type {o.__class__.__name__} '
TypeError: Object of type Response is not JSON serializable
2024-01-19 02:51:50,973 - django.request - WARNING - Not Found: /favicon.ico
2024-01-19 02:58:44,141 - django.request - ERROR - Internal Server Error: /trigger_web_scraping_dou_api/
Traceback (most recent call last):
  File "/venv/lib/python3.11/site-packages/requests/models.py", line 971, in json
    return complexjson.loads(self.text, **kwargs)
           ^^^^^^^^^^^^^^^^^^^^^^^^^^^^^^^^^^^^^^
  File "/usr/local/lib/python3.11/json/__init__.py", line 346, in loads
    return _default_decoder.decode(s)
           ^^^^^^^^^^^^^^^^^^^^^^^^^^
  File "/usr/local/lib/python3.11/json/decoder.py", line 337, in decode
    obj, end = self.raw_decode(s, idx=_w(s, 0).end())
               ^^^^^^^^^^^^^^^^^^^^^^^^^^^^^^^^^^^^^^
  File "/usr/local/lib/python3.11/json/decoder.py", line 355, in raw_decode
    raise JSONDecodeError("Expecting value", s, err.value) from None
json.decoder.JSONDecodeError: Expecting value: line 2 column 1 (char 1)

During handling of the above exception, another exception occurred:

Traceback (most recent call last):
  File "/djangoapp/trigger_web_scraping_dou_api/scrapers.py", line 357, in make_request_for_others_clone_api
    print(response.json())
          ^^^^^^^^^^^^^^^
  File "/venv/lib/python3.11/site-packages/requests/models.py", line 975, in json
    raise RequestsJSONDecodeError(e.msg, e.doc, e.pos)
requests.exceptions.JSONDecodeError: Expecting value: line 2 column 1 (char 1)

During handling of the above exception, another exception occurred:

Traceback (most recent call last):
  File "/venv/lib/python3.11/site-packages/django/core/handlers/exception.py", line 55, in inner
    response = get_response(request)
               ^^^^^^^^^^^^^^^^^^^^^
  File "/venv/lib/python3.11/site-packages/django/core/handlers/base.py", line 197, in _get_response
    response = wrapped_callback(request, *callback_args, **callback_kwargs)
               ^^^^^^^^^^^^^^^^^^^^^^^^^^^^^^^^^^^^^^^^^^^^^^^^^^^^^^^^^^^^
  File "/venv/lib/python3.11/site-packages/django/views/decorators/csrf.py", line 56, in wrapper_view
    return view_func(*args, **kwargs)
           ^^^^^^^^^^^^^^^^^^^^^^^^^^
  File "/venv/lib/python3.11/site-packages/django/views/generic/base.py", line 104, in view
    return self.dispatch(request, *args, **kwargs)
           ^^^^^^^^^^^^^^^^^^^^^^^^^^^^^^^^^^^^^^^
  File "/venv/lib/python3.11/site-packages/rest_framework/views.py", line 509, in dispatch
    response = self.handle_exception(exc)
               ^^^^^^^^^^^^^^^^^^^^^^^^^^
  File "/venv/lib/python3.11/site-packages/rest_framework/views.py", line 469, in handle_exception
    self.raise_uncaught_exception(exc)
  File "/venv/lib/python3.11/site-packages/rest_framework/views.py", line 480, in raise_uncaught_exception
    raise exc
  File "/venv/lib/python3.11/site-packages/rest_framework/views.py", line 506, in dispatch
    response = handler(request, *args, **kwargs)
               ^^^^^^^^^^^^^^^^^^^^^^^^^^^^^^^^^
  File "/djangoapp/trigger_web_scraping_dou_api/views.py", line 58, in get
    return self.handle_URL_empty_params(saveInDBFlag, detailDOUJournalFlag)
           ^^^^^^^^^^^^^^^^^^^^^^^^^^^^^^^^^^^^^^^^^^^^^^^^^^^^^^^^^^^^^^^^
  File "/djangoapp/trigger_web_scraping_dou_api/views.py", line 192, in handle_URL_empty_params
    response = ScraperUtil.run_scraper_with_empty_params_using_clone_instances(detailDOUJournalFlag)
               ^^^^^^^^^^^^^^^^^^^^^^^^^^^^^^^^^^^^^^^^^^^^^^^^^^^^^^^^^^^^^^^^^^^^^^^^^^^^^^^^^^^^^
  File "/djangoapp/trigger_web_scraping_dou_api/scrapers.py", line 294, in run_scraper_with_empty_params_using_clone_instances
    return ScraperUtil.run_scraper_using_clone_instances_when_secao_do1_do2_and_do3(date_now_db_and_brazilian_format,
          ^^^^^^^^^^^^^^^^^^^^^^^^^^^^^^^^^^^^^^^^^^^^^^^^^^^^^^^^^^^^^^^^^^^^^^^^^^^^^^^^^^^^^^^^^^^^^^^^^^^^^^^^^^^
  File "/djangoapp/trigger_web_scraping_dou_api/scrapers.py", line 336, in run_scraper_using_clone_instances_when_secao_do1_do2_and_do3
    all_dous_response = list(executor.map(ScraperUtil.make_request_for_others_clone_api,
                       ^^^^^^^^^^^^^^^^^^^^^^^^^^^^^^^^^^^^^^^^^^^^^^^^^^^^^^^^^^^^^^^^^
  File "/usr/local/lib/python3.11/concurrent/futures/_base.py", line 619, in result_iterator
    yield _result_or_cancel(fs.pop())
          ^^^^^^^^^^^^^^^^^^^^^^^^^^^
  File "/usr/local/lib/python3.11/concurrent/futures/_base.py", line 317, in _result_or_cancel
    return fut.result(timeout)
           ^^^^^^^^^^^^^^^^^^^
  File "/usr/local/lib/python3.11/concurrent/futures/_base.py", line 456, in result
    return self.__get_result()
           ^^^^^^^^^^^^^^^^^^^
  File "/usr/local/lib/python3.11/concurrent/futures/_base.py", line 401, in __get_result
    raise self._exception
  File "/usr/local/lib/python3.11/concurrent/futures/thread.py", line 58, in run
    result = self.fn(*self.args, **self.kwargs)
             ^^^^^^^^^^^^^^^^^^^^^^^^^^^^^^^^^^
  File "/djangoapp/trigger_web_scraping_dou_api/scrapers.py", line 367, in make_request_for_others_clone_api
    json_string_response = json.dumps({"text": response})
                           ^^^^^^^^^^^^^^^^^^^^^^^^^^^^^^
  File "/usr/local/lib/python3.11/json/__init__.py", line 231, in dumps
    return _default_encoder.encode(obj)
           ^^^^^^^^^^^^^^^^^^^^^^^^^^^^
  File "/usr/local/lib/python3.11/json/encoder.py", line 200, in encode
    chunks = self.iterencode(o, _one_shot=True)
             ^^^^^^^^^^^^^^^^^^^^^^^^^^^^^^^^^^
  File "/usr/local/lib/python3.11/json/encoder.py", line 258, in iterencode
    return _iterencode(o, 0)
           ^^^^^^^^^^^^^^^^^
  File "/usr/local/lib/python3.11/json/encoder.py", line 180, in default
    raise TypeError(f'Object of type {o.__class__.__name__} '
TypeError: Object of type Response is not JSON serializable
2024-01-19 03:42:34,724 - django.request - ERROR - Internal Server Error: /trigger_web_scraping_dou_api/
Traceback (most recent call last):
  File "/venv/lib/python3.11/site-packages/requests/models.py", line 971, in json
    return complexjson.loads(self.text, **kwargs)
           ^^^^^^^^^^^^^^^^^^^^^^^^^^^^^^^^^^^^^^
  File "/usr/local/lib/python3.11/json/__init__.py", line 346, in loads
    return _default_decoder.decode(s)
           ^^^^^^^^^^^^^^^^^^^^^^^^^^
  File "/usr/local/lib/python3.11/json/decoder.py", line 337, in decode
    obj, end = self.raw_decode(s, idx=_w(s, 0).end())
               ^^^^^^^^^^^^^^^^^^^^^^^^^^^^^^^^^^^^^^
  File "/usr/local/lib/python3.11/json/decoder.py", line 355, in raw_decode
    raise JSONDecodeError("Expecting value", s, err.value) from None
json.decoder.JSONDecodeError: Expecting value: line 2 column 1 (char 1)

During handling of the above exception, another exception occurred:

Traceback (most recent call last):
  File "/djangoapp/trigger_web_scraping_dou_api/scrapers.py", line 357, in make_request_for_others_clone_api
    print(response.json())
          ^^^^^^^^^^^^^^^
  File "/venv/lib/python3.11/site-packages/requests/models.py", line 975, in json
    raise RequestsJSONDecodeError(e.msg, e.doc, e.pos)
requests.exceptions.JSONDecodeError: Expecting value: line 2 column 1 (char 1)

During handling of the above exception, another exception occurred:

Traceback (most recent call last):
  File "/venv/lib/python3.11/site-packages/django/core/handlers/exception.py", line 55, in inner
    response = get_response(request)
               ^^^^^^^^^^^^^^^^^^^^^
  File "/venv/lib/python3.11/site-packages/django/core/handlers/base.py", line 197, in _get_response
    response = wrapped_callback(request, *callback_args, **callback_kwargs)
               ^^^^^^^^^^^^^^^^^^^^^^^^^^^^^^^^^^^^^^^^^^^^^^^^^^^^^^^^^^^^
  File "/venv/lib/python3.11/site-packages/django/views/decorators/csrf.py", line 56, in wrapper_view
    return view_func(*args, **kwargs)
           ^^^^^^^^^^^^^^^^^^^^^^^^^^
  File "/venv/lib/python3.11/site-packages/django/views/generic/base.py", line 104, in view
    return self.dispatch(request, *args, **kwargs)
           ^^^^^^^^^^^^^^^^^^^^^^^^^^^^^^^^^^^^^^^
  File "/venv/lib/python3.11/site-packages/rest_framework/views.py", line 509, in dispatch
    response = self.handle_exception(exc)
               ^^^^^^^^^^^^^^^^^^^^^^^^^^
  File "/venv/lib/python3.11/site-packages/rest_framework/views.py", line 469, in handle_exception
    self.raise_uncaught_exception(exc)
  File "/venv/lib/python3.11/site-packages/rest_framework/views.py", line 480, in raise_uncaught_exception
    raise exc
  File "/venv/lib/python3.11/site-packages/rest_framework/views.py", line 506, in dispatch
    response = handler(request, *args, **kwargs)
               ^^^^^^^^^^^^^^^^^^^^^^^^^^^^^^^^^
  File "/djangoapp/trigger_web_scraping_dou_api/views.py", line 58, in get
    return self.handle_URL_empty_params(saveInDBFlag, detailDOUJournalFlag)
           ^^^^^^^^^^^^^^^^^^^^^^^^^^^^^^^^^^^^^^^^^^^^^^^^^^^^^^^^^^^^^^^^
  File "/djangoapp/trigger_web_scraping_dou_api/views.py", line 192, in handle_URL_empty_params
    response = ScraperUtil.run_scraper_with_empty_params_using_clone_instances(detailDOUJournalFlag)
               ^^^^^^^^^^^^^^^^^^^^^^^^^^^^^^^^^^^^^^^^^^^^^^^^^^^^^^^^^^^^^^^^^^^^^^^^^^^^^^^^^^^^^
  File "/djangoapp/trigger_web_scraping_dou_api/scrapers.py", line 294, in run_scraper_with_empty_params_using_clone_instances
    return ScraperUtil.run_scraper_using_clone_instances_when_secao_do1_do2_and_do3(date_now_db_and_brazilian_format,
          ^^^^^^^^^^^^^^^^^^^^^^^^^^^^^^^^^^^^^^^^^^^^^^^^^^^^^^^^^^^^^^^^^^^^^^^^^^^^^^^^^^^^^^^^^^^^^^^^^^^^^^^^^^^
  File "/djangoapp/trigger_web_scraping_dou_api/scrapers.py", line 336, in run_scraper_using_clone_instances_when_secao_do1_do2_and_do3
    all_dous_response = list(executor.map(ScraperUtil.make_request_for_others_clone_api,
                       ^^^^^^^^^^^^^^^^^^^^^^^^^^^^^^^^^^^^^^^^^^^^^^^^^^^^^^^^^^^^^^^^^
  File "/usr/local/lib/python3.11/concurrent/futures/_base.py", line 619, in result_iterator
    yield _result_or_cancel(fs.pop())
          ^^^^^^^^^^^^^^^^^^^^^^^^^^^
  File "/usr/local/lib/python3.11/concurrent/futures/_base.py", line 317, in _result_or_cancel
    return fut.result(timeout)
           ^^^^^^^^^^^^^^^^^^^
  File "/usr/local/lib/python3.11/concurrent/futures/_base.py", line 456, in result
    return self.__get_result()
           ^^^^^^^^^^^^^^^^^^^
  File "/usr/local/lib/python3.11/concurrent/futures/_base.py", line 401, in __get_result
    raise self._exception
  File "/usr/local/lib/python3.11/concurrent/futures/thread.py", line 58, in run
    result = self.fn(*self.args, **self.kwargs)
             ^^^^^^^^^^^^^^^^^^^^^^^^^^^^^^^^^^
  File "/djangoapp/trigger_web_scraping_dou_api/scrapers.py", line 367, in make_request_for_others_clone_api
    json_string_response = json.dumps({"text": response})
                           ^^^^^^^^^^^^^^^^^^^^^^^^^^^^^^
  File "/usr/local/lib/python3.11/json/__init__.py", line 231, in dumps
    return _default_encoder.encode(obj)
           ^^^^^^^^^^^^^^^^^^^^^^^^^^^^
  File "/usr/local/lib/python3.11/json/encoder.py", line 200, in encode
    chunks = self.iterencode(o, _one_shot=True)
             ^^^^^^^^^^^^^^^^^^^^^^^^^^^^^^^^^^
  File "/usr/local/lib/python3.11/json/encoder.py", line 258, in iterencode
    return _iterencode(o, 0)
           ^^^^^^^^^^^^^^^^^
  File "/usr/local/lib/python3.11/json/encoder.py", line 180, in default
    raise TypeError(f'Object of type {o.__class__.__name__} '
TypeError: Object of type Response is not JSON serializable
2024-01-19 03:42:54,222 - django.request - ERROR - Internal Server Error: /trigger_web_scraping_dou_api/
Traceback (most recent call last):
  File "/venv/lib/python3.11/site-packages/requests/models.py", line 971, in json
    return complexjson.loads(self.text, **kwargs)
           ^^^^^^^^^^^^^^^^^^^^^^^^^^^^^^^^^^^^^^
  File "/usr/local/lib/python3.11/json/__init__.py", line 346, in loads
    return _default_decoder.decode(s)
           ^^^^^^^^^^^^^^^^^^^^^^^^^^
  File "/usr/local/lib/python3.11/json/decoder.py", line 337, in decode
    obj, end = self.raw_decode(s, idx=_w(s, 0).end())
               ^^^^^^^^^^^^^^^^^^^^^^^^^^^^^^^^^^^^^^
  File "/usr/local/lib/python3.11/json/decoder.py", line 355, in raw_decode
    raise JSONDecodeError("Expecting value", s, err.value) from None
json.decoder.JSONDecodeError: Expecting value: line 2 column 1 (char 1)

During handling of the above exception, another exception occurred:

Traceback (most recent call last):
  File "/djangoapp/trigger_web_scraping_dou_api/scrapers.py", line 357, in make_request_for_others_clone_api
    print(response.json())
          ^^^^^^^^^^^^^^^
  File "/venv/lib/python3.11/site-packages/requests/models.py", line 975, in json
    raise RequestsJSONDecodeError(e.msg, e.doc, e.pos)
requests.exceptions.JSONDecodeError: Expecting value: line 2 column 1 (char 1)

During handling of the above exception, another exception occurred:

Traceback (most recent call last):
  File "/venv/lib/python3.11/site-packages/django/core/handlers/exception.py", line 55, in inner
    response = get_response(request)
               ^^^^^^^^^^^^^^^^^^^^^
  File "/venv/lib/python3.11/site-packages/django/core/handlers/base.py", line 197, in _get_response
    response = wrapped_callback(request, *callback_args, **callback_kwargs)
               ^^^^^^^^^^^^^^^^^^^^^^^^^^^^^^^^^^^^^^^^^^^^^^^^^^^^^^^^^^^^
  File "/venv/lib/python3.11/site-packages/django/views/decorators/csrf.py", line 56, in wrapper_view
    return view_func(*args, **kwargs)
           ^^^^^^^^^^^^^^^^^^^^^^^^^^
  File "/venv/lib/python3.11/site-packages/django/views/generic/base.py", line 104, in view
    return self.dispatch(request, *args, **kwargs)
           ^^^^^^^^^^^^^^^^^^^^^^^^^^^^^^^^^^^^^^^
  File "/venv/lib/python3.11/site-packages/rest_framework/views.py", line 509, in dispatch
    response = self.handle_exception(exc)
               ^^^^^^^^^^^^^^^^^^^^^^^^^^
  File "/venv/lib/python3.11/site-packages/rest_framework/views.py", line 469, in handle_exception
    self.raise_uncaught_exception(exc)
  File "/venv/lib/python3.11/site-packages/rest_framework/views.py", line 480, in raise_uncaught_exception
    raise exc
  File "/venv/lib/python3.11/site-packages/rest_framework/views.py", line 506, in dispatch
    response = handler(request, *args, **kwargs)
               ^^^^^^^^^^^^^^^^^^^^^^^^^^^^^^^^^
  File "/djangoapp/trigger_web_scraping_dou_api/views.py", line 58, in get
    return self.handle_URL_empty_params(saveInDBFlag, detailDOUJournalFlag)
           ^^^^^^^^^^^^^^^^^^^^^^^^^^^^^^^^^^^^^^^^^^^^^^^^^^^^^^^^^^^^^^^^
  File "/djangoapp/trigger_web_scraping_dou_api/views.py", line 192, in handle_URL_empty_params
    response = ScraperUtil.run_scraper_with_empty_params_using_clone_instances(detailDOUJournalFlag)
               ^^^^^^^^^^^^^^^^^^^^^^^^^^^^^^^^^^^^^^^^^^^^^^^^^^^^^^^^^^^^^^^^^^^^^^^^^^^^^^^^^^^^^
  File "/djangoapp/trigger_web_scraping_dou_api/scrapers.py", line 294, in run_scraper_with_empty_params_using_clone_instances
    return ScraperUtil.run_scraper_using_clone_instances_when_secao_do1_do2_and_do3(date_now_db_and_brazilian_format,
          ^^^^^^^^^^^^^^^^^^^^^^^^^^^^^^^^^^^^^^^^^^^^^^^^^^^^^^^^^^^^^^^^^^^^^^^^^^^^^^^^^^^^^^^^^^^^^^^^^^^^^^^^^^^
  File "/djangoapp/trigger_web_scraping_dou_api/scrapers.py", line 336, in run_scraper_using_clone_instances_when_secao_do1_do2_and_do3
    all_dous_response = list(executor.map(ScraperUtil.make_request_for_others_clone_api,
                       ^^^^^^^^^^^^^^^^^^^^^^^^^^^^^^^^^^^^^^^^^^^^^^^^^^^^^^^^^^^^^^^^^
  File "/usr/local/lib/python3.11/concurrent/futures/_base.py", line 619, in result_iterator
    yield _result_or_cancel(fs.pop())
          ^^^^^^^^^^^^^^^^^^^^^^^^^^^
  File "/usr/local/lib/python3.11/concurrent/futures/_base.py", line 317, in _result_or_cancel
    return fut.result(timeout)
           ^^^^^^^^^^^^^^^^^^^
  File "/usr/local/lib/python3.11/concurrent/futures/_base.py", line 456, in result
    return self.__get_result()
           ^^^^^^^^^^^^^^^^^^^
  File "/usr/local/lib/python3.11/concurrent/futures/_base.py", line 401, in __get_result
    raise self._exception
  File "/usr/local/lib/python3.11/concurrent/futures/thread.py", line 58, in run
    result = self.fn(*self.args, **self.kwargs)
             ^^^^^^^^^^^^^^^^^^^^^^^^^^^^^^^^^^
  File "/djangoapp/trigger_web_scraping_dou_api/scrapers.py", line 367, in make_request_for_others_clone_api
    json_string_response = json.dumps({"text": response})
                           ^^^^^^^^^^^^^^^^^^^^^^^^^^^^^^
  File "/usr/local/lib/python3.11/json/__init__.py", line 231, in dumps
    return _default_encoder.encode(obj)
           ^^^^^^^^^^^^^^^^^^^^^^^^^^^^
  File "/usr/local/lib/python3.11/json/encoder.py", line 200, in encode
    chunks = self.iterencode(o, _one_shot=True)
             ^^^^^^^^^^^^^^^^^^^^^^^^^^^^^^^^^^
  File "/usr/local/lib/python3.11/json/encoder.py", line 258, in iterencode
    return _iterencode(o, 0)
           ^^^^^^^^^^^^^^^^^
  File "/usr/local/lib/python3.11/json/encoder.py", line 180, in default
    raise TypeError(f'Object of type {o.__class__.__name__} '
TypeError: Object of type Response is not JSON serializable
